<?xml version="1.0" ?>
<!-- Generated using onshape-to-robot -->
<!-- Onshape document_id: e9ee61a2e2678af2088d9f31 -->
<robot name="lite">
  <!-- Link chest -->
  <link name="chest">
    <inertial>
      <origin xyz="0.0229755 1.89075e-06 0.301247" rpy="0 0 0"/>
      <mass value="4.241"/>
      <inertia ixx="0.0293981" ixy="-3.33035e-07" ixz="0.00371359" iyy="0.0293132" iyz="-2.47e-10" izz="0.0103245"/>
    </inertial>
    <!-- Part chest_parts -->
    <collision>
      <origin xyz="0.025 -0 0.29" rpy="0.261799 0 -1.5708"/>
      <geometry>
        <box size="0.08 0.1 0.2"/>
      </geometry>
    </collision>
    <visual>
      <origin xyz="0.0229755 1.89075e-06 0.301247" rpy="0 -0 0"/>
      <geometry>
        <mesh filename="../meshes/chest_visual.stl"/>
      </geometry>
      <material name="chest_parts_material">
        <color rgba="0.800362 0.810299 0.761329 1"/>
      </material>
    </visual>
  </link>
  <!-- Link left_shoulder_pitch -->
  <link name="left_shoulder_pitch">
    <inertial>
      <origin xyz="-6.27e-10 -0.00168619 -0.00682299" rpy="0 0 0"/>
      <mass value="0.375"/>
      <inertia ixx="0.000232695" ixy="7e-12" ixz="2e-12" iyy="0.000233203" iyz="-1.40823e-05" izz="0.000199827"/>
    </inertial>
    <!-- Part left_shoulder_pitch_parts -->
    <visual>
      <origin xyz="-6.27e-10 -0.00168619 -0.00682299" rpy="1.39626 -0 -0"/>
      <geometry>
        <mesh filename="../meshes/left_shoulder_pitch_visual.stl"/>
      </geometry>
      <material name="left_shoulder_pitch_parts_material">
        <color rgba="0.498039 0.498039 0.498039 1"/>
      </material>
    </visual>
  </link>
  <!-- Link left_shoulder_roll -->
  <link name="left_shoulder_roll">
    <inertial>
      <origin xyz="-2.43656e-06 0.0799616 1.54812e-07" rpy="0 0 0"/>
      <mass value="0.41"/>
      <inertia ixx="0.000505028" ixy="-5.69e-08" ixz="-1.9756e-08" iyy="0.00019823" iyz="2.659e-09" izz="0.000477612"/>
    </inertial>
    <!-- Part left_shoulder_roll_parts -->
    <visual>
      <origin xyz="-2.43656e-06 0.0799616 1.54812e-07" rpy="0 -1.5708 0"/>
      <geometry>
        <mesh filename="../meshes/left_shoulder_roll_visual.stl"/>
      </geometry>
      <material name="left_shoulder_roll_parts_material">
        <color rgba="0.862745 0.661119 0.124438 1"/>
      </material>
    </visual>
  </link>
  <!-- Link left_shoulder_yaw -->
  <link name="left_shoulder_yaw">
    <inertial>
      <origin xyz="0.00515648 -2.4401e-08 -0.0554418" rpy="0 0 0"/>
      <mass value="0.416"/>
      <inertia ixx="0.000480518" ixy="-9.59e-10" ixz="4.64686e-05" iyy="0.000484791" iyz="1.64e-10" izz="0.00021421"/>
    </inertial>
    <!-- Part left_shoulder_yaw_parts -->
    <collision>
      <origin xyz="0 0 0.03" rpy="0 0 -1.5708"/>
      <geometry>
        <cylinder length="0.08" radius="0.03"/>
      </geometry>
    </collision>
    <visual>
      <origin xyz="0.00515648 -2.4401e-08 -0.0554418" rpy="-1.5708 0 -0"/>
      <geometry>
        <mesh filename="../meshes/left_shoulder_yaw_visual.stl"/>
      </geometry>
      <material name="left_shoulder_yaw_parts_material">
        <color rgba="0.615686 0.811765 0.929412 1"/>
      </material>
    </visual>
  </link>
  <!-- Link left_elbow_pitch -->
  <link name="left_elbow_pitch">
    <inertial>
      <origin xyz="-0.00846207 0.0260402 3.13818e-06" rpy="0 0 0"/>
      <mass value="0.1"/>
      <inertia ixx="0.000107182" ixy="7.39361e-06" ixz="-2.484e-09" iyy="8.53959e-05" iyz="5.512e-09" izz="7.35755e-05"/>
    </inertial>
    <!-- Part left_elbow_pitch_parts -->
    <visual>
      <origin xyz="-0.00846207 0.0260402 3.13818e-06" rpy="0 -0 0"/>
      <geometry>
        <mesh filename="../meshes/left_elbow_pitch_visual.stl"/>
      </geometry>
      <material name="left_elbow_pitch_parts_material">
        <color rgba="0.647059 0.647059 0.647059 1"/>
      </material>
    </visual>
  </link>
  <!-- Link left_wrist_yaw -->
  <link name="left_wrist_yaw">
    <inertial>
      <origin xyz="-2.41223e-07 0.000140366 -0.0579268" rpy="0 0 0"/>
      <mass value="0.6"/>
      <inertia ixx="0.00091929" ixy="-6.78e-10" ixz="-6.13e-10" iyy="0.000910171" iyz="-9.06095e-06" izz="0.000298189"/>
    </inertial>
    <!-- Part left_wrist_yaw_parts -->
    <collision>
      <origin xyz="0 0 -0.035" rpy="0 -0 -3.14159"/>
      <geometry>
        <cylinder length="0.08" radius="0.03"/>
      </geometry>
    </collision>
    <visual>
      <origin xyz="-2.41223e-07 0.000140366 -0.0579268" rpy="-1.5708 -0 0"/>
      <geometry>
        <mesh filename="../meshes/left_wrist_yaw_visual.stl"/>
      </geometry>
      <material name="left_wrist_yaw_parts_material">
        <color rgba="0.647059 0.647059 0.647059 1"/>
      </material>
    </visual>
  </link>
  <!-- Link left_wrist_roll -->
  <link name="left_wrist_roll">
    <inertial>
      <origin xyz="3.48e-10 1e-12 -2.12e-10" rpy="0 0 0"/>
      <mass value="0.25"/>
      <inertia ixx="7.92687e-05" ixy="0" ixz="0" iyy="9.19125e-05" iyz="-6.7e-11" izz="9.04076e-05"/>
    </inertial>
    <!-- Part left_wrist_roll_parts -->
    <visual>
      <origin xyz="3.48e-10 1e-12 -2.12e-10" rpy="0 0 0"/>
      <geometry>
        <mesh filename="../meshes/left_wrist_roll_visual.stl"/>
      </geometry>
      <material name="left_wrist_roll_parts_material">
        <color rgba="0.231373 0.380392 0.705882 1"/>
      </material>
    </visual>
  </link>
  <!-- Link left_hand -->
  <link name="left_hand">
    <inertial>
      <origin xyz="2.5307e-08 0.0307393 -0.0039657" rpy="0 0 0"/>
      <mass value="0.0692791"/>
      <inertia ixx="5.76781e-05" ixy="5.8e-11" ixz="1.8e-11" iyy="3.7322e-05" iyz="4.15711e-06" izz="2.86549e-05"/>
    </inertial>
    <!-- Part left_hand_parts -->
    <collision>
      <origin xyz="-0.03 0.07 -0" rpy="1.5708 -0 -1.5708"/>
      <geometry>
        <box size="0.1 0.07 0.015"/>
      </geometry>
    </collision>
    <visual>
      <origin xyz="2.5307e-08 0.0307393 -0.0039657" rpy="0 -1.5708 0"/>
      <geometry>
        <mesh filename="../meshes/left_hand_visual.stl"/>
      </geometry>
      <material name="left_hand_parts_material">
        <color rgba="0.804149 0.877849 0.922069 1"/>
      </material>
    </visual>
  </link>
  <!-- Link left_finger1_j1 -->
  <link name="left_finger1_j1">
    <inertial>
      <origin xyz="0 0.0025 0" rpy="0 0 0"/>
      <mass value="0.000744"/>
      <inertia ixx="1.0478e-08" ixy="-0" ixz="-0" iyy="1.5128e-08" iyz="0" izz="7.75e-09"/>
    </inertial>
    <!-- Part left_finger1_j1_parts -->
    <visual>
      <origin xyz="0 0.0025 0" rpy="-1.5708 -0.785398 1.5708"/>
      <geometry>
        <mesh filename="../meshes/left_finger1_j1_visual.stl"/>
      </geometry>
      <material name="left_finger1_j1_parts_material">
        <color rgba="0.498039 0.498039 0.498039 1"/>
      </material>
    </visual>
  </link>
  <!-- Link left_finger1_j2 -->
  <link name="left_finger1_j2">
    <inertial>
      <origin xyz="0 0.01 -0" rpy="0 0 0"/>
      <mass value="0.002976"/>
      <inertia ixx="1.24e-07" ixy="0" ixz="-0" iyy="6.0512e-08" iyz="-0" izz="1.34912e-07"/>
    </inertial>
    <!-- Part left_finger1_j2_parts -->
    <visual>
      <origin xyz="0 0.01 -0" rpy="0 -0 0.785398"/>
      <geometry>
        <mesh filename="../meshes/left_finger1_j2_visual.stl"/>
      </geometry>
      <material name="left_finger1_j2_parts_material">
        <color rgba="0.972549 0.529412 0.00392157 1"/>
      </material>
    </visual>
  </link>
  <!-- Link left_finger1_j3 -->
  <link name="left_finger1_j3">
    <inertial>
      <origin xyz="-0 0.01 -0" rpy="0 0 0"/>
      <mass value="0.001984"/>
      <inertia ixx="8.2667e-08" ixy="-0" ixz="0" iyy="2.7115e-08" iyz="0" izz="7.6715e-08"/>
    </inertial>
    <!-- Part left_finger1_j3_parts -->
    <visual>
      <origin xyz="-0 0.01 -0" rpy="-1.5708 -0.785398 1.5708"/>
      <geometry>
        <mesh filename="../meshes/left_finger1_j3_visual.stl"/>
      </geometry>
      <material name="left_finger1_j3_parts_material">
        <color rgba="0.498039 0.498039 0.498039 1"/>
      </material>
    </visual>
  </link>
  <!-- Link left_finger1_j4 -->
  <link name="left_finger1_j4">
    <inertial>
      <origin xyz="-0.000271318 0.00682171 -0" rpy="0 0 0"/>
      <mass value="0.001333"/>
      <inertia ixx="3.2905e-08" ixy="2.247e-09" ixz="0" iyy="1.7887e-08" iyz="0" izz="2.8576e-08"/>
    </inertial>
    <!-- Part left_finger1_j4_parts -->
    <visual>
      <origin xyz="-0.000271318 0.00682171 -0" rpy="-1.5708 -0.785398 1.5708"/>
      <geometry>
        <mesh filename="../meshes/left_finger1_j4_visual.stl"/>
      </geometry>
      <material name="left_finger1_j4_parts_material">
        <color rgba="0.980392 0.713725 0.00392157 1"/>
      </material>
    </visual>
  </link>
  <!-- Frame left_finger1_tip (dummy link + fixed joint) -->
  <link name="left_finger1_tip">
    <origin xyz="0 0 0" rpy="0 -0 0"/>
    <inertial>
      <origin xyz="0 0 0" rpy="0 0 0"/>
      <mass value="1e-9"/>
      <inertia ixx="0" ixy="0" ixz="0" iyy="0" iyz="0" izz="0"/>
    </inertial>
  </link>
  <joint name="left_finger1_tip_frame" type="fixed">
    <origin xyz="-0 0.015 -0" rpy="-1.5708 0 1.5708"/>
    <parent link="left_finger1_j4"/>
    <child link="left_finger1_tip"/>
    <axis xyz="0 0 0"/>
  </joint>
  <!-- Joint from left_finger1_j3 to left_finger1_j4 -->
  <joint name="left_finger1_j4" type="revolute">
    <origin xyz="0 0.025 -0" rpy="-0 0 -0"/>
    <parent link="left_finger1_j3"/>
    <child link="left_finger1_j4"/>
    <axis xyz="0 0 1"/>
    <limit effort="100" velocity="100" lower="-1.5708" upper="0.0872665"/>
    <joint_properties friction="0.1"/>
  </joint>
  <!-- Joint from left_finger1_j2 to left_finger1_j3 -->
  <joint name="left_finger1_j3" type="revolute">
    <origin xyz="0 0.025 0" rpy="0 1.5708 0"/>
    <parent link="left_finger1_j2"/>
    <child link="left_finger1_j3"/>
    <axis xyz="0 0 1"/>
    <limit effort="100" velocity="100" lower="-1.91986" upper="0.0872665"/>
    <joint_properties friction="0.1"/>
  </joint>
  <!-- Joint from left_finger1_j1 to left_finger1_j2 -->
  <joint name="left_finger1_j2" type="revolute">
    <origin xyz="0 0.01 0" rpy="0 -1.5708 0"/>
    <parent link="left_finger1_j1"/>
    <child link="left_finger1_j2"/>
    <axis xyz="0 0 1"/>
    <limit effort="100" velocity="100" lower="-0.349066" upper="0.349066"/>
    <joint_properties friction="0.1"/>
  </joint>
  <!-- Joint from left_hand to left_finger1_j1 -->
  <joint name="left_finger1_j1" type="revolute">
    <origin xyz="0 0.035 0.03" rpy="0.785398 -0 -0"/>
    <parent link="left_hand"/>
    <child link="left_finger1_j1"/>
    <axis xyz="0 0 1"/>
    <limit effort="100" velocity="100" lower="-1.5708" upper="-0"/>
    <joint_properties friction="0.1"/>
  </joint>
  <!-- Link left_finger2_j1 -->
  <link name="left_finger2_j1">
    <inertial>
      <origin xyz="-0 0.0025 -0" rpy="0 0 0"/>
      <mass value="0.000496"/>
      <inertia ixx="3.679e-09" ixy="0" ixz="0" iyy="6.779e-09" iyz="-0" izz="5.167e-09"/>
    </inertial>
    <!-- Part left_finger2_j1_parts -->
    <visual>
      <origin xyz="0 0.0025 -0" rpy="0 -1.5708 0"/>
      <geometry>
        <mesh filename="../meshes/left_finger2_j1_visual.stl"/>
      </geometry>
      <material name="left_finger2_j1_parts_material">
        <color rgba="0.980392 0.713725 0.00392157 1"/>
      </material>
    </visual>
  </link>
  <!-- Link left_finger2_j2 -->
  <link name="left_finger2_j2">
    <inertial>
      <origin xyz="0 0.0125 -0" rpy="0 0 0"/>
      <mass value="0.00248"/>
      <inertia ixx="1.49833e-07" ixy="-0" ixz="-0" iyy="3.3893e-08" iyz="0" izz="1.42393e-07"/>
    </inertial>
    <!-- Part left_finger2_j2_parts -->
    <visual>
      <origin xyz="0 0.0125 -0" rpy="-0 0 0"/>
      <geometry>
        <mesh filename="../meshes/left_finger2_j2_visual.stl"/>
      </geometry>
      <material name="left_finger2_j2_parts_material">
        <color rgba="0.647059 0.647059 0.647059 1"/>
      </material>
    </visual>
  </link>
  <!-- Link left_finger2_j3 -->
  <link name="left_finger2_j3">
    <inertial>
      <origin xyz="0 0.01 0" rpy="0 0 0"/>
      <mass value="0.0011904"/>
      <inertia ixx="4.3251e-08" ixy="-0" ixz="-0" iyy="9.92e-09" iyz="-0" izz="4.6029e-08"/>
    </inertial>
    <!-- Part left_finger2_j3_parts -->
    <visual>
      <origin xyz="0 0.01 0" rpy="0 -1.5708 0"/>
      <geometry>
        <mesh filename="../meshes/left_finger2_j3_visual.stl"/>
      </geometry>
      <material name="left_finger2_j3_parts_material">
        <color rgba="0.498039 0.498039 0.498039 1"/>
      </material>
    </visual>
  </link>
  <!-- Link left_finger2_j4 -->
  <link name="left_finger2_j4">
    <inertial>
      <origin xyz="-0.000432099 0.00438272 0" rpy="0 0 0"/>
      <mass value="0.0004185"/>
      <inertia ixx="3.877e-09" ixy="6.61e-10" ixz="-0" iyy="2.909e-09" iyz="0" izz="5.043e-09"/>
    </inertial>
    <!-- Part left_finger2_j4_parts -->
    <visual>
      <origin xyz="-0.000432099 0.00438272 0" rpy="0 -1.5708 0"/>
      <geometry>
        <mesh filename="../meshes/left_finger2_j4_visual.stl"/>
      </geometry>
      <material name="left_finger2_j4_parts_material">
        <color rgba="0.980392 0.713725 0.00392157 1"/>
      </material>
    </visual>
  </link>
  <!-- Frame left_finger2_tip (dummy link + fixed joint) -->
  <link name="left_finger2_tip">
    <origin xyz="0 0 0" rpy="0 -0 0"/>
    <inertial>
      <origin xyz="0 0 0" rpy="0 0 0"/>
      <mass value="1e-9"/>
      <inertia ixx="0" ixy="0" ixz="0" iyy="0" iyz="0" izz="0"/>
    </inertial>
  </link>
  <joint name="left_finger2_tip_frame" type="fixed">
    <origin xyz="0 0.01 0" rpy="-1.5708 0 1.5708"/>
    <parent link="left_finger2_j4"/>
    <child link="left_finger2_tip"/>
    <axis xyz="0 0 0"/>
  </joint>
  <!-- Joint from left_finger2_j3 to left_finger2_j4 -->
  <joint name="left_finger2_j4" type="revolute">
    <origin xyz="0 0.025 -0" rpy="0 -0 -0"/>
    <parent link="left_finger2_j3"/>
    <child link="left_finger2_j4"/>
    <axis xyz="0 0 1"/>
    <limit effort="100" velocity="100" lower="-1.5708" upper="0.0872665"/>
    <joint_properties friction="0.1"/>
  </joint>
  <!-- Joint from left_finger2_j2 to left_finger2_j3 -->
  <joint name="left_finger2_j3" type="revolute">
    <origin xyz="0 0.03 -0" rpy="-0 1.5708 0"/>
    <parent link="left_finger2_j2"/>
    <child link="left_finger2_j3"/>
    <axis xyz="0 0 1"/>
    <limit effort="100" velocity="100" lower="-1.91986" upper="0.0872665"/>
    <joint_properties friction="0.1"/>
  </joint>
  <!-- Joint from left_finger2_j1 to left_finger2_j2 -->
  <joint name="left_finger2_j2" type="revolute">
    <origin xyz="0 0.01 0" rpy="0 -1.5708 0"/>
    <parent link="left_finger2_j1"/>
    <child link="left_finger2_j2"/>
    <axis xyz="0 0 1"/>
    <limit effort="100" velocity="100" lower="-0.349066" upper="0.349066"/>
    <joint_properties friction="0.1"/>
  </joint>
  <!-- Joint from left_hand to left_finger2_j1 -->
  <joint name="left_finger2_j1" type="revolute">
    <origin xyz="0 0.07 0.015" rpy="0 0 -0"/>
    <parent link="left_hand"/>
    <child link="left_finger2_j1"/>
    <axis xyz="0 0 1"/>
    <limit effort="100" velocity="100" lower="-1.91986" upper="0.0872665"/>
    <joint_properties friction="0.1"/>
  </joint>
  <!-- Link left_finger3_j1 -->
  <link name="left_finger3_j1">
    <inertial>
      <origin xyz="-0 0.0025 -0" rpy="0 0 0"/>
      <mass value="0.000496"/>
      <inertia ixx="3.679e-09" ixy="-0" ixz="0" iyy="6.779e-09" iyz="-0" izz="5.167e-09"/>
    </inertial>
    <!-- Part left_finger3_j1_parts -->
    <visual>
      <origin xyz="-0 0.0025 -0" rpy="0 -1.5708 0"/>
      <geometry>
        <mesh filename="../meshes/left_finger3_j1_visual.stl"/>
      </geometry>
      <material name="left_finger3_j1_parts_material">
        <color rgba="0.615686 0.811765 0.929412 1"/>
      </material>
    </visual>
  </link>
  <!-- Link left_finger3_j2 -->
  <link name="left_finger3_j2">
    <inertial>
      <origin xyz="-0 0.015 -0" rpy="0 0 0"/>
      <mass value="0.002976"/>
      <inertia ixx="2.48e-07" ixy="0" ixz="0" iyy="4.0672e-08" iyz="-0" izz="2.39072e-07"/>
    </inertial>
    <!-- Part left_finger3_j2_parts -->
    <visual>
      <origin xyz="-0 0.015 -0" rpy="0 -0 0"/>
      <geometry>
        <mesh filename="../meshes/left_finger3_j2_visual.stl"/>
      </geometry>
      <material name="left_finger3_j2_parts_material">
        <color rgba="0.231373 0.380392 0.705882 1"/>
      </material>
    </visual>
  </link>
  <!-- Link left_finger3_j3 -->
  <link name="left_finger3_j3">
    <inertial>
      <origin xyz="-0 0.0125 0" rpy="0 0 0"/>
      <mass value="0.001488"/>
      <inertia ixx="8.1964e-08" ixy="0" ixz="-0" iyy="1.24e-08" iyz="0" izz="8.5436e-08"/>
    </inertial>
    <!-- Part left_finger3_j3_parts -->
    <visual>
      <origin xyz="-0 0.0125 0" rpy="-0 -1.5708 0"/>
      <geometry>
        <mesh filename="../meshes/left_finger3_j3_visual.stl"/>
      </geometry>
      <material name="left_finger3_j3_parts_material">
        <color rgba="0.615686 0.811765 0.929412 1"/>
      </material>
    </visual>
  </link>
  <!-- Link left_finger3_j4 -->
  <link name="left_finger3_j4">
    <inertial>
      <origin xyz="-0.000432099 0.00438272 0" rpy="0 0 0"/>
      <mass value="0.0004185"/>
      <inertia ixx="3.877e-09" ixy="6.61e-10" ixz="-0" iyy="2.909e-09" iyz="0" izz="5.043e-09"/>
    </inertial>
    <!-- Part left_finger3_j4_parts -->
    <visual>
      <origin xyz="-0.000432099 0.00438272 0" rpy="0 -1.5708 0"/>
      <geometry>
        <mesh filename="../meshes/left_finger3_j4_visual.stl"/>
      </geometry>
      <material name="left_finger3_j4_parts_material">
        <color rgba="0.647059 0.647059 0.647059 1"/>
      </material>
    </visual>
  </link>
  <!-- Frame left_finger3_tip (dummy link + fixed joint) -->
  <link name="left_finger3_tip">
    <origin xyz="0 0 0" rpy="0 -0 0"/>
    <inertial>
      <origin xyz="0 0 0" rpy="0 0 0"/>
      <mass value="1e-9"/>
      <inertia ixx="0" ixy="0" ixz="0" iyy="0" iyz="0" izz="0"/>
    </inertial>
  </link>
  <joint name="left_finger3_tip_frame" type="fixed">
    <origin xyz="0 0.01 0" rpy="-1.5708 -0 1.5708"/>
    <parent link="left_finger3_j4"/>
    <child link="left_finger3_tip"/>
    <axis xyz="0 0 0"/>
  </joint>
  <!-- Joint from left_finger3_j3 to left_finger3_j4 -->
  <joint name="left_finger3_j4" type="revolute">
    <origin xyz="0 0.03 0" rpy="0 -0 -0"/>
    <parent link="left_finger3_j3"/>
    <child link="left_finger3_j4"/>
    <axis xyz="0 0 1"/>
    <limit effort="100" velocity="100" lower="-1.5708" upper="0.0872665"/>
    <joint_properties friction="0.1"/>
  </joint>
  <!-- Joint from left_finger3_j2 to left_finger3_j3 -->
  <joint name="left_finger3_j3" type="revolute">
    <origin xyz="0 0.035 0" rpy="-0 1.5708 0"/>
    <parent link="left_finger3_j2"/>
    <child link="left_finger3_j3"/>
    <axis xyz="0 0 1"/>
    <limit effort="100" velocity="100" lower="-1.91986" upper="0.0872665"/>
    <joint_properties friction="0.1"/>
  </joint>
  <!-- Joint from left_finger3_j1 to left_finger3_j2 -->
  <joint name="left_finger3_j2" type="revolute">
    <origin xyz="0 0.01 0" rpy="0 -1.5708 0"/>
    <parent link="left_finger3_j1"/>
    <child link="left_finger3_j2"/>
    <axis xyz="0 0 1"/>
    <limit effort="100" velocity="100" lower="-0.349066" upper="0.349066"/>
    <joint_properties friction="0.1"/>
  </joint>
  <!-- Joint from left_hand to left_finger3_j1 -->
  <joint name="left_finger3_j1" type="revolute">
    <origin xyz="0 0.075 0" rpy="0 0 0"/>
    <parent link="left_hand"/>
    <child link="left_finger3_j1"/>
    <axis xyz="0 0 1"/>
    <limit effort="100" velocity="100" lower="-1.91986" upper="0.0872665"/>
    <joint_properties friction="0.1"/>
  </joint>
  <!-- Link left_finger4_j1 -->
  <link name="left_finger4_j1">
    <inertial>
      <origin xyz="-0 0.0025 0" rpy="0 0 0"/>
      <mass value="0.000496"/>
      <inertia ixx="3.679e-09" ixy="0" ixz="0" iyy="6.779e-09" iyz="-0" izz="5.167e-09"/>
    </inertial>
    <!-- Part left_finger4_j1_parts -->
    <visual>
      <origin xyz="-0 0.0025 0" rpy="0 -1.5708 0"/>
      <geometry>
        <mesh filename="../meshes/left_finger4_j1_visual.stl"/>
      </geometry>
      <material name="left_finger4_j1_parts_material">
        <color rgba="0.647059 0.647059 0.647059 1"/>
      </material>
    </visual>
  </link>
  <!-- Link left_finger4_j2 -->
  <link name="left_finger4_j2">
    <inertial>
      <origin xyz="-0 0.015 -0" rpy="0 0 0"/>
      <mass value="0.002976"/>
      <inertia ixx="2.48e-07" ixy="0" ixz="0" iyy="4.0672e-08" iyz="0" izz="2.39072e-07"/>
    </inertial>
    <!-- Part left_finger4_j2_parts -->
    <visual>
      <origin xyz="-0 0.015 -0" rpy="0 -0 -0"/>
      <geometry>
        <mesh filename="../meshes/left_finger4_j2_visual.stl"/>
      </geometry>
      <material name="left_finger4_j2_parts_material">
        <color rgba="0.917647 0.917647 0.917647 1"/>
      </material>
    </visual>
  </link>
  <!-- Link left_finger4_j3 -->
  <link name="left_finger4_j3">
    <inertial>
      <origin xyz="-0 0.01 0" rpy="0 0 0"/>
      <mass value="0.0011904"/>
      <inertia ixx="4.3251e-08" ixy="-0" ixz="0" iyy="9.92e-09" iyz="0" izz="4.6029e-08"/>
    </inertial>
    <!-- Part left_finger4_j3_parts -->
    <visual>
      <origin xyz="-0 0.01 0" rpy="-0 -1.5708 0"/>
      <geometry>
        <mesh filename="../meshes/left_finger4_j3_visual.stl"/>
      </geometry>
      <material name="left_finger4_j3_parts_material">
        <color rgba="0.231373 0.380392 0.705882 1"/>
      </material>
    </visual>
  </link>
  <!-- Link left_finger4_j4 -->
  <link name="left_finger4_j4">
    <inertial>
      <origin xyz="-0.000432099 0.00438272 -0" rpy="0 0 0"/>
      <mass value="0.0004185"/>
      <inertia ixx="3.877e-09" ixy="6.61e-10" ixz="0" iyy="2.909e-09" iyz="0" izz="5.043e-09"/>
    </inertial>
    <!-- Part left_finger4_j4_parts -->
    <visual>
      <origin xyz="-0.000432099 0.00438272 -0" rpy="0 -1.5708 0"/>
      <geometry>
        <mesh filename="../meshes/left_finger4_j4_visual.stl"/>
      </geometry>
      <material name="left_finger4_j4_parts_material">
        <color rgba="0.917647 0.917647 0.917647 1"/>
      </material>
    </visual>
  </link>
  <!-- Frame left_finger4_tip (dummy link + fixed joint) -->
  <link name="left_finger4_tip">
    <origin xyz="0 0 0" rpy="0 -0 0"/>
    <inertial>
      <origin xyz="0 0 0" rpy="0 0 0"/>
      <mass value="1e-9"/>
      <inertia ixx="0" ixy="0" ixz="0" iyy="0" iyz="0" izz="0"/>
    </inertial>
  </link>
  <joint name="left_finger4_tip_frame" type="fixed">
    <origin xyz="0 0.01 -0" rpy="-1.5708 -0 1.5708"/>
    <parent link="left_finger4_j4"/>
    <child link="left_finger4_tip"/>
    <axis xyz="0 0 0"/>
  </joint>
  <!-- Joint from left_finger4_j3 to left_finger4_j4 -->
  <joint name="left_finger4_j4" type="revolute">
    <origin xyz="0 0.025 0" rpy="-0 -0 -0"/>
    <parent link="left_finger4_j3"/>
    <child link="left_finger4_j4"/>
    <axis xyz="0 0 1"/>
    <limit effort="100" velocity="100" lower="-1.5708" upper="0.0872665"/>
    <joint_properties friction="0.1"/>
  </joint>
  <!-- Joint from left_finger4_j2 to left_finger4_j3 -->
  <joint name="left_finger4_j3" type="revolute">
    <origin xyz="0 0.035 0" rpy="0 1.5708 0"/>
    <parent link="left_finger4_j2"/>
    <child link="left_finger4_j3"/>
    <axis xyz="0 0 1"/>
    <limit effort="100" velocity="100" lower="-1.91986" upper="0.0872665"/>
    <joint_properties friction="0.1"/>
  </joint>
  <!-- Joint from left_finger4_j1 to left_finger4_j2 -->
  <joint name="left_finger4_j2" type="revolute">
    <origin xyz="0 0.01 0" rpy="0 -1.5708 0"/>
    <parent link="left_finger4_j1"/>
    <child link="left_finger4_j2"/>
    <axis xyz="0 0 1"/>
    <limit effort="100" velocity="100" lower="-0.349066" upper="0.349066"/>
    <joint_properties friction="0.1"/>
  </joint>
  <!-- Joint from left_hand to left_finger4_j1 -->
  <joint name="left_finger4_j1" type="revolute">
    <origin xyz="0 0.07 -0.015" rpy="-0 0 -0"/>
    <parent link="left_hand"/>
    <child link="left_finger4_j1"/>
    <axis xyz="0 0 1"/>
    <limit effort="100" velocity="100" lower="-1.91986" upper="0.0872665"/>
    <joint_properties friction="0.1"/>
  </joint>
  <!-- Link left_finger5_j1 -->
  <link name="left_finger5_j1">
    <inertial>
      <origin xyz="-0 0.0025 0" rpy="0 0 0"/>
      <mass value="0.000496"/>
      <inertia ixx="3.679e-09" ixy="-0" ixz="-0" iyy="6.779e-09" iyz="-0" izz="5.167e-09"/>
    </inertial>
    <!-- Part left_finger5_j1_parts -->
    <visual>
      <origin xyz="-0 0.0025 0" rpy="0 -1.5708 0"/>
      <geometry>
        <mesh filename="../meshes/left_finger5_j1_visual.stl"/>
      </geometry>
      <material name="left_finger5_j1_parts_material">
        <color rgba="0.231373 0.380392 0.705882 1"/>
      </material>
    </visual>
  </link>
  <!-- Link left_finger5_j2 -->
  <link name="left_finger5_j2">
    <inertial>
      <origin xyz="0 0.01 -0" rpy="0 0 0"/>
      <mass value="0.001984"/>
      <inertia ixx="8.2667e-08" ixy="-0" ixz="0" iyy="2.7115e-08" iyz="0" izz="7.6715e-08"/>
    </inertial>
    <!-- Part left_finger5_j2_parts -->
    <visual>
      <origin xyz="0 0.01 -0" rpy="0 -0 0"/>
      <geometry>
        <mesh filename="../meshes/left_finger5_j2_visual.stl"/>
      </geometry>
      <material name="left_finger5_j2_parts_material">
        <color rgba="0.768627 0.886275 0.952941 1"/>
      </material>
    </visual>
  </link>
  <!-- Link left_finger5_j3 -->
  <link name="left_finger5_j3">
    <inertial>
      <origin xyz="0 0.0075 0" rpy="0 0 0"/>
      <mass value="0.0008928"/>
      <inertia ixx="1.9418e-08" ixy="0" ixz="0" iyy="7.44e-09" iyz="0" izz="2.1502e-08"/>
    </inertial>
    <!-- Part left_finger5_j3_parts -->
    <visual>
      <origin xyz="0 0.0075 0" rpy="-0 -1.5708 0"/>
      <geometry>
        <mesh filename="../meshes/left_finger5_j3_visual.stl"/>
      </geometry>
      <material name="left_finger5_j3_parts_material">
        <color rgba="0.768627 0.886275 0.952941 1"/>
      </material>
    </visual>
  </link>
  <!-- Link left_finger5_j4 -->
  <link name="left_finger5_j4">
    <inertial>
      <origin xyz="-0.000432099 0.00438272 0" rpy="0 0 0"/>
      <mass value="0.0004185"/>
      <inertia ixx="3.877e-09" ixy="6.61e-10" ixz="-0" iyy="2.909e-09" iyz="0" izz="5.043e-09"/>
    </inertial>
    <!-- Part left_finger5_j4_parts -->
    <visual>
      <origin xyz="-0.000432099 0.00438272 0" rpy="0 -1.5708 0"/>
      <geometry>
        <mesh filename="../meshes/left_finger5_j4_visual.stl"/>
      </geometry>
      <material name="left_finger5_j4_parts_material">
        <color rgba="0.972549 0.529412 0.00392157 1"/>
      </material>
    </visual>
  </link>
  <!-- Frame left_finger5_tip (dummy link + fixed joint) -->
  <link name="left_finger5_tip">
    <origin xyz="0 0 0" rpy="0 -0 0"/>
    <inertial>
      <origin xyz="0 0 0" rpy="0 0 0"/>
      <mass value="1e-9"/>
      <inertia ixx="0" ixy="0" ixz="0" iyy="0" iyz="0" izz="0"/>
    </inertial>
  </link>
  <joint name="left_finger5_tip_frame" type="fixed">
    <origin xyz="0 0.01 0" rpy="-1.5708 -0 1.5708"/>
    <parent link="left_finger5_j4"/>
    <child link="left_finger5_tip"/>
    <axis xyz="0 0 0"/>
  </joint>
  <!-- Joint from left_finger5_j3 to left_finger5_j4 -->
  <joint name="left_finger5_j4" type="revolute">
    <origin xyz="0 0.02 0" rpy="0 -0 -0"/>
    <parent link="left_finger5_j3"/>
    <child link="left_finger5_j4"/>
    <axis xyz="0 0 1"/>
    <limit effort="100" velocity="100" lower="-1.5708" upper="0.0872665"/>
    <joint_properties friction="0.1"/>
  </joint>
  <!-- Joint from left_finger5_j2 to left_finger5_j3 -->
  <joint name="left_finger5_j3" type="revolute">
    <origin xyz="0 0.025 0" rpy="-0 1.5708 0"/>
    <parent link="left_finger5_j2"/>
    <child link="left_finger5_j3"/>
    <axis xyz="0 0 1"/>
    <limit effort="100" velocity="100" lower="-1.91986" upper="0.0872665"/>
    <joint_properties friction="0.1"/>
  </joint>
  <!-- Joint from left_finger5_j1 to left_finger5_j2 -->
  <joint name="left_finger5_j2" type="revolute">
    <origin xyz="0 0.01 0" rpy="0 -1.5708 0"/>
    <parent link="left_finger5_j1"/>
    <child link="left_finger5_j2"/>
    <axis xyz="0 0 1"/>
    <limit effort="100" velocity="100" lower="-0.349066" upper="0.349066"/>
    <joint_properties friction="0.1"/>
  </joint>
  <!-- Joint from left_hand to left_finger5_j1 -->
  <joint name="left_finger5_j1" type="revolute">
    <origin xyz="0 0.065 -0.03" rpy="0 0 -0"/>
    <parent link="left_hand"/>
    <child link="left_finger5_j1"/>
    <axis xyz="0 0 1"/>
    <limit effort="100" velocity="100" lower="-1.91986" upper="0.0872665"/>
    <joint_properties friction="0.1"/>
  </joint>
  <!-- Joint from left_wrist_roll to left_hand -->
  <joint name="left_wrist_pitch" type="revolute">
    <origin xyz="0 -0 0" rpy="0 1.5708 0"/>
    <parent link="left_wrist_roll"/>
    <child link="left_hand"/>
    <axis xyz="0 0 1"/>
    <limit effort="100" velocity="100" lower="-0.785398" upper="0.785398"/>
    <joint_properties friction="0.1"/>
  </joint>
  <!-- Joint from left_wrist_yaw to left_wrist_roll -->
  <joint name="left_wrist_roll" type="revolute">
    <origin xyz="-0 -0 -0.135" rpy="-1.5708 -0 0"/>
    <parent link="left_wrist_yaw"/>
    <child link="left_wrist_roll"/>
    <axis xyz="0 0 1"/>
    <limit effort="100" velocity="100" lower="-0.698132" upper="0.698132"/>
    <joint_properties friction="0.1"/>
  </joint>
  <!-- Joint from left_elbow_pitch to left_wrist_yaw -->
  <joint name="left_wrist_yaw" type="revolute">
    <origin xyz="-0.01 0.055 0" rpy="1.5708 0 0"/>
    <parent link="left_elbow_pitch"/>
    <child link="left_wrist_yaw"/>
    <axis xyz="0 0 1"/>
    <limit effort="100" velocity="100" lower="-1.5708" upper="1.5708"/>
    <joint_properties friction="0.1"/>
  </joint>
  <!-- Joint from left_shoulder_yaw to left_elbow_pitch -->
  <joint name="left_elbow_pitch" type="revolute">
    <origin xyz="0.01 0 -0.08" rpy="-1.5708 0 -0"/>
    <parent link="left_shoulder_yaw"/>
    <child link="left_elbow_pitch"/>
    <axis xyz="0 0 1"/>
    <limit effort="100" velocity="100" lower="-2.35619" upper="0"/>
    <joint_properties friction="0.1"/>
  </joint>
  <!-- Joint from left_shoulder_roll to left_shoulder_yaw -->
  <joint name="left_shoulder_yaw" type="revolute">
    <origin xyz="-0 0.12 0" rpy="1.5708 -1.5708 0"/>
    <parent link="left_shoulder_roll"/>
    <child link="left_shoulder_yaw"/>
    <axis xyz="0 0 1"/>
    <limit effort="100" velocity="100" lower="-1.5708" upper="1.5708"/>
    <joint_properties friction="0.1"/>
  </joint>
  <!-- Joint from left_shoulder_pitch to left_shoulder_roll -->
  <joint name="left_shoulder_roll" type="revolute">
    <origin xyz="0 0 0" rpy="1.5708 0.174533 1.5708"/>
    <parent link="left_shoulder_pitch"/>
    <child link="left_shoulder_roll"/>
    <axis xyz="0 0 1"/>
    <limit effort="100" velocity="100" lower="-1.5708" upper="1.91986"/>
    <joint_properties friction="0.1"/>
  </joint>
  <!-- Joint from chest to left_shoulder_pitch -->
  <joint name="left_shoulder_pitch" type="revolute">
    <origin xyz="-0 0.09 0.39" rpy="-1.39626 0 0"/>
    <parent link="chest"/>
    <child link="left_shoulder_pitch"/>
    <axis xyz="0 0 1"/>
    <limit effort="100" velocity="100" lower="-3.14159" upper="0.785398"/>
    <joint_properties friction="0.1"/>
  </joint>
  <!-- Link right_shoulder_pitch -->
  <link name="right_shoulder_pitch">
    <inertial>
      <origin xyz="6.27e-10 -0.00168619 0.00682299" rpy="0 0 0"/>
      <mass value="0.375"/>
      <inertia ixx="0.000232695" ixy="-7e-12" ixz="2e-12" iyy="0.000233203" iyz="1.40823e-05" izz="0.000199827"/>
    </inertial>
    <!-- Part right_shoulder_pitch_parts -->
    <visual>
      <origin xyz="6.27e-10 -0.00168619 0.00682299" rpy="1.74533 -0 0"/>
      <geometry>
        <mesh filename="../meshes/right_shoulder_pitch_visual.stl"/>
      </geometry>
      <material name="right_shoulder_pitch_parts_material">
        <color rgba="0.498039 0.498039 0.498039 1"/>
      </material>
    </visual>
  </link>
  <!-- Link right_shoulder_roll -->
  <link name="right_shoulder_roll">
    <inertial>
      <origin xyz="2.50093e-06 0.0799615 1.54345e-07" rpy="0 0 0"/>
      <mass value="0.41"/>
      <inertia ixx="0.000505034" ixy="5.8676e-08" ixz="1.9744e-08" iyy="0.000198231" iyz="3.008e-09" izz="0.000477617"/>
    </inertial>
    <!-- Part right_shoulder_roll_parts -->
    <visual>
      <origin xyz="2.50093e-06 0.0799615 1.54345e-07" rpy="3.14159 -1.5708 0"/>
      <geometry>
        <mesh filename="../meshes/right_shoulder_roll_visual.stl"/>
      </geometry>
      <material name="right_shoulder_roll_parts_material">
        <color rgba="0.862745 0.661119 0.124438 1"/>
      </material>
    </visual>
  </link>
  <!-- Link right_shoulder_yaw -->
  <link name="right_shoulder_yaw">
    <inertial>
      <origin xyz="0.00515641 2.57303e-07 -0.0554411" rpy="0 0 0"/>
      <mass value="0.416"/>
      <inertia ixx="0.000480531" ixy="1.235e-09" ixz="4.64697e-05" iyy="0.000484803" iyz="-5.174e-09" izz="0.00021421"/>
    </inertial>
    <!-- Part right_shoulder_yaw_parts -->
    <collision>
      <origin xyz="-0 0 0.03" rpy="-0 -0 -1.5708"/>
      <geometry>
        <cylinder length="0.08" radius="0.03"/>
      </geometry>
    </collision>
    <visual>
      <origin xyz="0.00515641 2.57303e-07 -0.0554411" rpy="1.5708 -0 0"/>
      <geometry>
        <mesh filename="../meshes/right_shoulder_yaw_visual.stl"/>
      </geometry>
      <material name="right_shoulder_yaw_parts_material">
        <color rgba="0.615686 0.811765 0.929412 1"/>
      </material>
    </visual>
  </link>
  <!-- Link right_elbow_pitch -->
  <link name="right_elbow_pitch">
    <inertial>
      <origin xyz="-0.00846033 0.0260389 8.87366e-07" rpy="0 0 0"/>
      <mass value="0.1"/>
      <inertia ixx="0.000107188" ixy="7.39689e-06" ixz="6.006e-09" iyy="8.53982e-05" iyz="-1.394e-09" izz="7.35763e-05"/>
    </inertial>
    <!-- Part right_elbow_pitch_parts -->
    <visual>
      <origin xyz="-0.00846033 0.0260389 8.87366e-07" rpy="3.14159 -0 -0"/>
      <geometry>
        <mesh filename="../meshes/right_elbow_pitch_visual.stl"/>
      </geometry>
      <material name="right_elbow_pitch_parts_material">
        <color rgba="0.647059 0.647059 0.647059 1"/>
      </material>
    </visual>
  </link>
  <!-- Link right_wrist_yaw -->
  <link name="right_wrist_yaw">
    <inertial>
      <origin xyz="1.15488e-07 0.000140175 -0.057929" rpy="0 0 0"/>
      <mass value="0.6"/>
      <inertia ixx="0.00091931" ixy="9.01e-10" ixz="5.741e-09" iyy="0.000910142" iyz="-9.05574e-06" izz="0.000298169"/>
    </inertial>
    <!-- Part right_wrist_yaw_parts -->
    <collision>
      <origin xyz="-0 -0 -0.035" rpy="-0 0 3.14159"/>
      <geometry>
        <cylinder length="0.08" radius="0.03"/>
      </geometry>
    </collision>
    <visual>
      <origin xyz="1.15488e-07 0.000140175 -0.057929" rpy="1.5708 0 0"/>
      <geometry>
        <mesh filename="../meshes/right_wrist_yaw_visual.stl"/>
      </geometry>
      <material name="right_wrist_yaw_parts_material">
        <color rgba="0.647059 0.647059 0.647059 1"/>
      </material>
    </visual>
  </link>
  <!-- Link right_wrist_roll -->
  <link name="right_wrist_roll">
    <inertial>
      <origin xyz="4.084e-09 -2e-12 -2.02e-10" rpy="0 0 0"/>
      <mass value="0.25"/>
      <inertia ixx="7.92688e-05" ixy="-0" ixz="0" iyy="9.19094e-05" iyz="2.493e-09" izz="9.04084e-05"/>
    </inertial>
    <!-- Part right_wrist_roll_parts -->
    <visual>
      <origin xyz="4.084e-09 -2e-12 -2.02e-10" rpy="3.14159 0 0"/>
      <geometry>
        <mesh filename="../meshes/right_wrist_roll_visual.stl"/>
      </geometry>
      <material name="right_wrist_roll_parts_material">
        <color rgba="0.231373 0.380392 0.705882 1"/>
      </material>
    </visual>
  </link>
  <!-- Link right_hand -->
  <link name="right_hand">
    <inertial>
      <origin xyz="2.5375e-08 0.0307394 -0.00396572" rpy="0 0 0"/>
      <mass value="0.0692787"/>
      <inertia ixx="5.76778e-05" ixy="5.8e-11" ixz="7.1e-11" iyy="3.73217e-05" iyz="4.15709e-06" izz="2.86548e-05"/>
    </inertial>
    <!-- Part right_hand_parts -->
    <collision>
      <origin xyz="0.03 0.07 -0" rpy="1.5708 -0 1.5708"/>
      <geometry>
        <box size="0.1 0.07 0.015"/>
      </geometry>
    </collision>
    <visual>
      <origin xyz="2.5375e-08 0.0307394 -0.00396572" rpy="3.14159 -1.5708 0"/>
      <geometry>
        <mesh filename="../meshes/right_hand_visual.stl"/>
      </geometry>
      <material name="right_hand_parts_material">
        <color rgba="0.804148 0.877849 0.922069 1"/>
      </material>
    </visual>
  </link>
  <!-- Link right_finger1_j1 -->
  <link name="right_finger1_j1">
    <inertial>
      <origin xyz="0 0.0025 -0" rpy="0 0 0"/>
      <mass value="0.000744"/>
      <inertia ixx="1.0478e-08" ixy="0" ixz="-0" iyy="1.5128e-08" iyz="0" izz="7.75e-09"/>
    </inertial>
    <!-- Part right_finger1_j1_parts -->
    <visual>
      <origin xyz="0 0.0025 -0" rpy="1.5708 -0.785398 1.5708"/>
      <geometry>
        <mesh filename="../meshes/right_finger1_j1_visual.stl"/>
      </geometry>
      <material name="right_finger1_j1_parts_material">
        <color rgba="0.498039 0.498039 0.498039 1"/>
      </material>
    </visual>
  </link>
  <!-- Link right_finger1_j2 -->
  <link name="right_finger1_j2">
    <inertial>
      <origin xyz="0 0.01 0" rpy="0 0 0"/>
      <mass value="0.002976"/>
      <inertia ixx="1.24e-07" ixy="0" ixz="0" iyy="6.0512e-08" iyz="-0" izz="1.34912e-07"/>
    </inertial>
    <!-- Part right_finger1_j2_parts -->
    <visual>
      <origin xyz="0 0.01 0" rpy="0 0 2.35619"/>
      <geometry>
        <mesh filename="../meshes/right_finger1_j2_visual.stl"/>
      </geometry>
      <material name="right_finger1_j2_parts_material">
        <color rgba="0.972549 0.529412 0.00392157 1"/>
      </material>
    </visual>
  </link>
  <!-- Link right_finger1_j3 -->
  <link name="right_finger1_j3">
    <inertial>
      <origin xyz="0 0.01 0" rpy="0 0 0"/>
      <mass value="0.001984"/>
      <inertia ixx="8.2667e-08" ixy="-0" ixz="-0" iyy="2.7115e-08" iyz="0" izz="7.6715e-08"/>
    </inertial>
    <!-- Part right_finger1_j3_parts -->
    <visual>
      <origin xyz="0 0.01 0" rpy="1.5708 -0.785398 1.5708"/>
      <geometry>
        <mesh filename="../meshes/right_finger1_j3_visual.stl"/>
      </geometry>
      <material name="right_finger1_j3_parts_material">
        <color rgba="0.498039 0.498039 0.498039 1"/>
      </material>
    </visual>
  </link>
  <!-- Link right_finger1_j4 -->
  <link name="right_finger1_j4">
    <inertial>
      <origin xyz="0.000271318 0.00682171 0" rpy="0 0 0"/>
      <mass value="0.001333"/>
      <inertia ixx="3.2905e-08" ixy="-2.247e-09" ixz="0" iyy="1.7887e-08" iyz="0" izz="2.8576e-08"/>
    </inertial>
    <!-- Part right_finger1_j4_parts -->
    <visual>
      <origin xyz="0.000271318 0.00682171 0" rpy="1.5708 -0.785398 1.5708"/>
      <geometry>
        <mesh filename="../meshes/right_finger1_j4_visual.stl"/>
      </geometry>
      <material name="right_finger1_j4_parts_material">
        <color rgba="0.980392 0.713725 0.00392157 1"/>
      </material>
    </visual>
  </link>
  <!-- Frame right_finger1_tip (dummy link + fixed joint) -->
  <link name="right_finger1_tip">
    <origin xyz="0 0 0" rpy="0 -0 0"/>
    <inertial>
      <origin xyz="0 0 0" rpy="0 0 0"/>
      <mass value="1e-9"/>
      <inertia ixx="0" ixy="0" ixz="0" iyy="0" iyz="0" izz="0"/>
    </inertial>
  </link>
  <joint name="right_finger1_tip_frame" type="fixed">
    <origin xyz="-0 0.015 0" rpy="1.5708 0 1.5708"/>
    <parent link="right_finger1_j4"/>
    <child link="right_finger1_tip"/>
    <axis xyz="0 0 0"/>
  </joint>
  <!-- Joint from right_finger1_j3 to right_finger1_j4 -->
  <joint name="right_finger1_j4" type="revolute">
    <origin xyz="-0 0.025 0" rpy="0 0 0"/>
    <parent link="right_finger1_j3"/>
    <child link="right_finger1_j4"/>
    <axis xyz="0 0 1"/>
    <limit effort="100" velocity="100" lower="-0.0872665" upper="1.5708"/>
    <joint_properties friction="0.1"/>
  </joint>
  <!-- Joint from right_finger1_j2 to right_finger1_j3 -->
  <joint name="right_finger1_j3" type="revolute">
    <origin xyz="0 0.025 -0" rpy="-0 -1.5708 0"/>
    <parent link="right_finger1_j2"/>
    <child link="right_finger1_j3"/>
    <axis xyz="0 0 1"/>
    <limit effort="100" velocity="100" lower="-0.0872665" upper="1.91986"/>
    <joint_properties friction="0.1"/>
  </joint>
  <!-- Joint from right_finger1_j1 to right_finger1_j2 -->
  <joint name="right_finger1_j2" type="revolute">
    <origin xyz="-0 0.01 0" rpy="-0 1.5708 0"/>
    <parent link="right_finger1_j1"/>
    <child link="right_finger1_j2"/>
    <axis xyz="0 0 1"/>
    <limit effort="100" velocity="100" lower="-0.349066" upper="0.349066"/>
    <joint_properties friction="0.1"/>
  </joint>
  <!-- Joint from right_hand to right_finger1_j1 -->
  <joint name="right_finger1_j1" type="revolute">
    <origin xyz="0 0.035 0.03" rpy="0.785398 0 -0"/>
    <parent link="right_hand"/>
    <child link="right_finger1_j1"/>
    <axis xyz="0 0 1"/>
    <limit effort="100" velocity="100" lower="0" upper="1.5708"/>
    <joint_properties friction="0.1"/>
  </joint>
  <!-- Link right_finger2_j1 -->
  <link name="right_finger2_j1">
    <inertial>
      <origin xyz="0 0.0025 0" rpy="0 0 0"/>
      <mass value="0.000496"/>
      <inertia ixx="3.679e-09" ixy="0" ixz="0" iyy="6.779e-09" iyz="0" izz="5.167e-09"/>
    </inertial>
    <!-- Part right_finger2_j1_parts -->
    <visual>
      <origin xyz="0 0.0025 0" rpy="3.14159 -1.5708 0"/>
      <geometry>
        <mesh filename="../meshes/right_finger2_j1_visual.stl"/>
      </geometry>
      <material name="right_finger2_j1_parts_material">
        <color rgba="0.980392 0.713725 0.00392157 1"/>
      </material>
    </visual>
  </link>
  <!-- Link right_finger2_j2 -->
  <link name="right_finger2_j2">
    <inertial>
      <origin xyz="-0 0.0125 -0" rpy="0 0 0"/>
      <mass value="0.00248"/>
      <inertia ixx="1.49833e-07" ixy="0" ixz="0" iyy="3.3893e-08" iyz="0" izz="1.42393e-07"/>
    </inertial>
    <!-- Part right_finger2_j2_parts -->
    <visual>
      <origin xyz="-0 0.0125 -0" rpy="-0 -0 3.14159"/>
      <geometry>
        <mesh filename="../meshes/right_finger2_j2_visual.stl"/>
      </geometry>
      <material name="right_finger2_j2_parts_material">
        <color rgba="0.647059 0.647059 0.647059 1"/>
      </material>
    </visual>
  </link>
  <!-- Link right_finger2_j3 -->
  <link name="right_finger2_j3">
    <inertial>
      <origin xyz="-0 0.01 -0" rpy="0 0 0"/>
      <mass value="0.0011904"/>
      <inertia ixx="4.3251e-08" ixy="-0" ixz="0" iyy="9.92e-09" iyz="-0" izz="4.6029e-08"/>
    </inertial>
    <!-- Part right_finger2_j3_parts -->
    <visual>
      <origin xyz="-0 0.01 -0" rpy="3.14159 -1.5708 0"/>
      <geometry>
        <mesh filename="../meshes/right_finger2_j3_visual.stl"/>
      </geometry>
      <material name="right_finger2_j3_parts_material">
        <color rgba="0.498039 0.498039 0.498039 1"/>
      </material>
    </visual>
  </link>
  <!-- Link right_finger2_j4 -->
  <link name="right_finger2_j4">
    <inertial>
      <origin xyz="0.000432099 0.00438272 -0" rpy="0 0 0"/>
      <mass value="0.0004185"/>
      <inertia ixx="3.877e-09" ixy="-6.61e-10" ixz="-0" iyy="2.909e-09" iyz="0" izz="5.043e-09"/>
    </inertial>
    <!-- Part right_finger2_j4_parts -->
    <visual>
      <origin xyz="0.000432099 0.00438272 -0" rpy="3.14159 -1.5708 0"/>
      <geometry>
        <mesh filename="../meshes/right_finger2_j4_visual.stl"/>
      </geometry>
      <material name="right_finger2_j4_parts_material">
        <color rgba="0.980392 0.713725 0.00392157 1"/>
      </material>
    </visual>
  </link>
  <!-- Frame right_finger2_tip (dummy link + fixed joint) -->
  <link name="right_finger2_tip">
    <origin xyz="0 0 0" rpy="0 -0 0"/>
    <inertial>
      <origin xyz="0 0 0" rpy="0 0 0"/>
      <mass value="1e-9"/>
      <inertia ixx="0" ixy="0" ixz="0" iyy="0" iyz="0" izz="0"/>
    </inertial>
  </link>
  <joint name="right_finger2_tip_frame" type="fixed">
    <origin xyz="-0 0.01 -0" rpy="1.5708 0 1.5708"/>
    <parent link="right_finger2_j4"/>
    <child link="right_finger2_tip"/>
    <axis xyz="0 0 0"/>
  </joint>
  <!-- Joint from right_finger2_j3 to right_finger2_j4 -->
  <joint name="right_finger2_j4" type="revolute">
    <origin xyz="-0 0.025 0" rpy="-0 -0 -0"/>
    <parent link="right_finger2_j3"/>
    <child link="right_finger2_j4"/>
    <axis xyz="0 0 1"/>
    <limit effort="100" velocity="100" lower="-0.0872665" upper="1.5708"/>
    <joint_properties friction="0.1"/>
  </joint>
  <!-- Joint from right_finger2_j2 to right_finger2_j3 -->
  <joint name="right_finger2_j3" type="revolute">
    <origin xyz="0 0.03 0" rpy="-0 -1.5708 0"/>
    <parent link="right_finger2_j2"/>
    <child link="right_finger2_j3"/>
    <axis xyz="0 0 1"/>
    <limit effort="100" velocity="100" lower="-0.0872665" upper="1.91986"/>
    <joint_properties friction="0.1"/>
  </joint>
  <!-- Joint from right_finger2_j1 to right_finger2_j2 -->
  <joint name="right_finger2_j2" type="revolute">
    <origin xyz="0 0.01 0" rpy="-0 1.5708 0"/>
    <parent link="right_finger2_j1"/>
    <child link="right_finger2_j2"/>
    <axis xyz="0 0 1"/>
    <limit effort="100" velocity="100" lower="-0.349066" upper="0.349066"/>
    <joint_properties friction="0.1"/>
  </joint>
  <!-- Joint from right_hand to right_finger2_j1 -->
  <joint name="right_finger2_j1" type="revolute">
    <origin xyz="-0 0.07 0.015" rpy="0 -0 0"/>
    <parent link="right_hand"/>
    <child link="right_finger2_j1"/>
    <axis xyz="0 0 1"/>
    <limit effort="100" velocity="100" lower="-0.0872665" upper="1.91986"/>
    <joint_properties friction="0.1"/>
  </joint>
  <!-- Link right_finger3_j1 -->
  <link name="right_finger3_j1">
    <inertial>
      <origin xyz="0 0.0025 -0" rpy="0 0 0"/>
      <mass value="0.000496"/>
      <inertia ixx="3.679e-09" ixy="0" ixz="-0" iyy="6.779e-09" iyz="0" izz="5.167e-09"/>
    </inertial>
    <!-- Part right_finger3_j1_parts -->
    <visual>
      <origin xyz="0 0.0025 -0" rpy="3.14159 -1.5708 0"/>
      <geometry>
        <mesh filename="../meshes/right_finger3_j1_visual.stl"/>
      </geometry>
      <material name="right_finger3_j1_parts_material">
        <color rgba="0.615686 0.811765 0.929412 1"/>
      </material>
    </visual>
  </link>
  <!-- Link right_finger3_j2 -->
  <link name="right_finger3_j2">
    <inertial>
      <origin xyz="0 0.015 0" rpy="0 0 0"/>
      <mass value="0.002976"/>
      <inertia ixx="2.48e-07" ixy="-0" ixz="0" iyy="4.0672e-08" iyz="0" izz="2.39072e-07"/>
    </inertial>
    <!-- Part right_finger3_j2_parts -->
    <visual>
      <origin xyz="0 0.015 0" rpy="0 -0 3.14159"/>
      <geometry>
        <mesh filename="../meshes/right_finger3_j2_visual.stl"/>
      </geometry>
      <material name="right_finger3_j2_parts_material">
        <color rgba="0.231373 0.380392 0.705882 1"/>
      </material>
    </visual>
  </link>
  <!-- Link right_finger3_j3 -->
  <link name="right_finger3_j3">
    <inertial>
      <origin xyz="-0 0.0125 0" rpy="0 0 0"/>
      <mass value="0.001488"/>
      <inertia ixx="8.1964e-08" ixy="-0" ixz="0" iyy="1.24e-08" iyz="-0" izz="8.5436e-08"/>
    </inertial>
    <!-- Part right_finger3_j3_parts -->
    <visual>
      <origin xyz="0 0.0125 0" rpy="3.14159 -1.5708 0"/>
      <geometry>
        <mesh filename="../meshes/right_finger3_j3_visual.stl"/>
      </geometry>
      <material name="right_finger3_j3_parts_material">
        <color rgba="0.615686 0.811765 0.929412 1"/>
      </material>
    </visual>
  </link>
  <!-- Link right_finger3_j4 -->
  <link name="right_finger3_j4">
    <inertial>
      <origin xyz="0.000432099 0.00438272 0" rpy="0 0 0"/>
      <mass value="0.0004185"/>
      <inertia ixx="3.877e-09" ixy="-6.61e-10" ixz="-0" iyy="2.909e-09" iyz="0" izz="5.043e-09"/>
    </inertial>
    <!-- Part right_finger3_j4_parts -->
    <visual>
      <origin xyz="0.000432099 0.00438272 0" rpy="3.14159 -1.5708 0"/>
      <geometry>
        <mesh filename="../meshes/right_finger3_j4_visual.stl"/>
      </geometry>
      <material name="right_finger3_j4_parts_material">
        <color rgba="0.647059 0.647059 0.647059 1"/>
      </material>
    </visual>
  </link>
  <!-- Frame right_finger3_tip (dummy link + fixed joint) -->
  <link name="right_finger3_tip">
    <origin xyz="0 0 0" rpy="0 -0 0"/>
    <inertial>
      <origin xyz="0 0 0" rpy="0 0 0"/>
      <mass value="1e-9"/>
      <inertia ixx="0" ixy="0" ixz="0" iyy="0" iyz="0" izz="0"/>
    </inertial>
  </link>
  <joint name="right_finger3_tip_frame" type="fixed">
    <origin xyz="-0 0.01 0" rpy="1.5708 -0 1.5708"/>
    <parent link="right_finger3_j4"/>
    <child link="right_finger3_tip"/>
    <axis xyz="0 0 0"/>
  </joint>
  <!-- Joint from right_finger3_j3 to right_finger3_j4 -->
  <joint name="right_finger3_j4" type="revolute">
    <origin xyz="0 0.03 -0" rpy="-0 0 0"/>
    <parent link="right_finger3_j3"/>
    <child link="right_finger3_j4"/>
    <axis xyz="0 0 1"/>
    <limit effort="100" velocity="100" lower="-0.0872665" upper="1.5708"/>
    <joint_properties friction="0.1"/>
  </joint>
  <!-- Joint from right_finger3_j2 to right_finger3_j3 -->
  <joint name="right_finger3_j3" type="revolute">
    <origin xyz="0 0.035 -0" rpy="0 -1.5708 0"/>
    <parent link="right_finger3_j2"/>
    <child link="right_finger3_j3"/>
    <axis xyz="0 0 1"/>
    <limit effort="100" velocity="100" lower="-0.0872665" upper="1.91986"/>
    <joint_properties friction="0.1"/>
  </joint>
  <!-- Joint from right_finger3_j1 to right_finger3_j2 -->
  <joint name="right_finger3_j2" type="revolute">
    <origin xyz="-0 0.01 0" rpy="0 1.5708 0"/>
    <parent link="right_finger3_j1"/>
    <child link="right_finger3_j2"/>
    <axis xyz="0 0 1"/>
    <limit effort="100" velocity="100" lower="-0.349066" upper="0.349066"/>
    <joint_properties friction="0.1"/>
  </joint>
  <!-- Joint from right_hand to right_finger3_j1 -->
  <joint name="right_finger3_j1" type="revolute">
    <origin xyz="0 0.075 0" rpy="0 -0 -0"/>
    <parent link="right_hand"/>
    <child link="right_finger3_j1"/>
    <axis xyz="0 0 1"/>
    <limit effort="100" velocity="100" lower="-0.0872665" upper="1.91986"/>
    <joint_properties friction="0.1"/>
  </joint>
  <!-- Link right_finger4_j1 -->
  <link name="right_finger4_j1">
    <inertial>
      <origin xyz="0 0.0025 0" rpy="0 0 0"/>
      <mass value="0.000496"/>
      <inertia ixx="3.679e-09" ixy="0" ixz="-0" iyy="6.779e-09" iyz="-0" izz="5.167e-09"/>
    </inertial>
    <!-- Part right_finger4_j1_parts -->
    <visual>
      <origin xyz="0 0.0025 0" rpy="3.14159 -1.5708 0"/>
      <geometry>
        <mesh filename="../meshes/right_finger4_j1_visual.stl"/>
      </geometry>
      <material name="right_finger4_j1_parts_material">
        <color rgba="0.647059 0.647059 0.647059 1"/>
      </material>
    </visual>
  </link>
  <!-- Link right_finger4_j2 -->
  <link name="right_finger4_j2">
    <inertial>
      <origin xyz="-0 0.015 0" rpy="0 0 0"/>
      <mass value="0.002976"/>
      <inertia ixx="2.48e-07" ixy="-0" ixz="-0" iyy="4.0672e-08" iyz="-0" izz="2.39072e-07"/>
    </inertial>
    <!-- Part right_finger4_j2_parts -->
    <visual>
      <origin xyz="-0 0.015 -0" rpy="-0 -0 3.14159"/>
      <geometry>
        <mesh filename="../meshes/right_finger4_j2_visual.stl"/>
      </geometry>
      <material name="right_finger4_j2_parts_material">
        <color rgba="0.917647 0.917647 0.917647 1"/>
      </material>
    </visual>
  </link>
  <!-- Link right_finger4_j3 -->
  <link name="right_finger4_j3">
    <inertial>
      <origin xyz="0 0.01 0" rpy="0 0 0"/>
      <mass value="0.0011904"/>
      <inertia ixx="4.3251e-08" ixy="0" ixz="0" iyy="9.92e-09" iyz="0" izz="4.6029e-08"/>
    </inertial>
    <!-- Part right_finger4_j3_parts -->
    <visual>
      <origin xyz="0 0.01 0" rpy="3.14159 -1.5708 0"/>
      <geometry>
        <mesh filename="../meshes/right_finger4_j3_visual.stl"/>
      </geometry>
      <material name="right_finger4_j3_parts_material">
        <color rgba="0.231373 0.380392 0.705882 1"/>
      </material>
    </visual>
  </link>
  <!-- Link right_finger4_j4 -->
  <link name="right_finger4_j4">
    <inertial>
      <origin xyz="0.000432099 0.00438272 0" rpy="0 0 0"/>
      <mass value="0.0004185"/>
      <inertia ixx="3.877e-09" ixy="-6.61e-10" ixz="0" iyy="2.909e-09" iyz="0" izz="5.043e-09"/>
    </inertial>
    <!-- Part right_finger4_j4_parts -->
    <visual>
      <origin xyz="0.000432099 0.00438272 0" rpy="3.14159 -1.5708 0"/>
      <geometry>
        <mesh filename="../meshes/right_finger4_j4_visual.stl"/>
      </geometry>
      <material name="right_finger4_j4_parts_material">
        <color rgba="0.917647 0.917647 0.917647 1"/>
      </material>
    </visual>
  </link>
  <!-- Frame right_finger4_tip (dummy link + fixed joint) -->
  <link name="right_finger4_tip">
    <origin xyz="0 0 0" rpy="0 -0 0"/>
    <inertial>
      <origin xyz="0 0 0" rpy="0 0 0"/>
      <mass value="1e-9"/>
      <inertia ixx="0" ixy="0" ixz="0" iyy="0" iyz="0" izz="0"/>
    </inertial>
  </link>
  <joint name="right_finger4_tip_frame" type="fixed">
    <origin xyz="-0 0.01 0" rpy="1.5708 0 1.5708"/>
    <parent link="right_finger4_j4"/>
    <child link="right_finger4_tip"/>
    <axis xyz="0 0 0"/>
  </joint>
  <!-- Joint from right_finger4_j3 to right_finger4_j4 -->
  <joint name="right_finger4_j4" type="revolute">
    <origin xyz="0 0.025 0" rpy="-0 0 0"/>
    <parent link="right_finger4_j3"/>
    <child link="right_finger4_j4"/>
    <axis xyz="0 0 1"/>
    <limit effort="100" velocity="100" lower="-0.0872665" upper="1.5708"/>
    <joint_properties friction="0.1"/>
  </joint>
  <!-- Joint from right_finger4_j2 to right_finger4_j3 -->
  <joint name="right_finger4_j3" type="revolute">
    <origin xyz="0 0.035 0" rpy="-0 -1.5708 0"/>
    <parent link="right_finger4_j2"/>
    <child link="right_finger4_j3"/>
    <axis xyz="0 0 1"/>
    <limit effort="100" velocity="100" lower="-0.0872665" upper="1.91986"/>
    <joint_properties friction="0.1"/>
  </joint>
  <!-- Joint from right_finger4_j1 to right_finger4_j2 -->
  <joint name="right_finger4_j2" type="revolute">
    <origin xyz="0 0.01 0" rpy="-0 1.5708 0"/>
    <parent link="right_finger4_j1"/>
    <child link="right_finger4_j2"/>
    <axis xyz="0 0 1"/>
    <limit effort="100" velocity="100" lower="-0.349066" upper="0.349066"/>
    <joint_properties friction="0.1"/>
  </joint>
  <!-- Joint from right_hand to right_finger4_j1 -->
  <joint name="right_finger4_j1" type="revolute">
    <origin xyz="-0 0.07 -0.015" rpy="0 -0 -0"/>
    <parent link="right_hand"/>
    <child link="right_finger4_j1"/>
    <axis xyz="0 0 1"/>
    <limit effort="100" velocity="100" lower="-0.0872665" upper="1.91986"/>
    <joint_properties friction="0.1"/>
  </joint>
  <!-- Link right_finger5_j1 -->
  <link name="right_finger5_j1">
    <inertial>
      <origin xyz="-0 0.0025 -0" rpy="0 0 0"/>
      <mass value="0.000496"/>
      <inertia ixx="3.679e-09" ixy="-0" ixz="-0" iyy="6.779e-09" iyz="0" izz="5.167e-09"/>
    </inertial>
    <!-- Part right_finger5_j1_parts -->
    <visual>
      <origin xyz="-0 0.0025 -0" rpy="3.14159 -1.5708 0"/>
      <geometry>
        <mesh filename="../meshes/right_finger5_j1_visual.stl"/>
      </geometry>
      <material name="right_finger5_j1_parts_material">
        <color rgba="0.231373 0.380392 0.705882 1"/>
      </material>
    </visual>
  </link>
  <!-- Link right_finger5_j2 -->
  <link name="right_finger5_j2">
    <inertial>
      <origin xyz="0 0.01 -0" rpy="0 0 0"/>
      <mass value="0.001984"/>
      <inertia ixx="8.2667e-08" ixy="-0" ixz="0" iyy="2.7115e-08" iyz="-0" izz="7.6715e-08"/>
    </inertial>
    <!-- Part right_finger5_j2_parts -->
    <visual>
      <origin xyz="0 0.01 -0" rpy="0 -0 3.14159"/>
      <geometry>
        <mesh filename="../meshes/right_finger5_j2_visual.stl"/>
      </geometry>
      <material name="right_finger5_j2_parts_material">
        <color rgba="0.768627 0.886275 0.952941 1"/>
      </material>
    </visual>
  </link>
  <!-- Link right_finger5_j3 -->
  <link name="right_finger5_j3">
    <inertial>
      <origin xyz="-0 0.0075 0" rpy="0 0 0"/>
      <mass value="0.0008928"/>
      <inertia ixx="1.9418e-08" ixy="0" ixz="-0" iyy="7.44e-09" iyz="0" izz="2.1502e-08"/>
    </inertial>
    <!-- Part right_finger5_j3_parts -->
    <visual>
      <origin xyz="-0 0.0075 0" rpy="3.14159 -1.5708 0"/>
      <geometry>
        <mesh filename="../meshes/right_finger5_j3_visual.stl"/>
      </geometry>
      <material name="right_finger5_j3_parts_material">
        <color rgba="0.768627 0.886275 0.952941 1"/>
      </material>
    </visual>
  </link>
  <!-- Link right_finger5_j4 -->
  <link name="right_finger5_j4">
    <inertial>
      <origin xyz="0.000432099 0.00438272 0" rpy="0 0 0"/>
      <mass value="0.0004185"/>
      <inertia ixx="3.877e-09" ixy="-6.61e-10" ixz="-0" iyy="2.909e-09" iyz="-0" izz="5.043e-09"/>
    </inertial>
    <!-- Part right_finger5_j4_parts -->
    <visual>
      <origin xyz="0.000432099 0.00438272 0" rpy="3.14159 -1.5708 0"/>
      <geometry>
        <mesh filename="../meshes/right_finger5_j4_visual.stl"/>
      </geometry>
      <material name="right_finger5_j4_parts_material">
        <color rgba="0.972549 0.529412 0.00392157 1"/>
      </material>
    </visual>
  </link>
  <!-- Frame right_finger5_tip (dummy link + fixed joint) -->
  <link name="right_finger5_tip">
    <origin xyz="0 0 0" rpy="0 -0 0"/>
    <inertial>
      <origin xyz="0 0 0" rpy="0 0 0"/>
      <mass value="1e-9"/>
      <inertia ixx="0" ixy="0" ixz="0" iyy="0" iyz="0" izz="0"/>
    </inertial>
  </link>
  <joint name="right_finger5_tip_frame" type="fixed">
    <origin xyz="-0 0.01 0" rpy="1.5708 0 1.5708"/>
    <parent link="right_finger5_j4"/>
    <child link="right_finger5_tip"/>
    <axis xyz="0 0 0"/>
  </joint>
  <!-- Joint from right_finger5_j3 to right_finger5_j4 -->
  <joint name="right_finger5_j4" type="revolute">
    <origin xyz="0 0.02 0" rpy="-0 -0 0"/>
    <parent link="right_finger5_j3"/>
    <child link="right_finger5_j4"/>
    <axis xyz="0 0 1"/>
    <limit effort="100" velocity="100" lower="-0.0872665" upper="1.5708"/>
    <joint_properties friction="0.1"/>
  </joint>
  <!-- Joint from right_finger5_j2 to right_finger5_j3 -->
  <joint name="right_finger5_j3" type="revolute">
    <origin xyz="0 0.025 -0" rpy="0 -1.5708 0"/>
    <parent link="right_finger5_j2"/>
    <child link="right_finger5_j3"/>
    <axis xyz="0 0 1"/>
    <limit effort="100" velocity="100" lower="-0.0872665" upper="1.91986"/>
    <joint_properties friction="0.1"/>
  </joint>
  <!-- Joint from right_finger5_j1 to right_finger5_j2 -->
  <joint name="right_finger5_j2" type="revolute">
    <origin xyz="0 0.01 0" rpy="-0 1.5708 0"/>
    <parent link="right_finger5_j1"/>
    <child link="right_finger5_j2"/>
    <axis xyz="0 0 1"/>
    <limit effort="100" velocity="100" lower="-0.349066" upper="0.349066"/>
    <joint_properties friction="0.1"/>
  </joint>
  <!-- Joint from right_hand to right_finger5_j1 -->
  <joint name="right_finger5_j1" type="revolute">
    <origin xyz="0 0.065 -0.03" rpy="0 -0 0"/>
    <parent link="right_hand"/>
    <child link="right_finger5_j1"/>
    <axis xyz="0 0 1"/>
    <limit effort="100" velocity="100" lower="-0.0872665" upper="1.91986"/>
    <joint_properties friction="0.1"/>
  </joint>
  <!-- Joint from right_wrist_roll to right_hand -->
  <joint name="right_wrist_pitch" type="revolute">
    <origin xyz="0 0 0" rpy="0 1.5708 0"/>
    <parent link="right_wrist_roll"/>
    <child link="right_hand"/>
    <axis xyz="0 0 1"/>
    <limit effort="100" velocity="100" lower="-0.785398" upper="0.785398"/>
    <joint_properties friction="0.1"/>
  </joint>
  <!-- Joint from right_wrist_yaw to right_wrist_roll -->
  <joint name="right_wrist_roll" type="revolute">
    <origin xyz="-0 0 -0.135" rpy="-1.5708 -0 0"/>
    <parent link="right_wrist_yaw"/>
    <child link="right_wrist_roll"/>
    <axis xyz="0 0 1"/>
    <limit effort="100" velocity="100" lower="-0.698132" upper="0.698132"/>
    <joint_properties friction="0.1"/>
  </joint>
  <!-- Joint from right_elbow_pitch to right_wrist_yaw -->
  <joint name="right_wrist_yaw" type="revolute">
    <origin xyz="-0.01 0.055 -0" rpy="1.5708 0 -0"/>
    <parent link="right_elbow_pitch"/>
    <child link="right_wrist_yaw"/>
    <axis xyz="0 0 1"/>
    <limit effort="100" velocity="100" lower="-1.5708" upper="1.5708"/>
    <joint_properties friction="0.1"/>
  </joint>
  <!-- Joint from right_shoulder_yaw to right_elbow_pitch -->
  <joint name="right_elbow_pitch" type="revolute">
    <origin xyz="0.01 0 -0.08" rpy="-1.5708 -0 0"/>
    <parent link="right_shoulder_yaw"/>
    <child link="right_elbow_pitch"/>
    <axis xyz="0 0 1"/>
    <limit effort="100" velocity="100" lower="-2.35619" upper="0"/>
    <joint_properties friction="0.1"/>
  </joint>
  <!-- Joint from right_shoulder_roll to right_shoulder_yaw -->
  <joint name="right_shoulder_yaw" type="revolute">
    <origin xyz="0 0.12 -0" rpy="1.5708 -1.5708 0"/>
    <parent link="right_shoulder_roll"/>
    <child link="right_shoulder_yaw"/>
    <axis xyz="0 0 1"/>
    <limit effort="100" velocity="100" lower="-1.5708" upper="1.5708"/>
    <joint_properties friction="0.1"/>
  </joint>
  <!-- Joint from right_shoulder_pitch to right_shoulder_roll -->
  <joint name="right_shoulder_roll" type="revolute">
    <origin xyz="-0 0 0" rpy="-1.5708 0.174533 -1.5708"/>
    <parent link="right_shoulder_pitch"/>
    <child link="right_shoulder_roll"/>
    <axis xyz="0 0 1"/>
    <limit effort="100" velocity="100" lower="-1.91986" upper="1.5708"/>
    <joint_properties friction="0.1"/>
  </joint>
  <!-- Joint from chest to right_shoulder_pitch -->
  <joint name="right_shoulder_pitch" type="revolute">
    <origin xyz="0 -0.09 0.39" rpy="-1.74533 -0 -0"/>
    <parent link="chest"/>
    <child link="right_shoulder_pitch"/>
    <axis xyz="0 0 1"/>
    <limit effort="100" velocity="100" lower="-3.14159" upper="0.785398"/>
    <joint_properties friction="0.1"/>
  </joint>
  <!-- Link neck_yaw -->
  <link name="neck_yaw">
    <inertial>
      <origin xyz="-0 -0 0.03" rpy="0 0 0"/>
      <mass value="0.0779115"/>
      <inertia ixx="1.55823e-05" ixy="0" ixz="-0" iyy="2.40227e-05" iyz="-0" izz="2.40227e-05"/>
    </inertial>
    <!-- Part neck_yaw_parts -->
    <visual>
      <origin xyz="0 -0 0.03" rpy="-0 0 -0"/>
      <geometry>
        <mesh filename="../meshes/neck_yaw_visual.stl"/>
      </geometry>
      <material name="neck_yaw_parts_material">
        <color rgba="0.647059 0.647059 0.647059 1"/>
      </material>
    </visual>
  </link>
  <!-- Link neck_roll -->
  <link name="neck_roll">
    <inertial>
      <origin xyz="0 0.03 -0" rpy="0 0 0"/>
      <mass value="0.0779115"/>
      <inertia ixx="1.55823e-05" ixy="-0" ixz="0" iyy="2.40227e-05" iyz="-0" izz="2.40227e-05"/>
    </inertial>
    <!-- Part neck_roll_parts -->
    <visual>
      <origin xyz="0 0.03 -0" rpy="-1.5708 -1.5708 0"/>
      <geometry>
        <mesh filename="../meshes/neck_roll_visual.stl"/>
      </geometry>
      <material name="neck_roll_parts_material">
        <color rgba="0.231373 0.380392 0.705882 1"/>
      </material>
    </visual>
  </link>
  <!-- Link head -->
  <link name="head">
    <inertial>
      <origin xyz="0.00134973 0.0584846 -5.43e-10" rpy="0 0 0"/>
      <mass value="4.7098"/>
      <inertia ixx="0.0192792" ixy="-0.00180799" ixz="-7.2e-11" iyy="0.0157942" iyz="-3e-11" izz="0.0201095"/>
    </inertial>
    <!-- Part head_parts -->
    <collision>
      <origin xyz="-0 0.05 -0" rpy="-1.5708 -1.5708 0"/>
      <geometry>
        <cylinder length="0.03" radius="0.09"/>
      </geometry>
    </collision>
    <visual>
      <origin xyz="0.00134973 0.0584846 -5.43e-10" rpy="1.5708 -0 -3.14159"/>
      <geometry>
        <mesh filename="../meshes/head_visual.stl"/>
      </geometry>
      <material name="head_parts_material">
        <color rgba="0.980392 0.713725 0.00392157 1"/>
      </material>
    </visual>
  </link>
  <!-- Joint from neck_roll to head -->
  <joint name="neck_pitch" type="revolute">
    <origin xyz="-0 0.03 0" rpy="-0 1.5708 0"/>
    <parent link="neck_roll"/>
    <child link="head"/>
    <axis xyz="0 0 1"/>
    <limit effort="100" velocity="100" lower="-0.523599" upper="0.523599"/>
    <joint_properties friction="0.1"/>
  </joint>
  <!-- Joint from neck_yaw to neck_roll -->
  <joint name="neck_roll" type="revolute">
    <origin xyz="0 0 0.03" rpy="1.5708 0 1.5708"/>
    <parent link="neck_yaw"/>
    <child link="neck_roll"/>
    <axis xyz="0 0 1"/>
    <limit effort="100" velocity="100" lower="-0.523599" upper="0.523599"/>
    <joint_properties friction="0.1"/>
  </joint>
  <!-- Joint from chest to neck_yaw -->
  <joint name="neck_yaw" type="revolute">
    <origin xyz="-0.01 -0 0.45" rpy="0 -0 0"/>
    <parent link="chest"/>
    <child link="neck_yaw"/>
    <axis xyz="0 0 1"/>
    <limit effort="100" velocity="100" lower="-0.785398" upper="0.785398"/>
    <joint_properties friction="0.1"/>
  </joint>
</robot>
