<?xml version="1.0" encoding="utf-8"?>
<robot name="piano_dep20">
  <material name="white">
    <color rgba="0.9 0.9 0.9 1" />
  </material>
  <material name="black">
    <color rgba="0.1 0.1 0.1 1" />
  </material>

  <!-- Base link -->
  <link name="base">
  </link>

  <!-- Piano body -->
  <link name="body">
    <visual>
      <origin xyz="-0.06 0 -0.05000000000000002" rpy="0 0 0" />
      <geometry>
        <box size="0.12 1.32 0.18" />
      </geometry>
    </visual>
    <visual>
      <origin xyz="0.027499999999999997 0 -0.081" rpy="0 0 0" />
      <geometry>
         <box size="0.295 1.32 0.11800000000000002" />
      </geometry>
    </visual>
    <collision>
      <origin xyz="-0.06 0 -0.05000000000000002" rpy="0 0 0" />
      <geometry>
         <box size="0.12 1.32 0.18" />
      </geometry>
    </collision>
    <collision>
      <origin xyz="0.027499999999999997 0 -0.081" rpy="0 0 0" />
      <geometry>
         <box size="0.295 1.32 0.11800000000000002" />
      </geometry>
    </collision>
    <inertial>
      <origin xyz="-0.06 0 -0.05000000000000002" rpy="0 0 0" />
      <mass value="10.0" />
      <inertia ixx="0.1" ixy="0.0" ixz="0.0" iyy="0.1" iyz="0.0" izz="0.1" />
    </inertial>
  </link>

  <joint name="base_body_joint" type="fixed">
    <parent link="base" />
    <child link="body" />
    <origin xyz="0 0 0" rpy="0 0 0" />
  </joint>

  <link name="white_key_0">
    <visual>
      <origin xyz="0.115 0 0" rpy="0 0 0" />
      <geometry>
        <box size="0.15 0.022 0.022" />
      </geometry>
      <material name="white" />
    </visual>
    <collision>
      <origin xyz="0.115 0 0" rpy="0 0 0" />
      <geometry>
        <box size="0.15 0.022 0.022" />
      </geometry>
    </collision>
    <inertial>
      <origin xyz="0.115 0 0" rpy="0 0 0" />
      <mass value="0.04" />
      <inertia ixx="3.226666666666666e-06" ixy="0.0" ixz="0.0" iyy="7.661333333333333e-05" iyz="0.0" izz="7.661333333333333e-05" />
    </inertial>
  </link>

  <joint name="white_joint_0" type="revolute">
    <parent link="base" />
    <child link="white_key_0" />
    <origin xyz="-0.04000000000000001 -0.5864999999999999 -0.011" rpy="0 0 0" />
    <axis xyz="0 1 0" />
    <limit lower="0" upper="0.06307411789691225" effort="0.3" velocity="6.67" />
  </joint>

  <link name="black_key_1">
    <visual>
      <origin xyz="0.075 0 0" rpy="0 0 0" />
      <geometry>
        <box size="0.09 0.01 0.018" />
      </geometry>
      <material name="black" />
    </visual>
    <collision>
      <origin xyz="0.075 0 0" rpy="0 0 0" />
      <geometry>
        <box size="0.09 0.01 0.018" />
      </geometry>
    </collision>
    <inertial>
      <origin xyz="0.075 0 0" rpy="0 0 0" />
      <mass value="0.02" />
      <inertia ixx="7.066666666666665e-07" ixy="0.0" ixz="0.0" iyy="1.404e-05" iyz="0.0" izz="1.3666666666666664e-05" />
    </inertial>
  </link>

  <joint name="black_joint_1" type="revolute">
    <parent link="base" />
    <child link="black_key_1" />
    <origin xyz="-0.03 -0.575 0.0035000000000000014" rpy="0 0 0" />
    <axis xyz="0 1 0" />
    <limit lower="0" upper="0.06656816377582381" effort="0.3" velocity="6.67" />
  </joint>

  <link name="white_key_2">
    <visual>
      <origin xyz="0.115 0 0" rpy="0 0 0" />
      <geometry>
        <box size="0.15 0.022 0.022" />
      </geometry>
      <material name="white" />
    </visual>
    <collision>
      <origin xyz="0.115 0 0" rpy="0 0 0" />
      <geometry>
        <box size="0.15 0.022 0.022" />
      </geometry>
    </collision>
    <inertial>
      <origin xyz="0.115 0 0" rpy="0 0 0" />
      <mass value="0.04" />
      <inertia ixx="3.226666666666666e-06" ixy="0.0" ixz="0.0" iyy="7.661333333333333e-05" iyz="0.0" izz="7.661333333333333e-05" />
    </inertial>
  </link>

  <joint name="white_joint_2" type="revolute">
    <parent link="base" />
    <child link="white_key_2" />
    <origin xyz="-0.04000000000000001 -0.5634999999999999 -0.011" rpy="0 0 0" />
    <axis xyz="0 1 0" />
    <limit lower="0" upper="0.06307411789691225" effort="0.3" velocity="6.67" />
  </joint>

  <link name="white_key_3">
    <visual>
      <origin xyz="0.115 0 0" rpy="0 0 0" />
      <geometry>
        <box size="0.15 0.022 0.022" />
      </geometry>
      <material name="white" />
    </visual>
    <collision>
      <origin xyz="0.115 0 0" rpy="0 0 0" />
      <geometry>
        <box size="0.15 0.022 0.022" />
      </geometry>
    </collision>
    <inertial>
      <origin xyz="0.115 0 0" rpy="0 0 0" />
      <mass value="0.04" />
      <inertia ixx="3.226666666666666e-06" ixy="0.0" ixz="0.0" iyy="7.661333333333333e-05" iyz="0.0" izz="7.661333333333333e-05" />
    </inertial>
  </link>

  <joint name="white_joint_3" type="revolute">
    <parent link="base" />
    <child link="white_key_3" />
    <origin xyz="-0.04000000000000001 -0.5404999999999999 -0.011" rpy="0 0 0" />
    <axis xyz="0 1 0" />
    <limit lower="0" upper="0.06307411789691225" effort="0.3" velocity="6.67" />
  </joint>

  <link name="black_key_4">
    <visual>
      <origin xyz="0.075 0 0" rpy="0 0 0" />
      <geometry>
        <box size="0.09 0.01 0.018" />
      </geometry>
      <material name="black" />
    </visual>
    <collision>
      <origin xyz="0.075 0 0" rpy="0 0 0" />
      <geometry>
        <box size="0.09 0.01 0.018" />
      </geometry>
    </collision>
    <inertial>
      <origin xyz="0.075 0 0" rpy="0 0 0" />
      <mass value="0.02" />
      <inertia ixx="7.066666666666665e-07" ixy="0.0" ixz="0.0" iyy="1.404e-05" iyz="0.0" izz="1.3666666666666664e-05" />
    </inertial>
  </link>

  <joint name="black_joint_4" type="revolute">
    <parent link="base" />
    <child link="black_key_4" />
    <origin xyz="-0.03 -0.5284999999999999 0.0035000000000000014" rpy="0 0 0" />
    <axis xyz="0 1 0" />
    <limit lower="0" upper="0.06656816377582381" effort="0.3" velocity="6.67" />
  </joint>

  <link name="white_key_5">
    <visual>
      <origin xyz="0.115 0 0" rpy="0 0 0" />
      <geometry>
        <box size="0.15 0.022 0.022" />
      </geometry>
      <material name="white" />
    </visual>
    <collision>
      <origin xyz="0.115 0 0" rpy="0 0 0" />
      <geometry>
        <box size="0.15 0.022 0.022" />
      </geometry>
    </collision>
    <inertial>
      <origin xyz="0.115 0 0" rpy="0 0 0" />
      <mass value="0.04" />
      <inertia ixx="3.226666666666666e-06" ixy="0.0" ixz="0.0" iyy="7.661333333333333e-05" iyz="0.0" izz="7.661333333333333e-05" />
    </inertial>
  </link>

  <joint name="white_joint_5" type="revolute">
    <parent link="base" />
    <child link="white_key_5" />
    <origin xyz="-0.04000000000000001 -0.5174999999999998 -0.011" rpy="0 0 0" />
    <axis xyz="0 1 0" />
    <limit lower="0" upper="0.06307411789691225" effort="0.3" velocity="6.67" />
  </joint>

  <link name="black_key_6">
    <visual>
      <origin xyz="0.075 0 0" rpy="0 0 0" />
      <geometry>
        <box size="0.09 0.01 0.018" />
      </geometry>
      <material name="black" />
    </visual>
    <collision>
      <origin xyz="0.075 0 0" rpy="0 0 0" />
      <geometry>
        <box size="0.09 0.01 0.018" />
      </geometry>
    </collision>
    <inertial>
      <origin xyz="0.075 0 0" rpy="0 0 0" />
      <mass value="0.02" />
      <inertia ixx="7.066666666666665e-07" ixy="0.0" ixz="0.0" iyy="1.404e-05" iyz="0.0" izz="1.3666666666666664e-05" />
    </inertial>
  </link>

  <joint name="black_joint_6" type="revolute">
    <parent link="base" />
    <child link="black_key_6" />
    <origin xyz="-0.03 -0.5054999999999998 0.0035000000000000014" rpy="0 0 0" />
    <axis xyz="0 1 0" />
    <limit lower="0" upper="0.06656816377582381" effort="0.3" velocity="6.67" />
  </joint>

  <link name="white_key_7">
    <visual>
      <origin xyz="0.115 0 0" rpy="0 0 0" />
      <geometry>
        <box size="0.15 0.022 0.022" />
      </geometry>
      <material name="white" />
    </visual>
    <collision>
      <origin xyz="0.115 0 0" rpy="0 0 0" />
      <geometry>
        <box size="0.15 0.022 0.022" />
      </geometry>
    </collision>
    <inertial>
      <origin xyz="0.115 0 0" rpy="0 0 0" />
      <mass value="0.04" />
      <inertia ixx="3.226666666666666e-06" ixy="0.0" ixz="0.0" iyy="7.661333333333333e-05" iyz="0.0" izz="7.661333333333333e-05" />
    </inertial>
  </link>

  <joint name="white_joint_7" type="revolute">
    <parent link="base" />
    <child link="white_key_7" />
    <origin xyz="-0.04000000000000001 -0.49449999999999994 -0.011" rpy="0 0 0" />
    <axis xyz="0 1 0" />
    <limit lower="0" upper="0.06307411789691225" effort="0.3" velocity="6.67" />
  </joint>

  <link name="white_key_8">
    <visual>
      <origin xyz="0.115 0 0" rpy="0 0 0" />
      <geometry>
        <box size="0.15 0.022 0.022" />
      </geometry>
      <material name="white" />
    </visual>
    <collision>
      <origin xyz="0.115 0 0" rpy="0 0 0" />
      <geometry>
        <box size="0.15 0.022 0.022" />
      </geometry>
    </collision>
    <inertial>
      <origin xyz="0.115 0 0" rpy="0 0 0" />
      <mass value="0.04" />
      <inertia ixx="3.226666666666666e-06" ixy="0.0" ixz="0.0" iyy="7.661333333333333e-05" iyz="0.0" izz="7.661333333333333e-05" />
    </inertial>
  </link>

  <joint name="white_joint_8" type="revolute">
    <parent link="base" />
    <child link="white_key_8" />
    <origin xyz="-0.04000000000000001 -0.4714999999999999 -0.011" rpy="0 0 0" />
    <axis xyz="0 1 0" />
    <limit lower="0" upper="0.06307411789691225" effort="0.3" velocity="6.67" />
  </joint>

  <link name="black_key_9">
    <visual>
      <origin xyz="0.075 0 0" rpy="0 0 0" />
      <geometry>
        <box size="0.09 0.01 0.018" />
      </geometry>
      <material name="black" />
    </visual>
    <collision>
      <origin xyz="0.075 0 0" rpy="0 0 0" />
      <geometry>
        <box size="0.09 0.01 0.018" />
      </geometry>
    </collision>
    <inertial>
      <origin xyz="0.075 0 0" rpy="0 0 0" />
      <mass value="0.02" />
      <inertia ixx="7.066666666666665e-07" ixy="0.0" ixz="0.0" iyy="1.404e-05" iyz="0.0" izz="1.3666666666666664e-05" />
    </inertial>
  </link>

  <joint name="black_joint_9" type="revolute">
    <parent link="base" />
    <child link="black_key_9" />
    <origin xyz="-0.03 -0.4594999999999999 0.0035000000000000014" rpy="0 0 0" />
    <axis xyz="0 1 0" />
    <limit lower="0" upper="0.06656816377582381" effort="0.3" velocity="6.67" />
  </joint>

  <link name="white_key_10">
    <visual>
      <origin xyz="0.115 0 0" rpy="0 0 0" />
      <geometry>
        <box size="0.15 0.022 0.022" />
      </geometry>
      <material name="white" />
    </visual>
    <collision>
      <origin xyz="0.115 0 0" rpy="0 0 0" />
      <geometry>
        <box size="0.15 0.022 0.022" />
      </geometry>
    </collision>
    <inertial>
      <origin xyz="0.115 0 0" rpy="0 0 0" />
      <mass value="0.04" />
      <inertia ixx="3.226666666666666e-06" ixy="0.0" ixz="0.0" iyy="7.661333333333333e-05" iyz="0.0" izz="7.661333333333333e-05" />
    </inertial>
  </link>

  <joint name="white_joint_10" type="revolute">
    <parent link="base" />
    <child link="white_key_10" />
    <origin xyz="-0.04000000000000001 -0.4484999999999999 -0.011" rpy="0 0 0" />
    <axis xyz="0 1 0" />
    <limit lower="0" upper="0.06307411789691225" effort="0.3" velocity="6.67" />
  </joint>

  <link name="black_key_11">
    <visual>
      <origin xyz="0.075 0 0" rpy="0 0 0" />
      <geometry>
        <box size="0.09 0.01 0.018" />
      </geometry>
      <material name="black" />
    </visual>
    <collision>
      <origin xyz="0.075 0 0" rpy="0 0 0" />
      <geometry>
        <box size="0.09 0.01 0.018" />
      </geometry>
    </collision>
    <inertial>
      <origin xyz="0.075 0 0" rpy="0 0 0" />
      <mass value="0.02" />
      <inertia ixx="7.066666666666665e-07" ixy="0.0" ixz="0.0" iyy="1.404e-05" iyz="0.0" izz="1.3666666666666664e-05" />
    </inertial>
  </link>

  <joint name="black_joint_11" type="revolute">
    <parent link="base" />
    <child link="black_key_11" />
    <origin xyz="-0.03 -0.4364999999999999 0.0035000000000000014" rpy="0 0 0" />
    <axis xyz="0 1 0" />
    <limit lower="0" upper="0.06656816377582381" effort="0.3" velocity="6.67" />
  </joint>

  <link name="white_key_12">
    <visual>
      <origin xyz="0.115 0 0" rpy="0 0 0" />
      <geometry>
        <box size="0.15 0.022 0.022" />
      </geometry>
      <material name="white" />
    </visual>
    <collision>
      <origin xyz="0.115 0 0" rpy="0 0 0" />
      <geometry>
        <box size="0.15 0.022 0.022" />
      </geometry>
    </collision>
    <inertial>
      <origin xyz="0.115 0 0" rpy="0 0 0" />
      <mass value="0.04" />
      <inertia ixx="3.226666666666666e-06" ixy="0.0" ixz="0.0" iyy="7.661333333333333e-05" iyz="0.0" izz="7.661333333333333e-05" />
    </inertial>
  </link>

  <joint name="white_joint_12" type="revolute">
    <parent link="base" />
    <child link="white_key_12" />
    <origin xyz="-0.04000000000000001 -0.4254999999999999 -0.011" rpy="0 0 0" />
    <axis xyz="0 1 0" />
    <limit lower="0" upper="0.06307411789691225" effort="0.3" velocity="6.67" />
  </joint>

  <link name="black_key_13">
    <visual>
      <origin xyz="0.075 0 0" rpy="0 0 0" />
      <geometry>
        <box size="0.09 0.01 0.018" />
      </geometry>
      <material name="black" />
    </visual>
    <collision>
      <origin xyz="0.075 0 0" rpy="0 0 0" />
      <geometry>
        <box size="0.09 0.01 0.018" />
      </geometry>
    </collision>
    <inertial>
      <origin xyz="0.075 0 0" rpy="0 0 0" />
      <mass value="0.02" />
      <inertia ixx="7.066666666666665e-07" ixy="0.0" ixz="0.0" iyy="1.404e-05" iyz="0.0" izz="1.3666666666666664e-05" />
    </inertial>
  </link>

  <joint name="black_joint_13" type="revolute">
    <parent link="base" />
    <child link="black_key_13" />
    <origin xyz="-0.03 -0.4135 0.0035000000000000014" rpy="0 0 0" />
    <axis xyz="0 1 0" />
    <limit lower="0" upper="0.06656816377582381" effort="0.3" velocity="6.67" />
  </joint>

  <link name="white_key_14">
    <visual>
      <origin xyz="0.115 0 0" rpy="0 0 0" />
      <geometry>
        <box size="0.15 0.022 0.022" />
      </geometry>
      <material name="white" />
    </visual>
    <collision>
      <origin xyz="0.115 0 0" rpy="0 0 0" />
      <geometry>
        <box size="0.15 0.022 0.022" />
      </geometry>
    </collision>
    <inertial>
      <origin xyz="0.115 0 0" rpy="0 0 0" />
      <mass value="0.04" />
      <inertia ixx="3.226666666666666e-06" ixy="0.0" ixz="0.0" iyy="7.661333333333333e-05" iyz="0.0" izz="7.661333333333333e-05" />
    </inertial>
  </link>

  <joint name="white_joint_14" type="revolute">
    <parent link="base" />
    <child link="white_key_14" />
    <origin xyz="-0.04000000000000001 -0.4024999999999999 -0.011" rpy="0 0 0" />
    <axis xyz="0 1 0" />
    <limit lower="0" upper="0.06307411789691225" effort="0.3" velocity="6.67" />
  </joint>

  <link name="white_key_15">
    <visual>
      <origin xyz="0.115 0 0" rpy="0 0 0" />
      <geometry>
        <box size="0.15 0.022 0.022" />
      </geometry>
      <material name="white" />
    </visual>
    <collision>
      <origin xyz="0.115 0 0" rpy="0 0 0" />
      <geometry>
        <box size="0.15 0.022 0.022" />
      </geometry>
    </collision>
    <inertial>
      <origin xyz="0.115 0 0" rpy="0 0 0" />
      <mass value="0.04" />
      <inertia ixx="3.226666666666666e-06" ixy="0.0" ixz="0.0" iyy="7.661333333333333e-05" iyz="0.0" izz="7.661333333333333e-05" />
    </inertial>
  </link>

  <joint name="white_joint_15" type="revolute">
    <parent link="base" />
    <child link="white_key_15" />
    <origin xyz="-0.04000000000000001 -0.37949999999999995 -0.011" rpy="0 0 0" />
    <axis xyz="0 1 0" />
    <limit lower="0" upper="0.06307411789691225" effort="0.3" velocity="6.67" />
  </joint>

  <link name="black_key_16">
    <visual>
      <origin xyz="0.075 0 0" rpy="0 0 0" />
      <geometry>
        <box size="0.09 0.01 0.018" />
      </geometry>
      <material name="black" />
    </visual>
    <collision>
      <origin xyz="0.075 0 0" rpy="0 0 0" />
      <geometry>
        <box size="0.09 0.01 0.018" />
      </geometry>
    </collision>
    <inertial>
      <origin xyz="0.075 0 0" rpy="0 0 0" />
      <mass value="0.02" />
      <inertia ixx="7.066666666666665e-07" ixy="0.0" ixz="0.0" iyy="1.404e-05" iyz="0.0" izz="1.3666666666666664e-05" />
    </inertial>
  </link>

  <joint name="black_joint_16" type="revolute">
    <parent link="base" />
    <child link="black_key_16" />
    <origin xyz="-0.03 -0.36749999999999994 0.0035000000000000014" rpy="0 0 0" />
    <axis xyz="0 1 0" />
    <limit lower="0" upper="0.06656816377582381" effort="0.3" velocity="6.67" />
  </joint>

  <link name="white_key_17">
    <visual>
      <origin xyz="0.115 0 0" rpy="0 0 0" />
      <geometry>
        <box size="0.15 0.022 0.022" />
      </geometry>
      <material name="white" />
    </visual>
    <collision>
      <origin xyz="0.115 0 0" rpy="0 0 0" />
      <geometry>
        <box size="0.15 0.022 0.022" />
      </geometry>
    </collision>
    <inertial>
      <origin xyz="0.115 0 0" rpy="0 0 0" />
      <mass value="0.04" />
      <inertia ixx="3.226666666666666e-06" ixy="0.0" ixz="0.0" iyy="7.661333333333333e-05" iyz="0.0" izz="7.661333333333333e-05" />
    </inertial>
  </link>

  <joint name="white_joint_17" type="revolute">
    <parent link="base" />
    <child link="white_key_17" />
    <origin xyz="-0.04000000000000001 -0.35649999999999993 -0.011" rpy="0 0 0" />
    <axis xyz="0 1 0" />
    <limit lower="0" upper="0.06307411789691225" effort="0.3" velocity="6.67" />
  </joint>

  <link name="black_key_18">
    <visual>
      <origin xyz="0.075 0 0" rpy="0 0 0" />
      <geometry>
        <box size="0.09 0.01 0.018" />
      </geometry>
      <material name="black" />
    </visual>
    <collision>
      <origin xyz="0.075 0 0" rpy="0 0 0" />
      <geometry>
        <box size="0.09 0.01 0.018" />
      </geometry>
    </collision>
    <inertial>
      <origin xyz="0.075 0 0" rpy="0 0 0" />
      <mass value="0.02" />
      <inertia ixx="7.066666666666665e-07" ixy="0.0" ixz="0.0" iyy="1.404e-05" iyz="0.0" izz="1.3666666666666664e-05" />
    </inertial>
  </link>

  <joint name="black_joint_18" type="revolute">
    <parent link="base" />
    <child link="black_key_18" />
    <origin xyz="-0.03 -0.3444999999999999 0.0035000000000000014" rpy="0 0 0" />
    <axis xyz="0 1 0" />
    <limit lower="0" upper="0.06656816377582381" effort="0.3" velocity="6.67" />
  </joint>

  <link name="white_key_19">
    <visual>
      <origin xyz="0.115 0 0" rpy="0 0 0" />
      <geometry>
        <box size="0.15 0.022 0.022" />
      </geometry>
      <material name="white" />
    </visual>
    <collision>
      <origin xyz="0.115 0 0" rpy="0 0 0" />
      <geometry>
        <box size="0.15 0.022 0.022" />
      </geometry>
    </collision>
    <inertial>
      <origin xyz="0.115 0 0" rpy="0 0 0" />
      <mass value="0.04" />
      <inertia ixx="3.226666666666666e-06" ixy="0.0" ixz="0.0" iyy="7.661333333333333e-05" iyz="0.0" izz="7.661333333333333e-05" />
    </inertial>
  </link>

  <joint name="white_joint_19" type="revolute">
    <parent link="base" />
    <child link="white_key_19" />
    <origin xyz="-0.04000000000000001 -0.3334999999999999 -0.011" rpy="0 0 0" />
    <axis xyz="0 1 0" />
    <limit lower="0" upper="0.06307411789691225" effort="0.3" velocity="6.67" />
  </joint>

  <link name="white_key_20">
    <visual>
      <origin xyz="0.115 0 0" rpy="0 0 0" />
      <geometry>
        <box size="0.15 0.022 0.022" />
      </geometry>
      <material name="white" />
    </visual>
    <collision>
      <origin xyz="0.115 0 0" rpy="0 0 0" />
      <geometry>
        <box size="0.15 0.022 0.022" />
      </geometry>
    </collision>
    <inertial>
      <origin xyz="0.115 0 0" rpy="0 0 0" />
      <mass value="0.04" />
      <inertia ixx="3.226666666666666e-06" ixy="0.0" ixz="0.0" iyy="7.661333333333333e-05" iyz="0.0" izz="7.661333333333333e-05" />
    </inertial>
  </link>

  <joint name="white_joint_20" type="revolute">
    <parent link="base" />
    <child link="white_key_20" />
    <origin xyz="-0.04000000000000001 -0.3104999999999999 -0.011" rpy="0 0 0" />
    <axis xyz="0 1 0" />
    <limit lower="0" upper="0.06307411789691225" effort="0.3" velocity="6.67" />
  </joint>

  <link name="black_key_21">
    <visual>
      <origin xyz="0.075 0 0" rpy="0 0 0" />
      <geometry>
        <box size="0.09 0.01 0.018" />
      </geometry>
      <material name="black" />
    </visual>
    <collision>
      <origin xyz="0.075 0 0" rpy="0 0 0" />
      <geometry>
        <box size="0.09 0.01 0.018" />
      </geometry>
    </collision>
    <inertial>
      <origin xyz="0.075 0 0" rpy="0 0 0" />
      <mass value="0.02" />
      <inertia ixx="7.066666666666665e-07" ixy="0.0" ixz="0.0" iyy="1.404e-05" iyz="0.0" izz="1.3666666666666664e-05" />
    </inertial>
  </link>

  <joint name="black_joint_21" type="revolute">
    <parent link="base" />
    <child link="black_key_21" />
    <origin xyz="-0.03 -0.2984999999999999 0.0035000000000000014" rpy="0 0 0" />
    <axis xyz="0 1 0" />
    <limit lower="0" upper="0.06656816377582381" effort="0.3" velocity="6.67" />
  </joint>

  <link name="white_key_22">
    <visual>
      <origin xyz="0.115 0 0" rpy="0 0 0" />
      <geometry>
        <box size="0.15 0.022 0.022" />
      </geometry>
      <material name="white" />
    </visual>
    <collision>
      <origin xyz="0.115 0 0" rpy="0 0 0" />
      <geometry>
        <box size="0.15 0.022 0.022" />
      </geometry>
    </collision>
    <inertial>
      <origin xyz="0.115 0 0" rpy="0 0 0" />
      <mass value="0.04" />
      <inertia ixx="3.226666666666666e-06" ixy="0.0" ixz="0.0" iyy="7.661333333333333e-05" iyz="0.0" izz="7.661333333333333e-05" />
    </inertial>
  </link>

  <joint name="white_joint_22" type="revolute">
    <parent link="base" />
    <child link="white_key_22" />
    <origin xyz="-0.04000000000000001 -0.2874999999999999 -0.011" rpy="0 0 0" />
    <axis xyz="0 1 0" />
    <limit lower="0" upper="0.06307411789691225" effort="0.3" velocity="6.67" />
  </joint>

  <link name="black_key_23">
    <visual>
      <origin xyz="0.075 0 0" rpy="0 0 0" />
      <geometry>
        <box size="0.09 0.01 0.018" />
      </geometry>
      <material name="black" />
    </visual>
    <collision>
      <origin xyz="0.075 0 0" rpy="0 0 0" />
      <geometry>
        <box size="0.09 0.01 0.018" />
      </geometry>
    </collision>
    <inertial>
      <origin xyz="0.075 0 0" rpy="0 0 0" />
      <mass value="0.02" />
      <inertia ixx="7.066666666666665e-07" ixy="0.0" ixz="0.0" iyy="1.404e-05" iyz="0.0" izz="1.3666666666666664e-05" />
    </inertial>
  </link>

  <joint name="black_joint_23" type="revolute">
    <parent link="base" />
    <child link="black_key_23" />
    <origin xyz="-0.03 -0.27549999999999986 0.0035000000000000014" rpy="0 0 0" />
    <axis xyz="0 1 0" />
    <limit lower="0" upper="0.06656816377582381" effort="0.3" velocity="6.67" />
  </joint>

  <link name="white_key_24">
    <visual>
      <origin xyz="0.115 0 0" rpy="0 0 0" />
      <geometry>
        <box size="0.15 0.022 0.022" />
      </geometry>
      <material name="white" />
    </visual>
    <collision>
      <origin xyz="0.115 0 0" rpy="0 0 0" />
      <geometry>
        <box size="0.15 0.022 0.022" />
      </geometry>
    </collision>
    <inertial>
      <origin xyz="0.115 0 0" rpy="0 0 0" />
      <mass value="0.04" />
      <inertia ixx="3.226666666666666e-06" ixy="0.0" ixz="0.0" iyy="7.661333333333333e-05" iyz="0.0" izz="7.661333333333333e-05" />
    </inertial>
  </link>

  <joint name="white_joint_24" type="revolute">
    <parent link="base" />
    <child link="white_key_24" />
    <origin xyz="-0.04000000000000001 -0.2644999999999999 -0.011" rpy="0 0 0" />
    <axis xyz="0 1 0" />
    <limit lower="0" upper="0.06307411789691225" effort="0.3" velocity="6.67" />
  </joint>

  <link name="black_key_25">
    <visual>
      <origin xyz="0.075 0 0" rpy="0 0 0" />
      <geometry>
        <box size="0.09 0.01 0.018" />
      </geometry>
      <material name="black" />
    </visual>
    <collision>
      <origin xyz="0.075 0 0" rpy="0 0 0" />
      <geometry>
        <box size="0.09 0.01 0.018" />
      </geometry>
    </collision>
    <inertial>
      <origin xyz="0.075 0 0" rpy="0 0 0" />
      <mass value="0.02" />
      <inertia ixx="7.066666666666665e-07" ixy="0.0" ixz="0.0" iyy="1.404e-05" iyz="0.0" izz="1.3666666666666664e-05" />
    </inertial>
  </link>

  <joint name="black_joint_25" type="revolute">
    <parent link="base" />
    <child link="black_key_25" />
    <origin xyz="-0.03 -0.25249999999999995 0.0035000000000000014" rpy="0 0 0" />
    <axis xyz="0 1 0" />
    <limit lower="0" upper="0.06656816377582381" effort="0.3" velocity="6.67" />
  </joint>

  <link name="white_key_26">
    <visual>
      <origin xyz="0.115 0 0" rpy="0 0 0" />
      <geometry>
        <box size="0.15 0.022 0.022" />
      </geometry>
      <material name="white" />
    </visual>
    <collision>
      <origin xyz="0.115 0 0" rpy="0 0 0" />
      <geometry>
        <box size="0.15 0.022 0.022" />
      </geometry>
    </collision>
    <inertial>
      <origin xyz="0.115 0 0" rpy="0 0 0" />
      <mass value="0.04" />
      <inertia ixx="3.226666666666666e-06" ixy="0.0" ixz="0.0" iyy="7.661333333333333e-05" iyz="0.0" izz="7.661333333333333e-05" />
    </inertial>
  </link>

  <joint name="white_joint_26" type="revolute">
    <parent link="base" />
    <child link="white_key_26" />
    <origin xyz="-0.04000000000000001 -0.24149999999999994 -0.011" rpy="0 0 0" />
    <axis xyz="0 1 0" />
    <limit lower="0" upper="0.06307411789691225" effort="0.3" velocity="6.67" />
  </joint>

  <link name="white_key_27">
    <visual>
      <origin xyz="0.115 0 0" rpy="0 0 0" />
      <geometry>
        <box size="0.15 0.022 0.022" />
      </geometry>
      <material name="white" />
    </visual>
    <collision>
      <origin xyz="0.115 0 0" rpy="0 0 0" />
      <geometry>
        <box size="0.15 0.022 0.022" />
      </geometry>
    </collision>
    <inertial>
      <origin xyz="0.115 0 0" rpy="0 0 0" />
      <mass value="0.04" />
      <inertia ixx="3.226666666666666e-06" ixy="0.0" ixz="0.0" iyy="7.661333333333333e-05" iyz="0.0" izz="7.661333333333333e-05" />
    </inertial>
  </link>

  <joint name="white_joint_27" type="revolute">
    <parent link="base" />
    <child link="white_key_27" />
    <origin xyz="-0.04000000000000001 -0.21849999999999992 -0.011" rpy="0 0 0" />
    <axis xyz="0 1 0" />
    <limit lower="0" upper="0.06307411789691225" effort="0.3" velocity="6.67" />
  </joint>

  <link name="black_key_28">
    <visual>
      <origin xyz="0.075 0 0" rpy="0 0 0" />
      <geometry>
        <box size="0.09 0.01 0.018" />
      </geometry>
      <material name="black" />
    </visual>
    <collision>
      <origin xyz="0.075 0 0" rpy="0 0 0" />
      <geometry>
        <box size="0.09 0.01 0.018" />
      </geometry>
    </collision>
    <inertial>
      <origin xyz="0.075 0 0" rpy="0 0 0" />
      <mass value="0.02" />
      <inertia ixx="7.066666666666665e-07" ixy="0.0" ixz="0.0" iyy="1.404e-05" iyz="0.0" izz="1.3666666666666664e-05" />
    </inertial>
  </link>

  <joint name="black_joint_28" type="revolute">
    <parent link="base" />
    <child link="black_key_28" />
    <origin xyz="-0.03 -0.2064999999999999 0.0035000000000000014" rpy="0 0 0" />
    <axis xyz="0 1 0" />
    <limit lower="0" upper="0.06656816377582381" effort="0.3" velocity="6.67" />
  </joint>

  <link name="white_key_29">
    <visual>
      <origin xyz="0.115 0 0" rpy="0 0 0" />
      <geometry>
        <box size="0.15 0.022 0.022" />
      </geometry>
      <material name="white" />
    </visual>
    <collision>
      <origin xyz="0.115 0 0" rpy="0 0 0" />
      <geometry>
        <box size="0.15 0.022 0.022" />
      </geometry>
    </collision>
    <inertial>
      <origin xyz="0.115 0 0" rpy="0 0 0" />
      <mass value="0.04" />
      <inertia ixx="3.226666666666666e-06" ixy="0.0" ixz="0.0" iyy="7.661333333333333e-05" iyz="0.0" izz="7.661333333333333e-05" />
    </inertial>
  </link>

  <joint name="white_joint_29" type="revolute">
    <parent link="base" />
    <child link="white_key_29" />
    <origin xyz="-0.04000000000000001 -0.1954999999999999 -0.011" rpy="0 0 0" />
    <axis xyz="0 1 0" />
    <limit lower="0" upper="0.06307411789691225" effort="0.3" velocity="6.67" />
  </joint>

  <link name="black_key_30">
    <visual>
      <origin xyz="0.075 0 0" rpy="0 0 0" />
      <geometry>
        <box size="0.09 0.01 0.018" />
      </geometry>
      <material name="black" />
    </visual>
    <collision>
      <origin xyz="0.075 0 0" rpy="0 0 0" />
      <geometry>
        <box size="0.09 0.01 0.018" />
      </geometry>
    </collision>
    <inertial>
      <origin xyz="0.075 0 0" rpy="0 0 0" />
      <mass value="0.02" />
      <inertia ixx="7.066666666666665e-07" ixy="0.0" ixz="0.0" iyy="1.404e-05" iyz="0.0" izz="1.3666666666666664e-05" />
    </inertial>
  </link>

  <joint name="black_joint_30" type="revolute">
    <parent link="base" />
    <child link="black_key_30" />
    <origin xyz="-0.03 -0.18349999999999989 0.0035000000000000014" rpy="0 0 0" />
    <axis xyz="0 1 0" />
    <limit lower="0" upper="0.06656816377582381" effort="0.3" velocity="6.67" />
  </joint>

  <link name="white_key_31">
    <visual>
      <origin xyz="0.115 0 0" rpy="0 0 0" />
      <geometry>
        <box size="0.15 0.022 0.022" />
      </geometry>
      <material name="white" />
    </visual>
    <collision>
      <origin xyz="0.115 0 0" rpy="0 0 0" />
      <geometry>
        <box size="0.15 0.022 0.022" />
      </geometry>
    </collision>
    <inertial>
      <origin xyz="0.115 0 0" rpy="0 0 0" />
      <mass value="0.04" />
      <inertia ixx="3.226666666666666e-06" ixy="0.0" ixz="0.0" iyy="7.661333333333333e-05" iyz="0.0" izz="7.661333333333333e-05" />
    </inertial>
  </link>

  <joint name="white_joint_31" type="revolute">
    <parent link="base" />
    <child link="white_key_31" />
    <origin xyz="-0.04000000000000001 -0.17249999999999993 -0.011" rpy="0 0 0" />
    <axis xyz="0 1 0" />
    <limit lower="0" upper="0.06307411789691225" effort="0.3" velocity="6.67" />
  </joint>

  <link name="white_key_32">
    <visual>
      <origin xyz="0.115 0 0" rpy="0 0 0" />
      <geometry>
        <box size="0.15 0.022 0.022" />
      </geometry>
      <material name="white" />
    </visual>
    <collision>
      <origin xyz="0.115 0 0" rpy="0 0 0" />
      <geometry>
        <box size="0.15 0.022 0.022" />
      </geometry>
    </collision>
    <inertial>
      <origin xyz="0.115 0 0" rpy="0 0 0" />
      <mass value="0.04" />
      <inertia ixx="3.226666666666666e-06" ixy="0.0" ixz="0.0" iyy="7.661333333333333e-05" iyz="0.0" izz="7.661333333333333e-05" />
    </inertial>
  </link>

  <joint name="white_joint_32" type="revolute">
    <parent link="base" />
    <child link="white_key_32" />
    <origin xyz="-0.04000000000000001 -0.1494999999999999 -0.011" rpy="0 0 0" />
    <axis xyz="0 1 0" />
    <limit lower="0" upper="0.06307411789691225" effort="0.3" velocity="6.67" />
  </joint>

  <link name="black_key_33">
    <visual>
      <origin xyz="0.075 0 0" rpy="0 0 0" />
      <geometry>
        <box size="0.09 0.01 0.018" />
      </geometry>
      <material name="black" />
    </visual>
    <collision>
      <origin xyz="0.075 0 0" rpy="0 0 0" />
      <geometry>
        <box size="0.09 0.01 0.018" />
      </geometry>
    </collision>
    <inertial>
      <origin xyz="0.075 0 0" rpy="0 0 0" />
      <mass value="0.02" />
      <inertia ixx="7.066666666666665e-07" ixy="0.0" ixz="0.0" iyy="1.404e-05" iyz="0.0" izz="1.3666666666666664e-05" />
    </inertial>
  </link>

  <joint name="black_joint_33" type="revolute">
    <parent link="base" />
    <child link="black_key_33" />
    <origin xyz="-0.03 -0.1374999999999999 0.0035000000000000014" rpy="0 0 0" />
    <axis xyz="0 1 0" />
    <limit lower="0" upper="0.06656816377582381" effort="0.3" velocity="6.67" />
  </joint>

  <link name="white_key_34">
    <visual>
      <origin xyz="0.115 0 0" rpy="0 0 0" />
      <geometry>
        <box size="0.15 0.022 0.022" />
      </geometry>
      <material name="white" />
    </visual>
    <collision>
      <origin xyz="0.115 0 0" rpy="0 0 0" />
      <geometry>
        <box size="0.15 0.022 0.022" />
      </geometry>
    </collision>
    <inertial>
      <origin xyz="0.115 0 0" rpy="0 0 0" />
      <mass value="0.04" />
      <inertia ixx="3.226666666666666e-06" ixy="0.0" ixz="0.0" iyy="7.661333333333333e-05" iyz="0.0" izz="7.661333333333333e-05" />
    </inertial>
  </link>

  <joint name="white_joint_34" type="revolute">
    <parent link="base" />
    <child link="white_key_34" />
    <origin xyz="-0.04000000000000001 -0.12649999999999995 -0.011" rpy="0 0 0" />
    <axis xyz="0 1 0" />
    <limit lower="0" upper="0.06307411789691225" effort="0.3" velocity="6.67" />
  </joint>

  <link name="black_key_35">
    <visual>
      <origin xyz="0.075 0 0" rpy="0 0 0" />
      <geometry>
        <box size="0.09 0.01 0.018" />
      </geometry>
      <material name="black" />
    </visual>
    <collision>
      <origin xyz="0.075 0 0" rpy="0 0 0" />
      <geometry>
        <box size="0.09 0.01 0.018" />
      </geometry>
    </collision>
    <inertial>
      <origin xyz="0.075 0 0" rpy="0 0 0" />
      <mass value="0.02" />
      <inertia ixx="7.066666666666665e-07" ixy="0.0" ixz="0.0" iyy="1.404e-05" iyz="0.0" izz="1.3666666666666664e-05" />
    </inertial>
  </link>

  <joint name="black_joint_35" type="revolute">
    <parent link="base" />
    <child link="black_key_35" />
    <origin xyz="-0.03 -0.11449999999999988 0.0035000000000000014" rpy="0 0 0" />
    <axis xyz="0 1 0" />
    <limit lower="0" upper="0.06656816377582381" effort="0.3" velocity="6.67" />
  </joint>

  <link name="white_key_36">
    <visual>
      <origin xyz="0.115 0 0" rpy="0 0 0" />
      <geometry>
        <box size="0.15 0.022 0.022" />
      </geometry>
      <material name="white" />
    </visual>
    <collision>
      <origin xyz="0.115 0 0" rpy="0 0 0" />
      <geometry>
        <box size="0.15 0.022 0.022" />
      </geometry>
    </collision>
    <inertial>
      <origin xyz="0.115 0 0" rpy="0 0 0" />
      <mass value="0.04" />
      <inertia ixx="3.226666666666666e-06" ixy="0.0" ixz="0.0" iyy="7.661333333333333e-05" iyz="0.0" izz="7.661333333333333e-05" />
    </inertial>
  </link>

  <joint name="white_joint_36" type="revolute">
    <parent link="base" />
    <child link="white_key_36" />
    <origin xyz="-0.04000000000000001 -0.10349999999999993 -0.011" rpy="0 0 0" />
    <axis xyz="0 1 0" />
    <limit lower="0" upper="0.06307411789691225" effort="0.3" velocity="6.67" />
  </joint>

  <link name="black_key_37">
    <visual>
      <origin xyz="0.075 0 0" rpy="0 0 0" />
      <geometry>
        <box size="0.09 0.01 0.018" />
      </geometry>
      <material name="black" />
    </visual>
    <collision>
      <origin xyz="0.075 0 0" rpy="0 0 0" />
      <geometry>
        <box size="0.09 0.01 0.018" />
      </geometry>
    </collision>
    <inertial>
      <origin xyz="0.075 0 0" rpy="0 0 0" />
      <mass value="0.02" />
      <inertia ixx="7.066666666666665e-07" ixy="0.0" ixz="0.0" iyy="1.404e-05" iyz="0.0" izz="1.3666666666666664e-05" />
    </inertial>
  </link>

  <joint name="black_joint_37" type="revolute">
    <parent link="base" />
    <child link="black_key_37" />
    <origin xyz="-0.03 -0.09149999999999997 0.0035000000000000014" rpy="0 0 0" />
    <axis xyz="0 1 0" />
    <limit lower="0" upper="0.06656816377582381" effort="0.3" velocity="6.67" />
  </joint>

  <link name="white_key_38">
    <visual>
      <origin xyz="0.115 0 0" rpy="0 0 0" />
      <geometry>
        <box size="0.15 0.022 0.022" />
      </geometry>
      <material name="white" />
    </visual>
    <collision>
      <origin xyz="0.115 0 0" rpy="0 0 0" />
      <geometry>
        <box size="0.15 0.022 0.022" />
      </geometry>
    </collision>
    <inertial>
      <origin xyz="0.115 0 0" rpy="0 0 0" />
      <mass value="0.04" />
      <inertia ixx="3.226666666666666e-06" ixy="0.0" ixz="0.0" iyy="7.661333333333333e-05" iyz="0.0" izz="7.661333333333333e-05" />
    </inertial>
  </link>

  <joint name="white_joint_38" type="revolute">
    <parent link="base" />
    <child link="white_key_38" />
    <origin xyz="-0.04000000000000001 -0.0804999999999999 -0.011" rpy="0 0 0" />
    <axis xyz="0 1 0" />
    <limit lower="0" upper="0.06307411789691225" effort="0.3" velocity="6.67" />
  </joint>

  <link name="white_key_39">
    <visual>
      <origin xyz="0.115 0 0" rpy="0 0 0" />
      <geometry>
        <box size="0.15 0.022 0.022" />
      </geometry>
      <material name="white" />
    </visual>
    <collision>
      <origin xyz="0.115 0 0" rpy="0 0 0" />
      <geometry>
        <box size="0.15 0.022 0.022" />
      </geometry>
    </collision>
    <inertial>
      <origin xyz="0.115 0 0" rpy="0 0 0" />
      <mass value="0.04" />
      <inertia ixx="3.226666666666666e-06" ixy="0.0" ixz="0.0" iyy="7.661333333333333e-05" iyz="0.0" izz="7.661333333333333e-05" />
    </inertial>
  </link>

  <joint name="white_joint_39" type="revolute">
    <parent link="base" />
    <child link="white_key_39" />
    <origin xyz="-0.04000000000000001 -0.057499999999999885 -0.011" rpy="0 0 0" />
    <axis xyz="0 1 0" />
    <limit lower="0" upper="0.06307411789691225" effort="0.3" velocity="6.67" />
  </joint>

  <link name="black_key_40">
    <visual>
      <origin xyz="0.075 0 0" rpy="0 0 0" />
      <geometry>
        <box size="0.09 0.01 0.018" />
      </geometry>
      <material name="black" />
    </visual>
    <collision>
      <origin xyz="0.075 0 0" rpy="0 0 0" />
      <geometry>
        <box size="0.09 0.01 0.018" />
      </geometry>
    </collision>
    <inertial>
      <origin xyz="0.075 0 0" rpy="0 0 0" />
      <mass value="0.02" />
      <inertia ixx="7.066666666666665e-07" ixy="0.0" ixz="0.0" iyy="1.404e-05" iyz="0.0" izz="1.3666666666666664e-05" />
    </inertial>
  </link>

  <joint name="black_joint_40" type="revolute">
    <parent link="base" />
    <child link="black_key_40" />
    <origin xyz="-0.03 -0.045499999999999874 0.0035000000000000014" rpy="0 0 0" />
    <axis xyz="0 1 0" />
    <limit lower="0" upper="0.06656816377582381" effort="0.3" velocity="6.67" />
  </joint>

  <link name="white_key_41">
    <visual>
      <origin xyz="0.115 0 0" rpy="0 0 0" />
      <geometry>
        <box size="0.15 0.022 0.022" />
      </geometry>
      <material name="white" />
    </visual>
    <collision>
      <origin xyz="0.115 0 0" rpy="0 0 0" />
      <geometry>
        <box size="0.15 0.022 0.022" />
      </geometry>
    </collision>
    <inertial>
      <origin xyz="0.115 0 0" rpy="0 0 0" />
      <mass value="0.04" />
      <inertia ixx="3.226666666666666e-06" ixy="0.0" ixz="0.0" iyy="7.661333333333333e-05" iyz="0.0" izz="7.661333333333333e-05" />
    </inertial>
  </link>

  <joint name="white_joint_41" type="revolute">
    <parent link="base" />
    <child link="white_key_41" />
    <origin xyz="-0.04000000000000001 -0.034499999999999864 -0.011" rpy="0 0 0" />
    <axis xyz="0 1 0" />
    <limit lower="0" upper="0.06307411789691225" effort="0.3" velocity="6.67" />
  </joint>

  <link name="black_key_42">
    <visual>
      <origin xyz="0.075 0 0" rpy="0 0 0" />
      <geometry>
        <box size="0.09 0.01 0.018" />
      </geometry>
      <material name="black" />
    </visual>
    <collision>
      <origin xyz="0.075 0 0" rpy="0 0 0" />
      <geometry>
        <box size="0.09 0.01 0.018" />
      </geometry>
    </collision>
    <inertial>
      <origin xyz="0.075 0 0" rpy="0 0 0" />
      <mass value="0.02" />
      <inertia ixx="7.066666666666665e-07" ixy="0.0" ixz="0.0" iyy="1.404e-05" iyz="0.0" izz="1.3666666666666664e-05" />
    </inertial>
  </link>

  <joint name="black_joint_42" type="revolute">
    <parent link="base" />
    <child link="black_key_42" />
    <origin xyz="-0.03 -0.022499999999999853 0.0035000000000000014" rpy="0 0 0" />
    <axis xyz="0 1 0" />
    <limit lower="0" upper="0.06656816377582381" effort="0.3" velocity="6.67" />
  </joint>

  <link name="white_key_43">
    <visual>
      <origin xyz="0.115 0 0" rpy="0 0 0" />
      <geometry>
        <box size="0.15 0.022 0.022" />
      </geometry>
      <material name="white" />
    </visual>
    <collision>
      <origin xyz="0.115 0 0" rpy="0 0 0" />
      <geometry>
        <box size="0.15 0.022 0.022" />
      </geometry>
    </collision>
    <inertial>
      <origin xyz="0.115 0 0" rpy="0 0 0" />
      <mass value="0.04" />
      <inertia ixx="3.226666666666666e-06" ixy="0.0" ixz="0.0" iyy="7.661333333333333e-05" iyz="0.0" izz="7.661333333333333e-05" />
    </inertial>
  </link>

  <joint name="white_joint_43" type="revolute">
    <parent link="base" />
    <child link="white_key_43" />
    <origin xyz="-0.04000000000000001 -0.011499999999999955 -0.011" rpy="0 0 0" />
    <axis xyz="0 1 0" />
    <limit lower="0" upper="0.06307411789691225" effort="0.3" velocity="6.67" />
  </joint>

  <link name="white_key_44">
    <visual>
      <origin xyz="0.115 0 0" rpy="0 0 0" />
      <geometry>
        <box size="0.15 0.022 0.022" />
      </geometry>
      <material name="white" />
    </visual>
    <collision>
      <origin xyz="0.115 0 0" rpy="0 0 0" />
      <geometry>
        <box size="0.15 0.022 0.022" />
      </geometry>
    </collision>
    <inertial>
      <origin xyz="0.115 0 0" rpy="0 0 0" />
      <mass value="0.04" />
      <inertia ixx="3.226666666666666e-06" ixy="0.0" ixz="0.0" iyy="7.661333333333333e-05" iyz="0.0" izz="7.661333333333333e-05" />
    </inertial>
  </link>

  <joint name="white_joint_44" type="revolute">
    <parent link="base" />
    <child link="white_key_44" />
    <origin xyz="-0.04000000000000001 0.011500000000000066 -0.011" rpy="0 0 0" />
    <axis xyz="0 1 0" />
    <limit lower="0" upper="0.06307411789691225" effort="0.3" velocity="6.67" />
  </joint>

  <link name="black_key_45">
    <visual>
      <origin xyz="0.075 0 0" rpy="0 0 0" />
      <geometry>
        <box size="0.09 0.01 0.018" />
      </geometry>
      <material name="black" />
    </visual>
    <collision>
      <origin xyz="0.075 0 0" rpy="0 0 0" />
      <geometry>
        <box size="0.09 0.01 0.018" />
      </geometry>
    </collision>
    <inertial>
      <origin xyz="0.075 0 0" rpy="0 0 0" />
      <mass value="0.02" />
      <inertia ixx="7.066666666666665e-07" ixy="0.0" ixz="0.0" iyy="1.404e-05" iyz="0.0" izz="1.3666666666666664e-05" />
    </inertial>
  </link>

  <joint name="black_joint_45" type="revolute">
    <parent link="base" />
    <child link="black_key_45" />
    <origin xyz="-0.03 0.023500000000000076 0.0035000000000000014" rpy="0 0 0" />
    <axis xyz="0 1 0" />
    <limit lower="0" upper="0.06656816377582381" effort="0.3" velocity="6.67" />
  </joint>

  <link name="white_key_46">
    <visual>
      <origin xyz="0.115 0 0" rpy="0 0 0" />
      <geometry>
        <box size="0.15 0.022 0.022" />
      </geometry>
      <material name="white" />
    </visual>
    <collision>
      <origin xyz="0.115 0 0" rpy="0 0 0" />
      <geometry>
        <box size="0.15 0.022 0.022" />
      </geometry>
    </collision>
    <inertial>
      <origin xyz="0.115 0 0" rpy="0 0 0" />
      <mass value="0.04" />
      <inertia ixx="3.226666666666666e-06" ixy="0.0" ixz="0.0" iyy="7.661333333333333e-05" iyz="0.0" izz="7.661333333333333e-05" />
    </inertial>
  </link>

  <joint name="white_joint_46" type="revolute">
    <parent link="base" />
    <child link="white_key_46" />
    <origin xyz="-0.04000000000000001 0.034500000000000086 -0.011" rpy="0 0 0" />
    <axis xyz="0 1 0" />
    <limit lower="0" upper="0.06307411789691225" effort="0.3" velocity="6.67" />
  </joint>

  <link name="black_key_47">
    <visual>
      <origin xyz="0.075 0 0" rpy="0 0 0" />
      <geometry>
        <box size="0.09 0.01 0.018" />
      </geometry>
      <material name="black" />
    </visual>
    <collision>
      <origin xyz="0.075 0 0" rpy="0 0 0" />
      <geometry>
        <box size="0.09 0.01 0.018" />
      </geometry>
    </collision>
    <inertial>
      <origin xyz="0.075 0 0" rpy="0 0 0" />
      <mass value="0.02" />
      <inertia ixx="7.066666666666665e-07" ixy="0.0" ixz="0.0" iyy="1.404e-05" iyz="0.0" izz="1.3666666666666664e-05" />
    </inertial>
  </link>

  <joint name="black_joint_47" type="revolute">
    <parent link="base" />
    <child link="black_key_47" />
    <origin xyz="-0.03 0.0465000000000001 0.0035000000000000014" rpy="0 0 0" />
    <axis xyz="0 1 0" />
    <limit lower="0" upper="0.06656816377582381" effort="0.3" velocity="6.67" />
  </joint>

  <link name="white_key_48">
    <visual>
      <origin xyz="0.115 0 0" rpy="0 0 0" />
      <geometry>
        <box size="0.15 0.022 0.022" />
      </geometry>
      <material name="white" />
    </visual>
    <collision>
      <origin xyz="0.115 0 0" rpy="0 0 0" />
      <geometry>
        <box size="0.15 0.022 0.022" />
      </geometry>
    </collision>
    <inertial>
      <origin xyz="0.115 0 0" rpy="0 0 0" />
      <mass value="0.04" />
      <inertia ixx="3.226666666666666e-06" ixy="0.0" ixz="0.0" iyy="7.661333333333333e-05" iyz="0.0" izz="7.661333333333333e-05" />
    </inertial>
  </link>

  <joint name="white_joint_48" type="revolute">
    <parent link="base" />
    <child link="white_key_48" />
    <origin xyz="-0.04000000000000001 0.05750000000000011 -0.011" rpy="0 0 0" />
    <axis xyz="0 1 0" />
    <limit lower="0" upper="0.06307411789691225" effort="0.3" velocity="6.67" />
  </joint>

  <link name="black_key_49">
    <visual>
      <origin xyz="0.075 0 0" rpy="0 0 0" />
      <geometry>
        <box size="0.09 0.01 0.018" />
      </geometry>
      <material name="black" />
    </visual>
    <collision>
      <origin xyz="0.075 0 0" rpy="0 0 0" />
      <geometry>
        <box size="0.09 0.01 0.018" />
      </geometry>
    </collision>
    <inertial>
      <origin xyz="0.075 0 0" rpy="0 0 0" />
      <mass value="0.02" />
      <inertia ixx="7.066666666666665e-07" ixy="0.0" ixz="0.0" iyy="1.404e-05" iyz="0.0" izz="1.3666666666666664e-05" />
    </inertial>
  </link>

  <joint name="black_joint_49" type="revolute">
    <parent link="base" />
    <child link="black_key_49" />
    <origin xyz="-0.03 0.0695 0.0035000000000000014" rpy="0 0 0" />
    <axis xyz="0 1 0" />
    <limit lower="0" upper="0.06656816377582381" effort="0.3" velocity="6.67" />
  </joint>

  <link name="white_key_50">
    <visual>
      <origin xyz="0.115 0 0" rpy="0 0 0" />
      <geometry>
        <box size="0.15 0.022 0.022" />
      </geometry>
      <material name="white" />
    </visual>
    <collision>
      <origin xyz="0.115 0 0" rpy="0 0 0" />
      <geometry>
        <box size="0.15 0.022 0.022" />
      </geometry>
    </collision>
    <inertial>
      <origin xyz="0.115 0 0" rpy="0 0 0" />
      <mass value="0.04" />
      <inertia ixx="3.226666666666666e-06" ixy="0.0" ixz="0.0" iyy="7.661333333333333e-05" iyz="0.0" izz="7.661333333333333e-05" />
    </inertial>
  </link>

  <joint name="white_joint_50" type="revolute">
    <parent link="base" />
    <child link="white_key_50" />
    <origin xyz="-0.04000000000000001 0.08050000000000013 -0.011" rpy="0 0 0" />
    <axis xyz="0 1 0" />
    <limit lower="0" upper="0.06307411789691225" effort="0.3" velocity="6.67" />
  </joint>

  <link name="white_key_51">
    <visual>
      <origin xyz="0.115 0 0" rpy="0 0 0" />
      <geometry>
        <box size="0.15 0.022 0.022" />
      </geometry>
      <material name="white" />
    </visual>
    <collision>
      <origin xyz="0.115 0 0" rpy="0 0 0" />
      <geometry>
        <box size="0.15 0.022 0.022" />
      </geometry>
    </collision>
    <inertial>
      <origin xyz="0.115 0 0" rpy="0 0 0" />
      <mass value="0.04" />
      <inertia ixx="3.226666666666666e-06" ixy="0.0" ixz="0.0" iyy="7.661333333333333e-05" iyz="0.0" izz="7.661333333333333e-05" />
    </inertial>
  </link>

  <joint name="white_joint_51" type="revolute">
    <parent link="base" />
    <child link="white_key_51" />
    <origin xyz="-0.04000000000000001 0.10350000000000004 -0.011" rpy="0 0 0" />
    <axis xyz="0 1 0" />
    <limit lower="0" upper="0.06307411789691225" effort="0.3" velocity="6.67" />
  </joint>

  <link name="black_key_52">
    <visual>
      <origin xyz="0.075 0 0" rpy="0 0 0" />
      <geometry>
        <box size="0.09 0.01 0.018" />
      </geometry>
      <material name="black" />
    </visual>
    <collision>
      <origin xyz="0.075 0 0" rpy="0 0 0" />
      <geometry>
        <box size="0.09 0.01 0.018" />
      </geometry>
    </collision>
    <inertial>
      <origin xyz="0.075 0 0" rpy="0 0 0" />
      <mass value="0.02" />
      <inertia ixx="7.066666666666665e-07" ixy="0.0" ixz="0.0" iyy="1.404e-05" iyz="0.0" izz="1.3666666666666664e-05" />
    </inertial>
  </link>

  <joint name="black_joint_52" type="revolute">
    <parent link="base" />
    <child link="black_key_52" />
    <origin xyz="-0.03 0.11550000000000005 0.0035000000000000014" rpy="0 0 0" />
    <axis xyz="0 1 0" />
    <limit lower="0" upper="0.06656816377582381" effort="0.3" velocity="6.67" />
  </joint>

  <link name="white_key_53">
    <visual>
      <origin xyz="0.115 0 0" rpy="0 0 0" />
      <geometry>
        <box size="0.15 0.022 0.022" />
      </geometry>
      <material name="white" />
    </visual>
    <collision>
      <origin xyz="0.115 0 0" rpy="0 0 0" />
      <geometry>
        <box size="0.15 0.022 0.022" />
      </geometry>
    </collision>
    <inertial>
      <origin xyz="0.115 0 0" rpy="0 0 0" />
      <mass value="0.04" />
      <inertia ixx="3.226666666666666e-06" ixy="0.0" ixz="0.0" iyy="7.661333333333333e-05" iyz="0.0" izz="7.661333333333333e-05" />
    </inertial>
  </link>

  <joint name="white_joint_53" type="revolute">
    <parent link="base" />
    <child link="white_key_53" />
    <origin xyz="-0.04000000000000001 0.12650000000000006 -0.011" rpy="0 0 0" />
    <axis xyz="0 1 0" />
    <limit lower="0" upper="0.06307411789691225" effort="0.3" velocity="6.67" />
  </joint>

  <link name="black_key_54">
    <visual>
      <origin xyz="0.075 0 0" rpy="0 0 0" />
      <geometry>
        <box size="0.09 0.01 0.018" />
      </geometry>
      <material name="black" />
    </visual>
    <collision>
      <origin xyz="0.075 0 0" rpy="0 0 0" />
      <geometry>
        <box size="0.09 0.01 0.018" />
      </geometry>
    </collision>
    <inertial>
      <origin xyz="0.075 0 0" rpy="0 0 0" />
      <mass value="0.02" />
      <inertia ixx="7.066666666666665e-07" ixy="0.0" ixz="0.0" iyy="1.404e-05" iyz="0.0" izz="1.3666666666666664e-05" />
    </inertial>
  </link>

  <joint name="black_joint_54" type="revolute">
    <parent link="base" />
    <child link="black_key_54" />
    <origin xyz="-0.03 0.13850000000000007 0.0035000000000000014" rpy="0 0 0" />
    <axis xyz="0 1 0" />
    <limit lower="0" upper="0.06656816377582381" effort="0.3" velocity="6.67" />
  </joint>

  <link name="white_key_55">
    <visual>
      <origin xyz="0.115 0 0" rpy="0 0 0" />
      <geometry>
        <box size="0.15 0.022 0.022" />
      </geometry>
      <material name="white" />
    </visual>
    <collision>
      <origin xyz="0.115 0 0" rpy="0 0 0" />
      <geometry>
        <box size="0.15 0.022 0.022" />
      </geometry>
    </collision>
    <inertial>
      <origin xyz="0.115 0 0" rpy="0 0 0" />
      <mass value="0.04" />
      <inertia ixx="3.226666666666666e-06" ixy="0.0" ixz="0.0" iyy="7.661333333333333e-05" iyz="0.0" izz="7.661333333333333e-05" />
    </inertial>
  </link>

  <joint name="white_joint_55" type="revolute">
    <parent link="base" />
    <child link="white_key_55" />
    <origin xyz="-0.04000000000000001 0.14950000000000008 -0.011" rpy="0 0 0" />
    <axis xyz="0 1 0" />
    <limit lower="0" upper="0.06307411789691225" effort="0.3" velocity="6.67" />
  </joint>

  <link name="white_key_56">
    <visual>
      <origin xyz="0.115 0 0" rpy="0 0 0" />
      <geometry>
        <box size="0.15 0.022 0.022" />
      </geometry>
      <material name="white" />
    </visual>
    <collision>
      <origin xyz="0.115 0 0" rpy="0 0 0" />
      <geometry>
        <box size="0.15 0.022 0.022" />
      </geometry>
    </collision>
    <inertial>
      <origin xyz="0.115 0 0" rpy="0 0 0" />
      <mass value="0.04" />
      <inertia ixx="3.226666666666666e-06" ixy="0.0" ixz="0.0" iyy="7.661333333333333e-05" iyz="0.0" izz="7.661333333333333e-05" />
    </inertial>
  </link>

  <joint name="white_joint_56" type="revolute">
    <parent link="base" />
    <child link="white_key_56" />
    <origin xyz="-0.04000000000000001 0.1725000000000001 -0.011" rpy="0 0 0" />
    <axis xyz="0 1 0" />
    <limit lower="0" upper="0.06307411789691225" effort="0.3" velocity="6.67" />
  </joint>

  <link name="black_key_57">
    <visual>
      <origin xyz="0.075 0 0" rpy="0 0 0" />
      <geometry>
        <box size="0.09 0.01 0.018" />
      </geometry>
      <material name="black" />
    </visual>
    <collision>
      <origin xyz="0.075 0 0" rpy="0 0 0" />
      <geometry>
        <box size="0.09 0.01 0.018" />
      </geometry>
    </collision>
    <inertial>
      <origin xyz="0.075 0 0" rpy="0 0 0" />
      <mass value="0.02" />
      <inertia ixx="7.066666666666665e-07" ixy="0.0" ixz="0.0" iyy="1.404e-05" iyz="0.0" izz="1.3666666666666664e-05" />
    </inertial>
  </link>

  <joint name="black_joint_57" type="revolute">
    <parent link="base" />
    <child link="black_key_57" />
    <origin xyz="-0.03 0.1845000000000001 0.0035000000000000014" rpy="0 0 0" />
    <axis xyz="0 1 0" />
    <limit lower="0" upper="0.06656816377582381" effort="0.3" velocity="6.67" />
  </joint>

  <link name="white_key_58">
    <visual>
      <origin xyz="0.115 0 0" rpy="0 0 0" />
      <geometry>
        <box size="0.15 0.022 0.022" />
      </geometry>
      <material name="white" />
    </visual>
    <collision>
      <origin xyz="0.115 0 0" rpy="0 0 0" />
      <geometry>
        <box size="0.15 0.022 0.022" />
      </geometry>
    </collision>
    <inertial>
      <origin xyz="0.115 0 0" rpy="0 0 0" />
      <mass value="0.04" />
      <inertia ixx="3.226666666666666e-06" ixy="0.0" ixz="0.0" iyy="7.661333333333333e-05" iyz="0.0" izz="7.661333333333333e-05" />
    </inertial>
  </link>

  <joint name="white_joint_58" type="revolute">
    <parent link="base" />
    <child link="white_key_58" />
    <origin xyz="-0.04000000000000001 0.19550000000000012 -0.011" rpy="0 0 0" />
    <axis xyz="0 1 0" />
    <limit lower="0" upper="0.06307411789691225" effort="0.3" velocity="6.67" />
  </joint>

  <link name="black_key_59">
    <visual>
      <origin xyz="0.075 0 0" rpy="0 0 0" />
      <geometry>
        <box size="0.09 0.01 0.018" />
      </geometry>
      <material name="black" />
    </visual>
    <collision>
      <origin xyz="0.075 0 0" rpy="0 0 0" />
      <geometry>
        <box size="0.09 0.01 0.018" />
      </geometry>
    </collision>
    <inertial>
      <origin xyz="0.075 0 0" rpy="0 0 0" />
      <mass value="0.02" />
      <inertia ixx="7.066666666666665e-07" ixy="0.0" ixz="0.0" iyy="1.404e-05" iyz="0.0" izz="1.3666666666666664e-05" />
    </inertial>
  </link>

  <joint name="black_joint_59" type="revolute">
    <parent link="base" />
    <child link="black_key_59" />
    <origin xyz="-0.03 0.20750000000000013 0.0035000000000000014" rpy="0 0 0" />
    <axis xyz="0 1 0" />
    <limit lower="0" upper="0.06656816377582381" effort="0.3" velocity="6.67" />
  </joint>

  <link name="white_key_60">
    <visual>
      <origin xyz="0.115 0 0" rpy="0 0 0" />
      <geometry>
        <box size="0.15 0.022 0.022" />
      </geometry>
      <material name="white" />
    </visual>
    <collision>
      <origin xyz="0.115 0 0" rpy="0 0 0" />
      <geometry>
        <box size="0.15 0.022 0.022" />
      </geometry>
    </collision>
    <inertial>
      <origin xyz="0.115 0 0" rpy="0 0 0" />
      <mass value="0.04" />
      <inertia ixx="3.226666666666666e-06" ixy="0.0" ixz="0.0" iyy="7.661333333333333e-05" iyz="0.0" izz="7.661333333333333e-05" />
    </inertial>
  </link>

  <joint name="white_joint_60" type="revolute">
    <parent link="base" />
    <child link="white_key_60" />
    <origin xyz="-0.04000000000000001 0.21850000000000003 -0.011" rpy="0 0 0" />
    <axis xyz="0 1 0" />
    <limit lower="0" upper="0.06307411789691225" effort="0.3" velocity="6.67" />
  </joint>

  <link name="black_key_61">
    <visual>
      <origin xyz="0.075 0 0" rpy="0 0 0" />
      <geometry>
        <box size="0.09 0.01 0.018" />
      </geometry>
      <material name="black" />
    </visual>
    <collision>
      <origin xyz="0.075 0 0" rpy="0 0 0" />
      <geometry>
        <box size="0.09 0.01 0.018" />
      </geometry>
    </collision>
    <inertial>
      <origin xyz="0.075 0 0" rpy="0 0 0" />
      <mass value="0.02" />
      <inertia ixx="7.066666666666665e-07" ixy="0.0" ixz="0.0" iyy="1.404e-05" iyz="0.0" izz="1.3666666666666664e-05" />
    </inertial>
  </link>

  <joint name="black_joint_61" type="revolute">
    <parent link="base" />
    <child link="black_key_61" />
    <origin xyz="-0.03 0.23050000000000004 0.0035000000000000014" rpy="0 0 0" />
    <axis xyz="0 1 0" />
    <limit lower="0" upper="0.06656816377582381" effort="0.3" velocity="6.67" />
  </joint>

  <link name="white_key_62">
    <visual>
      <origin xyz="0.115 0 0" rpy="0 0 0" />
      <geometry>
        <box size="0.15 0.022 0.022" />
      </geometry>
      <material name="white" />
    </visual>
    <collision>
      <origin xyz="0.115 0 0" rpy="0 0 0" />
      <geometry>
        <box size="0.15 0.022 0.022" />
      </geometry>
    </collision>
    <inertial>
      <origin xyz="0.115 0 0" rpy="0 0 0" />
      <mass value="0.04" />
      <inertia ixx="3.226666666666666e-06" ixy="0.0" ixz="0.0" iyy="7.661333333333333e-05" iyz="0.0" izz="7.661333333333333e-05" />
    </inertial>
  </link>

  <joint name="white_joint_62" type="revolute">
    <parent link="base" />
    <child link="white_key_62" />
    <origin xyz="-0.04000000000000001 0.24150000000000005 -0.011" rpy="0 0 0" />
    <axis xyz="0 1 0" />
    <limit lower="0" upper="0.06307411789691225" effort="0.3" velocity="6.67" />
  </joint>

  <link name="white_key_63">
    <visual>
      <origin xyz="0.115 0 0" rpy="0 0 0" />
      <geometry>
        <box size="0.15 0.022 0.022" />
      </geometry>
      <material name="white" />
    </visual>
    <collision>
      <origin xyz="0.115 0 0" rpy="0 0 0" />
      <geometry>
        <box size="0.15 0.022 0.022" />
      </geometry>
    </collision>
    <inertial>
      <origin xyz="0.115 0 0" rpy="0 0 0" />
      <mass value="0.04" />
      <inertia ixx="3.226666666666666e-06" ixy="0.0" ixz="0.0" iyy="7.661333333333333e-05" iyz="0.0" izz="7.661333333333333e-05" />
    </inertial>
  </link>

  <joint name="white_joint_63" type="revolute">
    <parent link="base" />
    <child link="white_key_63" />
    <origin xyz="-0.04000000000000001 0.26450000000000007 -0.011" rpy="0 0 0" />
    <axis xyz="0 1 0" />
    <limit lower="0" upper="0.06307411789691225" effort="0.3" velocity="6.67" />
  </joint>

  <link name="black_key_64">
    <visual>
      <origin xyz="0.075 0 0" rpy="0 0 0" />
      <geometry>
        <box size="0.09 0.01 0.018" />
      </geometry>
      <material name="black" />
    </visual>
    <collision>
      <origin xyz="0.075 0 0" rpy="0 0 0" />
      <geometry>
        <box size="0.09 0.01 0.018" />
      </geometry>
    </collision>
    <inertial>
      <origin xyz="0.075 0 0" rpy="0 0 0" />
      <mass value="0.02" />
      <inertia ixx="7.066666666666665e-07" ixy="0.0" ixz="0.0" iyy="1.404e-05" iyz="0.0" izz="1.3666666666666664e-05" />
    </inertial>
  </link>

  <joint name="black_joint_64" type="revolute">
    <parent link="base" />
    <child link="black_key_64" />
    <origin xyz="-0.03 0.2765000000000001 0.0035000000000000014" rpy="0 0 0" />
    <axis xyz="0 1 0" />
    <limit lower="0" upper="0.06656816377582381" effort="0.3" velocity="6.67" />
  </joint>

  <link name="white_key_65">
    <visual>
      <origin xyz="0.115 0 0" rpy="0 0 0" />
      <geometry>
        <box size="0.15 0.022 0.022" />
      </geometry>
      <material name="white" />
    </visual>
    <collision>
      <origin xyz="0.115 0 0" rpy="0 0 0" />
      <geometry>
        <box size="0.15 0.022 0.022" />
      </geometry>
    </collision>
    <inertial>
      <origin xyz="0.115 0 0" rpy="0 0 0" />
      <mass value="0.04" />
      <inertia ixx="3.226666666666666e-06" ixy="0.0" ixz="0.0" iyy="7.661333333333333e-05" iyz="0.0" izz="7.661333333333333e-05" />
    </inertial>
  </link>

  <joint name="white_joint_65" type="revolute">
    <parent link="base" />
    <child link="white_key_65" />
    <origin xyz="-0.04000000000000001 0.2875000000000001 -0.011" rpy="0 0 0" />
    <axis xyz="0 1 0" />
    <limit lower="0" upper="0.06307411789691225" effort="0.3" velocity="6.67" />
  </joint>

  <link name="black_key_66">
    <visual>
      <origin xyz="0.075 0 0" rpy="0 0 0" />
      <geometry>
        <box size="0.09 0.01 0.018" />
      </geometry>
      <material name="black" />
    </visual>
    <collision>
      <origin xyz="0.075 0 0" rpy="0 0 0" />
      <geometry>
        <box size="0.09 0.01 0.018" />
      </geometry>
    </collision>
    <inertial>
      <origin xyz="0.075 0 0" rpy="0 0 0" />
      <mass value="0.02" />
      <inertia ixx="7.066666666666665e-07" ixy="0.0" ixz="0.0" iyy="1.404e-05" iyz="0.0" izz="1.3666666666666664e-05" />
    </inertial>
  </link>

  <joint name="black_joint_66" type="revolute">
    <parent link="base" />
    <child link="black_key_66" />
    <origin xyz="-0.03 0.2995000000000001 0.0035000000000000014" rpy="0 0 0" />
    <axis xyz="0 1 0" />
    <limit lower="0" upper="0.06656816377582381" effort="0.3" velocity="6.67" />
  </joint>

  <link name="white_key_67">
    <visual>
      <origin xyz="0.115 0 0" rpy="0 0 0" />
      <geometry>
        <box size="0.15 0.022 0.022" />
      </geometry>
      <material name="white" />
    </visual>
    <collision>
      <origin xyz="0.115 0 0" rpy="0 0 0" />
      <geometry>
        <box size="0.15 0.022 0.022" />
      </geometry>
    </collision>
    <inertial>
      <origin xyz="0.115 0 0" rpy="0 0 0" />
      <mass value="0.04" />
      <inertia ixx="3.226666666666666e-06" ixy="0.0" ixz="0.0" iyy="7.661333333333333e-05" iyz="0.0" izz="7.661333333333333e-05" />
    </inertial>
  </link>

  <joint name="white_joint_67" type="revolute">
    <parent link="base" />
    <child link="white_key_67" />
    <origin xyz="-0.04000000000000001 0.3105000000000001 -0.011" rpy="0 0 0" />
    <axis xyz="0 1 0" />
    <limit lower="0" upper="0.06307411789691225" effort="0.3" velocity="6.67" />
  </joint>

  <link name="white_key_68">
    <visual>
      <origin xyz="0.115 0 0" rpy="0 0 0" />
      <geometry>
        <box size="0.15 0.022 0.022" />
      </geometry>
      <material name="white" />
    </visual>
    <collision>
      <origin xyz="0.115 0 0" rpy="0 0 0" />
      <geometry>
        <box size="0.15 0.022 0.022" />
      </geometry>
    </collision>
    <inertial>
      <origin xyz="0.115 0 0" rpy="0 0 0" />
      <mass value="0.04" />
      <inertia ixx="3.226666666666666e-06" ixy="0.0" ixz="0.0" iyy="7.661333333333333e-05" iyz="0.0" izz="7.661333333333333e-05" />
    </inertial>
  </link>

  <joint name="white_joint_68" type="revolute">
    <parent link="base" />
    <child link="white_key_68" />
    <origin xyz="-0.04000000000000001 0.3335 -0.011" rpy="0 0 0" />
    <axis xyz="0 1 0" />
    <limit lower="0" upper="0.06307411789691225" effort="0.3" velocity="6.67" />
  </joint>

  <link name="black_key_69">
    <visual>
      <origin xyz="0.075 0 0" rpy="0 0 0" />
      <geometry>
        <box size="0.09 0.01 0.018" />
      </geometry>
      <material name="black" />
    </visual>
    <collision>
      <origin xyz="0.075 0 0" rpy="0 0 0" />
      <geometry>
        <box size="0.09 0.01 0.018" />
      </geometry>
    </collision>
    <inertial>
      <origin xyz="0.075 0 0" rpy="0 0 0" />
      <mass value="0.02" />
      <inertia ixx="7.066666666666665e-07" ixy="0.0" ixz="0.0" iyy="1.404e-05" iyz="0.0" izz="1.3666666666666664e-05" />
    </inertial>
  </link>

  <joint name="black_joint_69" type="revolute">
    <parent link="base" />
    <child link="black_key_69" />
    <origin xyz="-0.03 0.34550000000000003 0.0035000000000000014" rpy="0 0 0" />
    <axis xyz="0 1 0" />
    <limit lower="0" upper="0.06656816377582381" effort="0.3" velocity="6.67" />
  </joint>

  <link name="white_key_70">
    <visual>
      <origin xyz="0.115 0 0" rpy="0 0 0" />
      <geometry>
        <box size="0.15 0.022 0.022" />
      </geometry>
      <material name="white" />
    </visual>
    <collision>
      <origin xyz="0.115 0 0" rpy="0 0 0" />
      <geometry>
        <box size="0.15 0.022 0.022" />
      </geometry>
    </collision>
    <inertial>
      <origin xyz="0.115 0 0" rpy="0 0 0" />
      <mass value="0.04" />
      <inertia ixx="3.226666666666666e-06" ixy="0.0" ixz="0.0" iyy="7.661333333333333e-05" iyz="0.0" izz="7.661333333333333e-05" />
    </inertial>
  </link>

  <joint name="white_joint_70" type="revolute">
    <parent link="base" />
    <child link="white_key_70" />
    <origin xyz="-0.04000000000000001 0.35650000000000004 -0.011" rpy="0 0 0" />
    <axis xyz="0 1 0" />
    <limit lower="0" upper="0.06307411789691225" effort="0.3" velocity="6.67" />
  </joint>

  <link name="black_key_71">
    <visual>
      <origin xyz="0.075 0 0" rpy="0 0 0" />
      <geometry>
        <box size="0.09 0.01 0.018" />
      </geometry>
      <material name="black" />
    </visual>
    <collision>
      <origin xyz="0.075 0 0" rpy="0 0 0" />
      <geometry>
        <box size="0.09 0.01 0.018" />
      </geometry>
    </collision>
    <inertial>
      <origin xyz="0.075 0 0" rpy="0 0 0" />
      <mass value="0.02" />
      <inertia ixx="7.066666666666665e-07" ixy="0.0" ixz="0.0" iyy="1.404e-05" iyz="0.0" izz="1.3666666666666664e-05" />
    </inertial>
  </link>

  <joint name="black_joint_71" type="revolute">
    <parent link="base" />
    <child link="black_key_71" />
    <origin xyz="-0.03 0.36850000000000005 0.0035000000000000014" rpy="0 0 0" />
    <axis xyz="0 1 0" />
    <limit lower="0" upper="0.06656816377582381" effort="0.3" velocity="6.67" />
  </joint>

  <link name="white_key_72">
    <visual>
      <origin xyz="0.115 0 0" rpy="0 0 0" />
      <geometry>
        <box size="0.15 0.022 0.022" />
      </geometry>
      <material name="white" />
    </visual>
    <collision>
      <origin xyz="0.115 0 0" rpy="0 0 0" />
      <geometry>
        <box size="0.15 0.022 0.022" />
      </geometry>
    </collision>
    <inertial>
      <origin xyz="0.115 0 0" rpy="0 0 0" />
      <mass value="0.04" />
      <inertia ixx="3.226666666666666e-06" ixy="0.0" ixz="0.0" iyy="7.661333333333333e-05" iyz="0.0" izz="7.661333333333333e-05" />
    </inertial>
  </link>

  <joint name="white_joint_72" type="revolute">
    <parent link="base" />
    <child link="white_key_72" />
    <origin xyz="-0.04000000000000001 0.37950000000000006 -0.011" rpy="0 0 0" />
    <axis xyz="0 1 0" />
    <limit lower="0" upper="0.06307411789691225" effort="0.3" velocity="6.67" />
  </joint>

  <link name="black_key_73">
    <visual>
      <origin xyz="0.075 0 0" rpy="0 0 0" />
      <geometry>
        <box size="0.09 0.01 0.018" />
      </geometry>
      <material name="black" />
    </visual>
    <collision>
      <origin xyz="0.075 0 0" rpy="0 0 0" />
      <geometry>
        <box size="0.09 0.01 0.018" />
      </geometry>
    </collision>
    <inertial>
      <origin xyz="0.075 0 0" rpy="0 0 0" />
      <mass value="0.02" />
      <inertia ixx="7.066666666666665e-07" ixy="0.0" ixz="0.0" iyy="1.404e-05" iyz="0.0" izz="1.3666666666666664e-05" />
    </inertial>
  </link>

  <joint name="black_joint_73" type="revolute">
    <parent link="base" />
    <child link="black_key_73" />
    <origin xyz="-0.03 0.39149999999999996 0.0035000000000000014" rpy="0 0 0" />
    <axis xyz="0 1 0" />
    <limit lower="0" upper="0.06656816377582381" effort="0.3" velocity="6.67" />
  </joint>

  <link name="white_key_74">
    <visual>
      <origin xyz="0.115 0 0" rpy="0 0 0" />
      <geometry>
        <box size="0.15 0.022 0.022" />
      </geometry>
      <material name="white" />
    </visual>
    <collision>
      <origin xyz="0.115 0 0" rpy="0 0 0" />
      <geometry>
        <box size="0.15 0.022 0.022" />
      </geometry>
    </collision>
    <inertial>
      <origin xyz="0.115 0 0" rpy="0 0 0" />
      <mass value="0.04" />
      <inertia ixx="3.226666666666666e-06" ixy="0.0" ixz="0.0" iyy="7.661333333333333e-05" iyz="0.0" izz="7.661333333333333e-05" />
    </inertial>
  </link>

  <joint name="white_joint_74" type="revolute">
    <parent link="base" />
    <child link="white_key_74" />
    <origin xyz="-0.04000000000000001 0.4025000000000001 -0.011" rpy="0 0 0" />
    <axis xyz="0 1 0" />
    <limit lower="0" upper="0.06307411789691225" effort="0.3" velocity="6.67" />
  </joint>

  <link name="white_key_75">
    <visual>
      <origin xyz="0.115 0 0" rpy="0 0 0" />
      <geometry>
        <box size="0.15 0.022 0.022" />
      </geometry>
      <material name="white" />
    </visual>
    <collision>
      <origin xyz="0.115 0 0" rpy="0 0 0" />
      <geometry>
        <box size="0.15 0.022 0.022" />
      </geometry>
    </collision>
    <inertial>
      <origin xyz="0.115 0 0" rpy="0 0 0" />
      <mass value="0.04" />
      <inertia ixx="3.226666666666666e-06" ixy="0.0" ixz="0.0" iyy="7.661333333333333e-05" iyz="0.0" izz="7.661333333333333e-05" />
    </inertial>
  </link>

  <joint name="white_joint_75" type="revolute">
    <parent link="base" />
    <child link="white_key_75" />
    <origin xyz="-0.04000000000000001 0.4255000000000001 -0.011" rpy="0 0 0" />
    <axis xyz="0 1 0" />
    <limit lower="0" upper="0.06307411789691225" effort="0.3" velocity="6.67" />
  </joint>

  <link name="black_key_76">
    <visual>
      <origin xyz="0.075 0 0" rpy="0 0 0" />
      <geometry>
        <box size="0.09 0.01 0.018" />
      </geometry>
      <material name="black" />
    </visual>
    <collision>
      <origin xyz="0.075 0 0" rpy="0 0 0" />
      <geometry>
        <box size="0.09 0.01 0.018" />
      </geometry>
    </collision>
    <inertial>
      <origin xyz="0.075 0 0" rpy="0 0 0" />
      <mass value="0.02" />
      <inertia ixx="7.066666666666665e-07" ixy="0.0" ixz="0.0" iyy="1.404e-05" iyz="0.0" izz="1.3666666666666664e-05" />
    </inertial>
  </link>

  <joint name="black_joint_76" type="revolute">
    <parent link="base" />
    <child link="black_key_76" />
    <origin xyz="-0.03 0.4375000000000001 0.0035000000000000014" rpy="0 0 0" />
    <axis xyz="0 1 0" />
    <limit lower="0" upper="0.06656816377582381" effort="0.3" velocity="6.67" />
  </joint>

  <link name="white_key_77">
    <visual>
      <origin xyz="0.115 0 0" rpy="0 0 0" />
      <geometry>
        <box size="0.15 0.022 0.022" />
      </geometry>
      <material name="white" />
    </visual>
    <collision>
      <origin xyz="0.115 0 0" rpy="0 0 0" />
      <geometry>
        <box size="0.15 0.022 0.022" />
      </geometry>
    </collision>
    <inertial>
      <origin xyz="0.115 0 0" rpy="0 0 0" />
      <mass value="0.04" />
      <inertia ixx="3.226666666666666e-06" ixy="0.0" ixz="0.0" iyy="7.661333333333333e-05" iyz="0.0" izz="7.661333333333333e-05" />
    </inertial>
  </link>

  <joint name="white_joint_77" type="revolute">
    <parent link="base" />
    <child link="white_key_77" />
    <origin xyz="-0.04000000000000001 0.4485 -0.011" rpy="0 0 0" />
    <axis xyz="0 1 0" />
    <limit lower="0" upper="0.06307411789691225" effort="0.3" velocity="6.67" />
  </joint>

  <link name="black_key_78">
    <visual>
      <origin xyz="0.075 0 0" rpy="0 0 0" />
      <geometry>
        <box size="0.09 0.01 0.018" />
      </geometry>
      <material name="black" />
    </visual>
    <collision>
      <origin xyz="0.075 0 0" rpy="0 0 0" />
      <geometry>
        <box size="0.09 0.01 0.018" />
      </geometry>
    </collision>
    <inertial>
      <origin xyz="0.075 0 0" rpy="0 0 0" />
      <mass value="0.02" />
      <inertia ixx="7.066666666666665e-07" ixy="0.0" ixz="0.0" iyy="1.404e-05" iyz="0.0" izz="1.3666666666666664e-05" />
    </inertial>
  </link>

  <joint name="black_joint_78" type="revolute">
    <parent link="base" />
    <child link="black_key_78" />
    <origin xyz="-0.03 0.46050000000000013 0.0035000000000000014" rpy="0 0 0" />
    <axis xyz="0 1 0" />
    <limit lower="0" upper="0.06656816377582381" effort="0.3" velocity="6.67" />
  </joint>

  <link name="white_key_79">
    <visual>
      <origin xyz="0.115 0 0" rpy="0 0 0" />
      <geometry>
        <box size="0.15 0.022 0.022" />
      </geometry>
      <material name="white" />
    </visual>
    <collision>
      <origin xyz="0.115 0 0" rpy="0 0 0" />
      <geometry>
        <box size="0.15 0.022 0.022" />
      </geometry>
    </collision>
    <inertial>
      <origin xyz="0.115 0 0" rpy="0 0 0" />
      <mass value="0.04" />
      <inertia ixx="3.226666666666666e-06" ixy="0.0" ixz="0.0" iyy="7.661333333333333e-05" iyz="0.0" izz="7.661333333333333e-05" />
    </inertial>
  </link>

  <joint name="white_joint_79" type="revolute">
    <parent link="base" />
    <child link="white_key_79" />
    <origin xyz="-0.04000000000000001 0.47150000000000014 -0.011" rpy="0 0 0" />
    <axis xyz="0 1 0" />
    <limit lower="0" upper="0.06307411789691225" effort="0.3" velocity="6.67" />
  </joint>

  <link name="white_key_80">
    <visual>
      <origin xyz="0.115 0 0" rpy="0 0 0" />
      <geometry>
        <box size="0.15 0.022 0.022" />
      </geometry>
      <material name="white" />
    </visual>
    <collision>
      <origin xyz="0.115 0 0" rpy="0 0 0" />
      <geometry>
        <box size="0.15 0.022 0.022" />
      </geometry>
    </collision>
    <inertial>
      <origin xyz="0.115 0 0" rpy="0 0 0" />
      <mass value="0.04" />
      <inertia ixx="3.226666666666666e-06" ixy="0.0" ixz="0.0" iyy="7.661333333333333e-05" iyz="0.0" izz="7.661333333333333e-05" />
    </inertial>
  </link>

  <joint name="white_joint_80" type="revolute">
    <parent link="base" />
    <child link="white_key_80" />
    <origin xyz="-0.04000000000000001 0.49450000000000005 -0.011" rpy="0 0 0" />
    <axis xyz="0 1 0" />
    <limit lower="0" upper="0.06307411789691225" effort="0.3" velocity="6.67" />
  </joint>

  <link name="black_key_81">
    <visual>
      <origin xyz="0.075 0 0" rpy="0 0 0" />
      <geometry>
        <box size="0.09 0.01 0.018" />
      </geometry>
      <material name="black" />
    </visual>
    <collision>
      <origin xyz="0.075 0 0" rpy="0 0 0" />
      <geometry>
        <box size="0.09 0.01 0.018" />
      </geometry>
    </collision>
    <inertial>
      <origin xyz="0.075 0 0" rpy="0 0 0" />
      <mass value="0.02" />
      <inertia ixx="7.066666666666665e-07" ixy="0.0" ixz="0.0" iyy="1.404e-05" iyz="0.0" izz="1.3666666666666664e-05" />
    </inertial>
  </link>

  <joint name="black_joint_81" type="revolute">
    <parent link="base" />
    <child link="black_key_81" />
    <origin xyz="-0.03 0.5065000000000001 0.0035000000000000014" rpy="0 0 0" />
    <axis xyz="0 1 0" />
    <limit lower="0" upper="0.06656816377582381" effort="0.3" velocity="6.67" />
  </joint>

  <link name="white_key_82">
    <visual>
      <origin xyz="0.115 0 0" rpy="0 0 0" />
      <geometry>
        <box size="0.15 0.022 0.022" />
      </geometry>
      <material name="white" />
    </visual>
    <collision>
      <origin xyz="0.115 0 0" rpy="0 0 0" />
      <geometry>
        <box size="0.15 0.022 0.022" />
      </geometry>
    </collision>
    <inertial>
      <origin xyz="0.115 0 0" rpy="0 0 0" />
      <mass value="0.04" />
      <inertia ixx="3.226666666666666e-06" ixy="0.0" ixz="0.0" iyy="7.661333333333333e-05" iyz="0.0" izz="7.661333333333333e-05" />
    </inertial>
  </link>

  <joint name="white_joint_82" type="revolute">
    <parent link="base" />
    <child link="white_key_82" />
    <origin xyz="-0.04000000000000001 0.5175000000000002 -0.011" rpy="0 0 0" />
    <axis xyz="0 1 0" />
    <limit lower="0" upper="0.06307411789691225" effort="0.3" velocity="6.67" />
  </joint>

  <link name="black_key_83">
    <visual>
      <origin xyz="0.075 0 0" rpy="0 0 0" />
      <geometry>
        <box size="0.09 0.01 0.018" />
      </geometry>
      <material name="black" />
    </visual>
    <collision>
      <origin xyz="0.075 0 0" rpy="0 0 0" />
      <geometry>
        <box size="0.09 0.01 0.018" />
      </geometry>
    </collision>
    <inertial>
      <origin xyz="0.075 0 0" rpy="0 0 0" />
      <mass value="0.02" />
      <inertia ixx="7.066666666666665e-07" ixy="0.0" ixz="0.0" iyy="1.404e-05" iyz="0.0" izz="1.3666666666666664e-05" />
    </inertial>
  </link>

  <joint name="black_joint_83" type="revolute">
    <parent link="base" />
    <child link="black_key_83" />
    <origin xyz="-0.03 0.5295000000000001 0.0035000000000000014" rpy="0 0 0" />
    <axis xyz="0 1 0" />
    <limit lower="0" upper="0.06656816377582381" effort="0.3" velocity="6.67" />
  </joint>

  <link name="white_key_84">
    <visual>
      <origin xyz="0.115 0 0" rpy="0 0 0" />
      <geometry>
        <box size="0.15 0.022 0.022" />
      </geometry>
      <material name="white" />
    </visual>
    <collision>
      <origin xyz="0.115 0 0" rpy="0 0 0" />
      <geometry>
        <box size="0.15 0.022 0.022" />
      </geometry>
    </collision>
    <inertial>
      <origin xyz="0.115 0 0" rpy="0 0 0" />
      <mass value="0.04" />
      <inertia ixx="3.226666666666666e-06" ixy="0.0" ixz="0.0" iyy="7.661333333333333e-05" iyz="0.0" izz="7.661333333333333e-05" />
    </inertial>
  </link>

  <joint name="white_joint_84" type="revolute">
    <parent link="base" />
    <child link="white_key_84" />
    <origin xyz="-0.04000000000000001 0.5405000000000001 -0.011" rpy="0 0 0" />
    <axis xyz="0 1 0" />
    <limit lower="0" upper="0.06307411789691225" effort="0.3" velocity="6.67" />
  </joint>

  <link name="black_key_85">
    <visual>
      <origin xyz="0.075 0 0" rpy="0 0 0" />
      <geometry>
        <box size="0.09 0.01 0.018" />
      </geometry>
      <material name="black" />
    </visual>
    <collision>
      <origin xyz="0.075 0 0" rpy="0 0 0" />
      <geometry>
        <box size="0.09 0.01 0.018" />
      </geometry>
    </collision>
    <inertial>
      <origin xyz="0.075 0 0" rpy="0 0 0" />
      <mass value="0.02" />
      <inertia ixx="7.066666666666665e-07" ixy="0.0" ixz="0.0" iyy="1.404e-05" iyz="0.0" izz="1.3666666666666664e-05" />
    </inertial>
  </link>

  <joint name="black_joint_85" type="revolute">
    <parent link="base" />
    <child link="black_key_85" />
    <origin xyz="-0.03 0.5525 0.0035000000000000014" rpy="0 0 0" />
    <axis xyz="0 1 0" />
    <limit lower="0" upper="0.06656816377582381" effort="0.3" velocity="6.67" />
  </joint>

  <link name="white_key_86">
    <visual>
      <origin xyz="0.115 0 0" rpy="0 0 0" />
      <geometry>
        <box size="0.15 0.022 0.022" />
      </geometry>
      <material name="white" />
    </visual>
    <collision>
      <origin xyz="0.115 0 0" rpy="0 0 0" />
      <geometry>
        <box size="0.15 0.022 0.022" />
      </geometry>
    </collision>
    <inertial>
      <origin xyz="0.115 0 0" rpy="0 0 0" />
      <mass value="0.04" />
      <inertia ixx="3.226666666666666e-06" ixy="0.0" ixz="0.0" iyy="7.661333333333333e-05" iyz="0.0" izz="7.661333333333333e-05" />
    </inertial>
  </link>

  <joint name="white_joint_86" type="revolute">
    <parent link="base" />
    <child link="white_key_86" />
    <origin xyz="-0.04000000000000001 0.5635 -0.011" rpy="0 0 0" />
    <axis xyz="0 1 0" />
    <limit lower="0" upper="0.06307411789691225" effort="0.3" velocity="6.67" />
  </joint>

  <link name="white_key_87">
    <visual>
      <origin xyz="0.115 0 0" rpy="0 0 0" />
      <geometry>
        <box size="0.15 0.022 0.022" />
      </geometry>
      <material name="white" />
    </visual>
    <collision>
      <origin xyz="0.115 0 0" rpy="0 0 0" />
      <geometry>
        <box size="0.15 0.022 0.022" />
      </geometry>
    </collision>
    <inertial>
      <origin xyz="0.115 0 0" rpy="0 0 0" />
      <mass value="0.04" />
      <inertia ixx="3.226666666666666e-06" ixy="0.0" ixz="0.0" iyy="7.661333333333333e-05" iyz="0.0" izz="7.661333333333333e-05" />
    </inertial>
  </link>

  <joint name="white_joint_87" type="revolute">
    <parent link="base" />
    <child link="white_key_87" />
    <origin xyz="-0.04000000000000001 0.5865000000000001 -0.011" rpy="0 0 0" />
    <axis xyz="0 1 0" />
    <limit lower="0" upper="0.06307411789691225" effort="0.3" velocity="6.67" />
  </joint>

</robot>