<?xml version="1.0" encoding="utf-8"?>
<robot name="piano">
  <material name="white">
    <color rgba="0.9 0.9 0.9 1" />
  </material>
  <material name="black">
    <color rgba="0.1 0.1 0.1 1" />
  </material>

  <!-- Base link -->
  <link name="base">
  </link>

  <!-- Piano body -->
  <link name="body">
    <visual>
      <origin xyz="-0.06 0 0.09" rpy="0 0 0" />
      <geometry>
        <box size="0.12 1.32 0.18" />
      </geometry>
    </visual>
    <visual>
      <origin xyz="0.027499999999999997 0 0.05900000000000001" rpy="0 0 0" />
      <geometry>
         <box size="0.295 1.32 0.11800000000000002" />
      </geometry>
    </visual>
    <collision>
      <origin xyz="-0.06 0 0.09" rpy="0 0 0" />
      <geometry>
         <box size="0.12 1.32 0.18" />
      </geometry>
    </collision>
    <collision>
      <origin xyz="0.027499999999999997 0 0.05900000000000001" rpy="0 0 0" />
      <geometry>
         <box size="0.295 1.32 0.11800000000000002" />
      </geometry>
    </collision>
    <inertial>
      <origin xyz="-0.06 0 0.09" rpy="0 0 0" />
      <mass value="10.0" />
      <inertia ixx="0.1" ixy="0.0" ixz="0.0" iyy="0.1" iyz="0.0" izz="0.1" />
    </inertial>
  </link>

  <joint name="base_body_joint" type="fixed">
    <parent link="base" />
    <child link="body" />
    <origin xyz="0 0 0" rpy="0 0 0" />
  </joint>

  <link name="key_0">
    <visual>
      <origin xyz="0.115 0 0" rpy="0 0 0" />
      <geometry>
        <box size="0.15 0.022 0.022" />
      </geometry>
      <material name="white" />
    </visual>
    <collision>
      <origin xyz="0.115 0 0" rpy="0 0 0" />
      <geometry>
        <box size="0.15 0.022 0.022" />
      </geometry>
    </collision>
    <inertial>
      <origin xyz="0.115 0 0" rpy="0 0 0" />
      <mass value="0.04" />
      <inertia ixx="3.226666666666666e-06" ixy="0.0" ixz="0.0" iyy="7.661333333333333e-05" iyz="0.0" izz="7.661333333333333e-05" />
    </inertial>
  </link>

  <joint name="key_0_joint" type="revolute">
    <parent link="base" />
    <child link="key_0" />
    <origin xyz="-0.04000000000000001 -0.5864999999999999 0.129" rpy="0 0 0" />
    <axis xyz="0 1 0" />
    <limit lower="0" upper="0.06307411789691225" effort="10.00" velocity="6.67" />
  </joint>

  <link name="key_2">
    <visual>
      <origin xyz="0.115 0 0" rpy="0 0 0" />
      <geometry>
        <box size="0.15 0.022 0.022" />
      </geometry>
      <material name="white" />
    </visual>
    <collision>
      <origin xyz="0.115 0 0" rpy="0 0 0" />
      <geometry>
        <box size="0.15 0.022 0.022" />
      </geometry>
    </collision>
    <inertial>
      <origin xyz="0.115 0 0" rpy="0 0 0" />
      <mass value="0.04" />
      <inertia ixx="3.226666666666666e-06" ixy="0.0" ixz="0.0" iyy="7.661333333333333e-05" iyz="0.0" izz="7.661333333333333e-05" />
    </inertial>
  </link>

  <joint name="key_2_joint" type="revolute">
    <parent link="base" />
    <child link="key_2" />
    <origin xyz="-0.04000000000000001 -0.5634999999999999 0.129" rpy="0 0 0" />
    <axis xyz="0 1 0" />
    <limit lower="0" upper="0.06307411789691225" effort="10.00" velocity="6.67" />
  </joint>

  <link name="key_3">
    <visual>
      <origin xyz="0.115 0 0" rpy="0 0 0" />
      <geometry>
        <box size="0.15 0.022 0.022" />
      </geometry>
      <material name="white" />
    </visual>
    <collision>
      <origin xyz="0.115 0 0" rpy="0 0 0" />
      <geometry>
        <box size="0.15 0.022 0.022" />
      </geometry>
    </collision>
    <inertial>
      <origin xyz="0.115 0 0" rpy="0 0 0" />
      <mass value="0.04" />
      <inertia ixx="3.226666666666666e-06" ixy="0.0" ixz="0.0" iyy="7.661333333333333e-05" iyz="0.0" izz="7.661333333333333e-05" />
    </inertial>
  </link>

  <joint name="key_3_joint" type="revolute">
    <parent link="base" />
    <child link="key_3" />
    <origin xyz="-0.04000000000000001 -0.5404999999999999 0.129" rpy="0 0 0" />
    <axis xyz="0 1 0" />
    <limit lower="0" upper="0.06307411789691225" effort="10.00" velocity="6.67" />
  </joint>

  <link name="key_5">
    <visual>
      <origin xyz="0.115 0 0" rpy="0 0 0" />
      <geometry>
        <box size="0.15 0.022 0.022" />
      </geometry>
      <material name="white" />
    </visual>
    <collision>
      <origin xyz="0.115 0 0" rpy="0 0 0" />
      <geometry>
        <box size="0.15 0.022 0.022" />
      </geometry>
    </collision>
    <inertial>
      <origin xyz="0.115 0 0" rpy="0 0 0" />
      <mass value="0.04" />
      <inertia ixx="3.226666666666666e-06" ixy="0.0" ixz="0.0" iyy="7.661333333333333e-05" iyz="0.0" izz="7.661333333333333e-05" />
    </inertial>
  </link>

  <joint name="key_5_joint" type="revolute">
    <parent link="base" />
    <child link="key_5" />
    <origin xyz="-0.04000000000000001 -0.5174999999999998 0.129" rpy="0 0 0" />
    <axis xyz="0 1 0" />
    <limit lower="0" upper="0.06307411789691225" effort="10.00" velocity="6.67" />
  </joint>

  <link name="key_7">
    <visual>
      <origin xyz="0.115 0 0" rpy="0 0 0" />
      <geometry>
        <box size="0.15 0.022 0.022" />
      </geometry>
      <material name="white" />
    </visual>
    <collision>
      <origin xyz="0.115 0 0" rpy="0 0 0" />
      <geometry>
        <box size="0.15 0.022 0.022" />
      </geometry>
    </collision>
    <inertial>
      <origin xyz="0.115 0 0" rpy="0 0 0" />
      <mass value="0.04" />
      <inertia ixx="3.226666666666666e-06" ixy="0.0" ixz="0.0" iyy="7.661333333333333e-05" iyz="0.0" izz="7.661333333333333e-05" />
    </inertial>
  </link>

  <joint name="key_7_joint" type="revolute">
    <parent link="base" />
    <child link="key_7" />
    <origin xyz="-0.04000000000000001 -0.49449999999999994 0.129" rpy="0 0 0" />
    <axis xyz="0 1 0" />
    <limit lower="0" upper="0.06307411789691225" effort="10.00" velocity="6.67" />
  </joint>

  <link name="key_8">
    <visual>
      <origin xyz="0.115 0 0" rpy="0 0 0" />
      <geometry>
        <box size="0.15 0.022 0.022" />
      </geometry>
      <material name="white" />
    </visual>
    <collision>
      <origin xyz="0.115 0 0" rpy="0 0 0" />
      <geometry>
        <box size="0.15 0.022 0.022" />
      </geometry>
    </collision>
    <inertial>
      <origin xyz="0.115 0 0" rpy="0 0 0" />
      <mass value="0.04" />
      <inertia ixx="3.226666666666666e-06" ixy="0.0" ixz="0.0" iyy="7.661333333333333e-05" iyz="0.0" izz="7.661333333333333e-05" />
    </inertial>
  </link>

  <joint name="key_8_joint" type="revolute">
    <parent link="base" />
    <child link="key_8" />
    <origin xyz="-0.04000000000000001 -0.4714999999999999 0.129" rpy="0 0 0" />
    <axis xyz="0 1 0" />
    <limit lower="0" upper="0.06307411789691225" effort="10.00" velocity="6.67" />
  </joint>

  <link name="key_10">
    <visual>
      <origin xyz="0.115 0 0" rpy="0 0 0" />
      <geometry>
        <box size="0.15 0.022 0.022" />
      </geometry>
      <material name="white" />
    </visual>
    <collision>
      <origin xyz="0.115 0 0" rpy="0 0 0" />
      <geometry>
        <box size="0.15 0.022 0.022" />
      </geometry>
    </collision>
    <inertial>
      <origin xyz="0.115 0 0" rpy="0 0 0" />
      <mass value="0.04" />
      <inertia ixx="3.226666666666666e-06" ixy="0.0" ixz="0.0" iyy="7.661333333333333e-05" iyz="0.0" izz="7.661333333333333e-05" />
    </inertial>
  </link>

  <joint name="key_10_joint" type="revolute">
    <parent link="base" />
    <child link="key_10" />
    <origin xyz="-0.04000000000000001 -0.4484999999999999 0.129" rpy="0 0 0" />
    <axis xyz="0 1 0" />
    <limit lower="0" upper="0.06307411789691225" effort="10.00" velocity="6.67" />
  </joint>

  <link name="key_12">
    <visual>
      <origin xyz="0.115 0 0" rpy="0 0 0" />
      <geometry>
        <box size="0.15 0.022 0.022" />
      </geometry>
      <material name="white" />
    </visual>
    <collision>
      <origin xyz="0.115 0 0" rpy="0 0 0" />
      <geometry>
        <box size="0.15 0.022 0.022" />
      </geometry>
    </collision>
    <inertial>
      <origin xyz="0.115 0 0" rpy="0 0 0" />
      <mass value="0.04" />
      <inertia ixx="3.226666666666666e-06" ixy="0.0" ixz="0.0" iyy="7.661333333333333e-05" iyz="0.0" izz="7.661333333333333e-05" />
    </inertial>
  </link>

  <joint name="key_12_joint" type="revolute">
    <parent link="base" />
    <child link="key_12" />
    <origin xyz="-0.04000000000000001 -0.4254999999999999 0.129" rpy="0 0 0" />
    <axis xyz="0 1 0" />
    <limit lower="0" upper="0.06307411789691225" effort="10.00" velocity="6.67" />
  </joint>

  <link name="key_14">
    <visual>
      <origin xyz="0.115 0 0" rpy="0 0 0" />
      <geometry>
        <box size="0.15 0.022 0.022" />
      </geometry>
      <material name="white" />
    </visual>
    <collision>
      <origin xyz="0.115 0 0" rpy="0 0 0" />
      <geometry>
        <box size="0.15 0.022 0.022" />
      </geometry>
    </collision>
    <inertial>
      <origin xyz="0.115 0 0" rpy="0 0 0" />
      <mass value="0.04" />
      <inertia ixx="3.226666666666666e-06" ixy="0.0" ixz="0.0" iyy="7.661333333333333e-05" iyz="0.0" izz="7.661333333333333e-05" />
    </inertial>
  </link>

  <joint name="key_14_joint" type="revolute">
    <parent link="base" />
    <child link="key_14" />
    <origin xyz="-0.04000000000000001 -0.4024999999999999 0.129" rpy="0 0 0" />
    <axis xyz="0 1 0" />
    <limit lower="0" upper="0.06307411789691225" effort="10.00" velocity="6.67" />
  </joint>

  <link name="key_15">
    <visual>
      <origin xyz="0.115 0 0" rpy="0 0 0" />
      <geometry>
        <box size="0.15 0.022 0.022" />
      </geometry>
      <material name="white" />
    </visual>
    <collision>
      <origin xyz="0.115 0 0" rpy="0 0 0" />
      <geometry>
        <box size="0.15 0.022 0.022" />
      </geometry>
    </collision>
    <inertial>
      <origin xyz="0.115 0 0" rpy="0 0 0" />
      <mass value="0.04" />
      <inertia ixx="3.226666666666666e-06" ixy="0.0" ixz="0.0" iyy="7.661333333333333e-05" iyz="0.0" izz="7.661333333333333e-05" />
    </inertial>
  </link>

  <joint name="key_15_joint" type="revolute">
    <parent link="base" />
    <child link="key_15" />
    <origin xyz="-0.04000000000000001 -0.37949999999999995 0.129" rpy="0 0 0" />
    <axis xyz="0 1 0" />
    <limit lower="0" upper="0.06307411789691225" effort="10.00" velocity="6.67" />
  </joint>

  <link name="key_17">
    <visual>
      <origin xyz="0.115 0 0" rpy="0 0 0" />
      <geometry>
        <box size="0.15 0.022 0.022" />
      </geometry>
      <material name="white" />
    </visual>
    <collision>
      <origin xyz="0.115 0 0" rpy="0 0 0" />
      <geometry>
        <box size="0.15 0.022 0.022" />
      </geometry>
    </collision>
    <inertial>
      <origin xyz="0.115 0 0" rpy="0 0 0" />
      <mass value="0.04" />
      <inertia ixx="3.226666666666666e-06" ixy="0.0" ixz="0.0" iyy="7.661333333333333e-05" iyz="0.0" izz="7.661333333333333e-05" />
    </inertial>
  </link>

  <joint name="key_17_joint" type="revolute">
    <parent link="base" />
    <child link="key_17" />
    <origin xyz="-0.04000000000000001 -0.35649999999999993 0.129" rpy="0 0 0" />
    <axis xyz="0 1 0" />
    <limit lower="0" upper="0.06307411789691225" effort="10.00" velocity="6.67" />
  </joint>

  <link name="key_19">
    <visual>
      <origin xyz="0.115 0 0" rpy="0 0 0" />
      <geometry>
        <box size="0.15 0.022 0.022" />
      </geometry>
      <material name="white" />
    </visual>
    <collision>
      <origin xyz="0.115 0 0" rpy="0 0 0" />
      <geometry>
        <box size="0.15 0.022 0.022" />
      </geometry>
    </collision>
    <inertial>
      <origin xyz="0.115 0 0" rpy="0 0 0" />
      <mass value="0.04" />
      <inertia ixx="3.226666666666666e-06" ixy="0.0" ixz="0.0" iyy="7.661333333333333e-05" iyz="0.0" izz="7.661333333333333e-05" />
    </inertial>
  </link>

  <joint name="key_19_joint" type="revolute">
    <parent link="base" />
    <child link="key_19" />
    <origin xyz="-0.04000000000000001 -0.3334999999999999 0.129" rpy="0 0 0" />
    <axis xyz="0 1 0" />
    <limit lower="0" upper="0.06307411789691225" effort="10.00" velocity="6.67" />
  </joint>

  <link name="key_20">
    <visual>
      <origin xyz="0.115 0 0" rpy="0 0 0" />
      <geometry>
        <box size="0.15 0.022 0.022" />
      </geometry>
      <material name="white" />
    </visual>
    <collision>
      <origin xyz="0.115 0 0" rpy="0 0 0" />
      <geometry>
        <box size="0.15 0.022 0.022" />
      </geometry>
    </collision>
    <inertial>
      <origin xyz="0.115 0 0" rpy="0 0 0" />
      <mass value="0.04" />
      <inertia ixx="3.226666666666666e-06" ixy="0.0" ixz="0.0" iyy="7.661333333333333e-05" iyz="0.0" izz="7.661333333333333e-05" />
    </inertial>
  </link>

  <joint name="key_20_joint" type="revolute">
    <parent link="base" />
    <child link="key_20" />
    <origin xyz="-0.04000000000000001 -0.3104999999999999 0.129" rpy="0 0 0" />
    <axis xyz="0 1 0" />
    <limit lower="0" upper="0.06307411789691225" effort="10.00" velocity="6.67" />
  </joint>

  <link name="key_22">
    <visual>
      <origin xyz="0.115 0 0" rpy="0 0 0" />
      <geometry>
        <box size="0.15 0.022 0.022" />
      </geometry>
      <material name="white" />
    </visual>
    <collision>
      <origin xyz="0.115 0 0" rpy="0 0 0" />
      <geometry>
        <box size="0.15 0.022 0.022" />
      </geometry>
    </collision>
    <inertial>
      <origin xyz="0.115 0 0" rpy="0 0 0" />
      <mass value="0.04" />
      <inertia ixx="3.226666666666666e-06" ixy="0.0" ixz="0.0" iyy="7.661333333333333e-05" iyz="0.0" izz="7.661333333333333e-05" />
    </inertial>
  </link>

  <joint name="key_22_joint" type="revolute">
    <parent link="base" />
    <child link="key_22" />
    <origin xyz="-0.04000000000000001 -0.2874999999999999 0.129" rpy="0 0 0" />
    <axis xyz="0 1 0" />
    <limit lower="0" upper="0.06307411789691225" effort="10.00" velocity="6.67" />
  </joint>

  <link name="key_24">
    <visual>
      <origin xyz="0.115 0 0" rpy="0 0 0" />
      <geometry>
        <box size="0.15 0.022 0.022" />
      </geometry>
      <material name="white" />
    </visual>
    <collision>
      <origin xyz="0.115 0 0" rpy="0 0 0" />
      <geometry>
        <box size="0.15 0.022 0.022" />
      </geometry>
    </collision>
    <inertial>
      <origin xyz="0.115 0 0" rpy="0 0 0" />
      <mass value="0.04" />
      <inertia ixx="3.226666666666666e-06" ixy="0.0" ixz="0.0" iyy="7.661333333333333e-05" iyz="0.0" izz="7.661333333333333e-05" />
    </inertial>
  </link>

  <joint name="key_24_joint" type="revolute">
    <parent link="base" />
    <child link="key_24" />
    <origin xyz="-0.04000000000000001 -0.2644999999999999 0.129" rpy="0 0 0" />
    <axis xyz="0 1 0" />
    <limit lower="0" upper="0.06307411789691225" effort="10.00" velocity="6.67" />
  </joint>

  <link name="key_26">
    <visual>
      <origin xyz="0.115 0 0" rpy="0 0 0" />
      <geometry>
        <box size="0.15 0.022 0.022" />
      </geometry>
      <material name="white" />
    </visual>
    <collision>
      <origin xyz="0.115 0 0" rpy="0 0 0" />
      <geometry>
        <box size="0.15 0.022 0.022" />
      </geometry>
    </collision>
    <inertial>
      <origin xyz="0.115 0 0" rpy="0 0 0" />
      <mass value="0.04" />
      <inertia ixx="3.226666666666666e-06" ixy="0.0" ixz="0.0" iyy="7.661333333333333e-05" iyz="0.0" izz="7.661333333333333e-05" />
    </inertial>
  </link>

  <joint name="key_26_joint" type="revolute">
    <parent link="base" />
    <child link="key_26" />
    <origin xyz="-0.04000000000000001 -0.24149999999999994 0.129" rpy="0 0 0" />
    <axis xyz="0 1 0" />
    <limit lower="0" upper="0.06307411789691225" effort="10.00" velocity="6.67" />
  </joint>

  <link name="key_27">
    <visual>
      <origin xyz="0.115 0 0" rpy="0 0 0" />
      <geometry>
        <box size="0.15 0.022 0.022" />
      </geometry>
      <material name="white" />
    </visual>
    <collision>
      <origin xyz="0.115 0 0" rpy="0 0 0" />
      <geometry>
        <box size="0.15 0.022 0.022" />
      </geometry>
    </collision>
    <inertial>
      <origin xyz="0.115 0 0" rpy="0 0 0" />
      <mass value="0.04" />
      <inertia ixx="3.226666666666666e-06" ixy="0.0" ixz="0.0" iyy="7.661333333333333e-05" iyz="0.0" izz="7.661333333333333e-05" />
    </inertial>
  </link>

  <joint name="key_27_joint" type="revolute">
    <parent link="base" />
    <child link="key_27" />
    <origin xyz="-0.04000000000000001 -0.21849999999999992 0.129" rpy="0 0 0" />
    <axis xyz="0 1 0" />
    <limit lower="0" upper="0.06307411789691225" effort="10.00" velocity="6.67" />
  </joint>

  <link name="key_29">
    <visual>
      <origin xyz="0.115 0 0" rpy="0 0 0" />
      <geometry>
        <box size="0.15 0.022 0.022" />
      </geometry>
      <material name="white" />
    </visual>
    <collision>
      <origin xyz="0.115 0 0" rpy="0 0 0" />
      <geometry>
        <box size="0.15 0.022 0.022" />
      </geometry>
    </collision>
    <inertial>
      <origin xyz="0.115 0 0" rpy="0 0 0" />
      <mass value="0.04" />
      <inertia ixx="3.226666666666666e-06" ixy="0.0" ixz="0.0" iyy="7.661333333333333e-05" iyz="0.0" izz="7.661333333333333e-05" />
    </inertial>
  </link>

  <joint name="key_29_joint" type="revolute">
    <parent link="base" />
    <child link="key_29" />
    <origin xyz="-0.04000000000000001 -0.1954999999999999 0.129" rpy="0 0 0" />
    <axis xyz="0 1 0" />
    <limit lower="0" upper="0.06307411789691225" effort="10.00" velocity="6.67" />
  </joint>

  <link name="key_31">
    <visual>
      <origin xyz="0.115 0 0" rpy="0 0 0" />
      <geometry>
        <box size="0.15 0.022 0.022" />
      </geometry>
      <material name="white" />
    </visual>
    <collision>
      <origin xyz="0.115 0 0" rpy="0 0 0" />
      <geometry>
        <box size="0.15 0.022 0.022" />
      </geometry>
    </collision>
    <inertial>
      <origin xyz="0.115 0 0" rpy="0 0 0" />
      <mass value="0.04" />
      <inertia ixx="3.226666666666666e-06" ixy="0.0" ixz="0.0" iyy="7.661333333333333e-05" iyz="0.0" izz="7.661333333333333e-05" />
    </inertial>
  </link>

  <joint name="key_31_joint" type="revolute">
    <parent link="base" />
    <child link="key_31" />
    <origin xyz="-0.04000000000000001 -0.17249999999999993 0.129" rpy="0 0 0" />
    <axis xyz="0 1 0" />
    <limit lower="0" upper="0.06307411789691225" effort="10.00" velocity="6.67" />
  </joint>

  <link name="key_32">
    <visual>
      <origin xyz="0.115 0 0" rpy="0 0 0" />
      <geometry>
        <box size="0.15 0.022 0.022" />
      </geometry>
      <material name="white" />
    </visual>
    <collision>
      <origin xyz="0.115 0 0" rpy="0 0 0" />
      <geometry>
        <box size="0.15 0.022 0.022" />
      </geometry>
    </collision>
    <inertial>
      <origin xyz="0.115 0 0" rpy="0 0 0" />
      <mass value="0.04" />
      <inertia ixx="3.226666666666666e-06" ixy="0.0" ixz="0.0" iyy="7.661333333333333e-05" iyz="0.0" izz="7.661333333333333e-05" />
    </inertial>
  </link>

  <joint name="key_32_joint" type="revolute">
    <parent link="base" />
    <child link="key_32" />
    <origin xyz="-0.04000000000000001 -0.1494999999999999 0.129" rpy="0 0 0" />
    <axis xyz="0 1 0" />
    <limit lower="0" upper="0.06307411789691225" effort="10.00" velocity="6.67" />
  </joint>

  <link name="key_34">
    <visual>
      <origin xyz="0.115 0 0" rpy="0 0 0" />
      <geometry>
        <box size="0.15 0.022 0.022" />
      </geometry>
      <material name="white" />
    </visual>
    <collision>
      <origin xyz="0.115 0 0" rpy="0 0 0" />
      <geometry>
        <box size="0.15 0.022 0.022" />
      </geometry>
    </collision>
    <inertial>
      <origin xyz="0.115 0 0" rpy="0 0 0" />
      <mass value="0.04" />
      <inertia ixx="3.226666666666666e-06" ixy="0.0" ixz="0.0" iyy="7.661333333333333e-05" iyz="0.0" izz="7.661333333333333e-05" />
    </inertial>
  </link>

  <joint name="key_34_joint" type="revolute">
    <parent link="base" />
    <child link="key_34" />
    <origin xyz="-0.04000000000000001 -0.12649999999999995 0.129" rpy="0 0 0" />
    <axis xyz="0 1 0" />
    <limit lower="0" upper="0.06307411789691225" effort="10.00" velocity="6.67" />
  </joint>

  <link name="key_36">
    <visual>
      <origin xyz="0.115 0 0" rpy="0 0 0" />
      <geometry>
        <box size="0.15 0.022 0.022" />
      </geometry>
      <material name="white" />
    </visual>
    <collision>
      <origin xyz="0.115 0 0" rpy="0 0 0" />
      <geometry>
        <box size="0.15 0.022 0.022" />
      </geometry>
    </collision>
    <inertial>
      <origin xyz="0.115 0 0" rpy="0 0 0" />
      <mass value="0.04" />
      <inertia ixx="3.226666666666666e-06" ixy="0.0" ixz="0.0" iyy="7.661333333333333e-05" iyz="0.0" izz="7.661333333333333e-05" />
    </inertial>
  </link>

  <joint name="key_36_joint" type="revolute">
    <parent link="base" />
    <child link="key_36" />
    <origin xyz="-0.04000000000000001 -0.10349999999999993 0.129" rpy="0 0 0" />
    <axis xyz="0 1 0" />
    <limit lower="0" upper="0.06307411789691225" effort="10.00" velocity="6.67" />
  </joint>

  <link name="key_38">
    <visual>
      <origin xyz="0.115 0 0" rpy="0 0 0" />
      <geometry>
        <box size="0.15 0.022 0.022" />
      </geometry>
      <material name="white" />
    </visual>
    <collision>
      <origin xyz="0.115 0 0" rpy="0 0 0" />
      <geometry>
        <box size="0.15 0.022 0.022" />
      </geometry>
    </collision>
    <inertial>
      <origin xyz="0.115 0 0" rpy="0 0 0" />
      <mass value="0.04" />
      <inertia ixx="3.226666666666666e-06" ixy="0.0" ixz="0.0" iyy="7.661333333333333e-05" iyz="0.0" izz="7.661333333333333e-05" />
    </inertial>
  </link>

  <joint name="key_38_joint" type="revolute">
    <parent link="base" />
    <child link="key_38" />
    <origin xyz="-0.04000000000000001 -0.0804999999999999 0.129" rpy="0 0 0" />
    <axis xyz="0 1 0" />
    <limit lower="0" upper="0.06307411789691225" effort="10.00" velocity="6.67" />
  </joint>

  <link name="key_39">
    <visual>
      <origin xyz="0.115 0 0" rpy="0 0 0" />
      <geometry>
        <box size="0.15 0.022 0.022" />
      </geometry>
      <material name="white" />
    </visual>
    <collision>
      <origin xyz="0.115 0 0" rpy="0 0 0" />
      <geometry>
        <box size="0.15 0.022 0.022" />
      </geometry>
    </collision>
    <inertial>
      <origin xyz="0.115 0 0" rpy="0 0 0" />
      <mass value="0.04" />
      <inertia ixx="3.226666666666666e-06" ixy="0.0" ixz="0.0" iyy="7.661333333333333e-05" iyz="0.0" izz="7.661333333333333e-05" />
    </inertial>
  </link>

  <joint name="key_39_joint" type="revolute">
    <parent link="base" />
    <child link="key_39" />
    <origin xyz="-0.04000000000000001 -0.057499999999999885 0.129" rpy="0 0 0" />
    <axis xyz="0 1 0" />
    <limit lower="0" upper="0.06307411789691225" effort="10.00" velocity="6.67" />
  </joint>

  <link name="key_41">
    <visual>
      <origin xyz="0.115 0 0" rpy="0 0 0" />
      <geometry>
        <box size="0.15 0.022 0.022" />
      </geometry>
      <material name="white" />
    </visual>
    <collision>
      <origin xyz="0.115 0 0" rpy="0 0 0" />
      <geometry>
        <box size="0.15 0.022 0.022" />
      </geometry>
    </collision>
    <inertial>
      <origin xyz="0.115 0 0" rpy="0 0 0" />
      <mass value="0.04" />
      <inertia ixx="3.226666666666666e-06" ixy="0.0" ixz="0.0" iyy="7.661333333333333e-05" iyz="0.0" izz="7.661333333333333e-05" />
    </inertial>
  </link>

  <joint name="key_41_joint" type="revolute">
    <parent link="base" />
    <child link="key_41" />
    <origin xyz="-0.04000000000000001 -0.034499999999999864 0.129" rpy="0 0 0" />
    <axis xyz="0 1 0" />
    <limit lower="0" upper="0.06307411789691225" effort="10.00" velocity="6.67" />
  </joint>

  <link name="key_43">
    <visual>
      <origin xyz="0.115 0 0" rpy="0 0 0" />
      <geometry>
        <box size="0.15 0.022 0.022" />
      </geometry>
      <material name="white" />
    </visual>
    <collision>
      <origin xyz="0.115 0 0" rpy="0 0 0" />
      <geometry>
        <box size="0.15 0.022 0.022" />
      </geometry>
    </collision>
    <inertial>
      <origin xyz="0.115 0 0" rpy="0 0 0" />
      <mass value="0.04" />
      <inertia ixx="3.226666666666666e-06" ixy="0.0" ixz="0.0" iyy="7.661333333333333e-05" iyz="0.0" izz="7.661333333333333e-05" />
    </inertial>
  </link>

  <joint name="key_43_joint" type="revolute">
    <parent link="base" />
    <child link="key_43" />
    <origin xyz="-0.04000000000000001 -0.011499999999999955 0.129" rpy="0 0 0" />
    <axis xyz="0 1 0" />
    <limit lower="0" upper="0.06307411789691225" effort="10.00" velocity="6.67" />
  </joint>

  <link name="key_44">
    <visual>
      <origin xyz="0.115 0 0" rpy="0 0 0" />
      <geometry>
        <box size="0.15 0.022 0.022" />
      </geometry>
      <material name="white" />
    </visual>
    <collision>
      <origin xyz="0.115 0 0" rpy="0 0 0" />
      <geometry>
        <box size="0.15 0.022 0.022" />
      </geometry>
    </collision>
    <inertial>
      <origin xyz="0.115 0 0" rpy="0 0 0" />
      <mass value="0.04" />
      <inertia ixx="3.226666666666666e-06" ixy="0.0" ixz="0.0" iyy="7.661333333333333e-05" iyz="0.0" izz="7.661333333333333e-05" />
    </inertial>
  </link>

  <joint name="key_44_joint" type="revolute">
    <parent link="base" />
    <child link="key_44" />
    <origin xyz="-0.04000000000000001 0.011500000000000066 0.129" rpy="0 0 0" />
    <axis xyz="0 1 0" />
    <limit lower="0" upper="0.06307411789691225" effort="10.00" velocity="6.67" />
  </joint>

  <link name="key_46">
    <visual>
      <origin xyz="0.115 0 0" rpy="0 0 0" />
      <geometry>
        <box size="0.15 0.022 0.022" />
      </geometry>
      <material name="white" />
    </visual>
    <collision>
      <origin xyz="0.115 0 0" rpy="0 0 0" />
      <geometry>
        <box size="0.15 0.022 0.022" />
      </geometry>
    </collision>
    <inertial>
      <origin xyz="0.115 0 0" rpy="0 0 0" />
      <mass value="0.04" />
      <inertia ixx="3.226666666666666e-06" ixy="0.0" ixz="0.0" iyy="7.661333333333333e-05" iyz="0.0" izz="7.661333333333333e-05" />
    </inertial>
  </link>

  <joint name="key_46_joint" type="revolute">
    <parent link="base" />
    <child link="key_46" />
    <origin xyz="-0.04000000000000001 0.034500000000000086 0.129" rpy="0 0 0" />
    <axis xyz="0 1 0" />
    <limit lower="0" upper="0.06307411789691225" effort="10.00" velocity="6.67" />
  </joint>

  <link name="key_48">
    <visual>
      <origin xyz="0.115 0 0" rpy="0 0 0" />
      <geometry>
        <box size="0.15 0.022 0.022" />
      </geometry>
      <material name="white" />
    </visual>
    <collision>
      <origin xyz="0.115 0 0" rpy="0 0 0" />
      <geometry>
        <box size="0.15 0.022 0.022" />
      </geometry>
    </collision>
    <inertial>
      <origin xyz="0.115 0 0" rpy="0 0 0" />
      <mass value="0.04" />
      <inertia ixx="3.226666666666666e-06" ixy="0.0" ixz="0.0" iyy="7.661333333333333e-05" iyz="0.0" izz="7.661333333333333e-05" />
    </inertial>
  </link>

  <joint name="key_48_joint" type="revolute">
    <parent link="base" />
    <child link="key_48" />
    <origin xyz="-0.04000000000000001 0.05750000000000011 0.129" rpy="0 0 0" />
    <axis xyz="0 1 0" />
    <limit lower="0" upper="0.06307411789691225" effort="10.00" velocity="6.67" />
  </joint>

  <link name="key_50">
    <visual>
      <origin xyz="0.115 0 0" rpy="0 0 0" />
      <geometry>
        <box size="0.15 0.022 0.022" />
      </geometry>
      <material name="white" />
    </visual>
    <collision>
      <origin xyz="0.115 0 0" rpy="0 0 0" />
      <geometry>
        <box size="0.15 0.022 0.022" />
      </geometry>
    </collision>
    <inertial>
      <origin xyz="0.115 0 0" rpy="0 0 0" />
      <mass value="0.04" />
      <inertia ixx="3.226666666666666e-06" ixy="0.0" ixz="0.0" iyy="7.661333333333333e-05" iyz="0.0" izz="7.661333333333333e-05" />
    </inertial>
  </link>

  <joint name="key_50_joint" type="revolute">
    <parent link="base" />
    <child link="key_50" />
    <origin xyz="-0.04000000000000001 0.08050000000000013 0.129" rpy="0 0 0" />
    <axis xyz="0 1 0" />
    <limit lower="0" upper="0.06307411789691225" effort="10.00" velocity="6.67" />
  </joint>

  <link name="key_51">
    <visual>
      <origin xyz="0.115 0 0" rpy="0 0 0" />
      <geometry>
        <box size="0.15 0.022 0.022" />
      </geometry>
      <material name="white" />
    </visual>
    <collision>
      <origin xyz="0.115 0 0" rpy="0 0 0" />
      <geometry>
        <box size="0.15 0.022 0.022" />
      </geometry>
    </collision>
    <inertial>
      <origin xyz="0.115 0 0" rpy="0 0 0" />
      <mass value="0.04" />
      <inertia ixx="3.226666666666666e-06" ixy="0.0" ixz="0.0" iyy="7.661333333333333e-05" iyz="0.0" izz="7.661333333333333e-05" />
    </inertial>
  </link>

  <joint name="key_51_joint" type="revolute">
    <parent link="base" />
    <child link="key_51" />
    <origin xyz="-0.04000000000000001 0.10350000000000004 0.129" rpy="0 0 0" />
    <axis xyz="0 1 0" />
    <limit lower="0" upper="0.06307411789691225" effort="10.00" velocity="6.67" />
  </joint>

  <link name="key_53">
    <visual>
      <origin xyz="0.115 0 0" rpy="0 0 0" />
      <geometry>
        <box size="0.15 0.022 0.022" />
      </geometry>
      <material name="white" />
    </visual>
    <collision>
      <origin xyz="0.115 0 0" rpy="0 0 0" />
      <geometry>
        <box size="0.15 0.022 0.022" />
      </geometry>
    </collision>
    <inertial>
      <origin xyz="0.115 0 0" rpy="0 0 0" />
      <mass value="0.04" />
      <inertia ixx="3.226666666666666e-06" ixy="0.0" ixz="0.0" iyy="7.661333333333333e-05" iyz="0.0" izz="7.661333333333333e-05" />
    </inertial>
  </link>

  <joint name="key_53_joint" type="revolute">
    <parent link="base" />
    <child link="key_53" />
    <origin xyz="-0.04000000000000001 0.12650000000000006 0.129" rpy="0 0 0" />
    <axis xyz="0 1 0" />
    <limit lower="0" upper="0.06307411789691225" effort="10.00" velocity="6.67" />
  </joint>

  <link name="key_55">
    <visual>
      <origin xyz="0.115 0 0" rpy="0 0 0" />
      <geometry>
        <box size="0.15 0.022 0.022" />
      </geometry>
      <material name="white" />
    </visual>
    <collision>
      <origin xyz="0.115 0 0" rpy="0 0 0" />
      <geometry>
        <box size="0.15 0.022 0.022" />
      </geometry>
    </collision>
    <inertial>
      <origin xyz="0.115 0 0" rpy="0 0 0" />
      <mass value="0.04" />
      <inertia ixx="3.226666666666666e-06" ixy="0.0" ixz="0.0" iyy="7.661333333333333e-05" iyz="0.0" izz="7.661333333333333e-05" />
    </inertial>
  </link>

  <joint name="key_55_joint" type="revolute">
    <parent link="base" />
    <child link="key_55" />
    <origin xyz="-0.04000000000000001 0.14950000000000008 0.129" rpy="0 0 0" />
    <axis xyz="0 1 0" />
    <limit lower="0" upper="0.06307411789691225" effort="10.00" velocity="6.67" />
  </joint>

  <link name="key_56">
    <visual>
      <origin xyz="0.115 0 0" rpy="0 0 0" />
      <geometry>
        <box size="0.15 0.022 0.022" />
      </geometry>
      <material name="white" />
    </visual>
    <collision>
      <origin xyz="0.115 0 0" rpy="0 0 0" />
      <geometry>
        <box size="0.15 0.022 0.022" />
      </geometry>
    </collision>
    <inertial>
      <origin xyz="0.115 0 0" rpy="0 0 0" />
      <mass value="0.04" />
      <inertia ixx="3.226666666666666e-06" ixy="0.0" ixz="0.0" iyy="7.661333333333333e-05" iyz="0.0" izz="7.661333333333333e-05" />
    </inertial>
  </link>

  <joint name="key_56_joint" type="revolute">
    <parent link="base" />
    <child link="key_56" />
    <origin xyz="-0.04000000000000001 0.1725000000000001 0.129" rpy="0 0 0" />
    <axis xyz="0 1 0" />
    <limit lower="0" upper="0.06307411789691225" effort="10.00" velocity="6.67" />
  </joint>

  <link name="key_58">
    <visual>
      <origin xyz="0.115 0 0" rpy="0 0 0" />
      <geometry>
        <box size="0.15 0.022 0.022" />
      </geometry>
      <material name="white" />
    </visual>
    <collision>
      <origin xyz="0.115 0 0" rpy="0 0 0" />
      <geometry>
        <box size="0.15 0.022 0.022" />
      </geometry>
    </collision>
    <inertial>
      <origin xyz="0.115 0 0" rpy="0 0 0" />
      <mass value="0.04" />
      <inertia ixx="3.226666666666666e-06" ixy="0.0" ixz="0.0" iyy="7.661333333333333e-05" iyz="0.0" izz="7.661333333333333e-05" />
    </inertial>
  </link>

  <joint name="key_58_joint" type="revolute">
    <parent link="base" />
    <child link="key_58" />
    <origin xyz="-0.04000000000000001 0.19550000000000012 0.129" rpy="0 0 0" />
    <axis xyz="0 1 0" />
    <limit lower="0" upper="0.06307411789691225" effort="10.00" velocity="6.67" />
  </joint>

  <link name="key_60">
    <visual>
      <origin xyz="0.115 0 0" rpy="0 0 0" />
      <geometry>
        <box size="0.15 0.022 0.022" />
      </geometry>
      <material name="white" />
    </visual>
    <collision>
      <origin xyz="0.115 0 0" rpy="0 0 0" />
      <geometry>
        <box size="0.15 0.022 0.022" />
      </geometry>
    </collision>
    <inertial>
      <origin xyz="0.115 0 0" rpy="0 0 0" />
      <mass value="0.04" />
      <inertia ixx="3.226666666666666e-06" ixy="0.0" ixz="0.0" iyy="7.661333333333333e-05" iyz="0.0" izz="7.661333333333333e-05" />
    </inertial>
  </link>

  <joint name="key_60_joint" type="revolute">
    <parent link="base" />
    <child link="key_60" />
    <origin xyz="-0.04000000000000001 0.21850000000000003 0.129" rpy="0 0 0" />
    <axis xyz="0 1 0" />
    <limit lower="0" upper="0.06307411789691225" effort="10.00" velocity="6.67" />
  </joint>

  <link name="key_62">
    <visual>
      <origin xyz="0.115 0 0" rpy="0 0 0" />
      <geometry>
        <box size="0.15 0.022 0.022" />
      </geometry>
      <material name="white" />
    </visual>
    <collision>
      <origin xyz="0.115 0 0" rpy="0 0 0" />
      <geometry>
        <box size="0.15 0.022 0.022" />
      </geometry>
    </collision>
    <inertial>
      <origin xyz="0.115 0 0" rpy="0 0 0" />
      <mass value="0.04" />
      <inertia ixx="3.226666666666666e-06" ixy="0.0" ixz="0.0" iyy="7.661333333333333e-05" iyz="0.0" izz="7.661333333333333e-05" />
    </inertial>
  </link>

  <joint name="key_62_joint" type="revolute">
    <parent link="base" />
    <child link="key_62" />
    <origin xyz="-0.04000000000000001 0.24150000000000005 0.129" rpy="0 0 0" />
    <axis xyz="0 1 0" />
    <limit lower="0" upper="0.06307411789691225" effort="10.00" velocity="6.67" />
  </joint>

  <link name="key_63">
    <visual>
      <origin xyz="0.115 0 0" rpy="0 0 0" />
      <geometry>
        <box size="0.15 0.022 0.022" />
      </geometry>
      <material name="white" />
    </visual>
    <collision>
      <origin xyz="0.115 0 0" rpy="0 0 0" />
      <geometry>
        <box size="0.15 0.022 0.022" />
      </geometry>
    </collision>
    <inertial>
      <origin xyz="0.115 0 0" rpy="0 0 0" />
      <mass value="0.04" />
      <inertia ixx="3.226666666666666e-06" ixy="0.0" ixz="0.0" iyy="7.661333333333333e-05" iyz="0.0" izz="7.661333333333333e-05" />
    </inertial>
  </link>

  <joint name="key_63_joint" type="revolute">
    <parent link="base" />
    <child link="key_63" />
    <origin xyz="-0.04000000000000001 0.26450000000000007 0.129" rpy="0 0 0" />
    <axis xyz="0 1 0" />
    <limit lower="0" upper="0.06307411789691225" effort="10.00" velocity="6.67" />
  </joint>

  <link name="key_65">
    <visual>
      <origin xyz="0.115 0 0" rpy="0 0 0" />
      <geometry>
        <box size="0.15 0.022 0.022" />
      </geometry>
      <material name="white" />
    </visual>
    <collision>
      <origin xyz="0.115 0 0" rpy="0 0 0" />
      <geometry>
        <box size="0.15 0.022 0.022" />
      </geometry>
    </collision>
    <inertial>
      <origin xyz="0.115 0 0" rpy="0 0 0" />
      <mass value="0.04" />
      <inertia ixx="3.226666666666666e-06" ixy="0.0" ixz="0.0" iyy="7.661333333333333e-05" iyz="0.0" izz="7.661333333333333e-05" />
    </inertial>
  </link>

  <joint name="key_65_joint" type="revolute">
    <parent link="base" />
    <child link="key_65" />
    <origin xyz="-0.04000000000000001 0.2875000000000001 0.129" rpy="0 0 0" />
    <axis xyz="0 1 0" />
    <limit lower="0" upper="0.06307411789691225" effort="10.00" velocity="6.67" />
  </joint>

  <link name="key_67">
    <visual>
      <origin xyz="0.115 0 0" rpy="0 0 0" />
      <geometry>
        <box size="0.15 0.022 0.022" />
      </geometry>
      <material name="white" />
    </visual>
    <collision>
      <origin xyz="0.115 0 0" rpy="0 0 0" />
      <geometry>
        <box size="0.15 0.022 0.022" />
      </geometry>
    </collision>
    <inertial>
      <origin xyz="0.115 0 0" rpy="0 0 0" />
      <mass value="0.04" />
      <inertia ixx="3.226666666666666e-06" ixy="0.0" ixz="0.0" iyy="7.661333333333333e-05" iyz="0.0" izz="7.661333333333333e-05" />
    </inertial>
  </link>

  <joint name="key_67_joint" type="revolute">
    <parent link="base" />
    <child link="key_67" />
    <origin xyz="-0.04000000000000001 0.3105000000000001 0.129" rpy="0 0 0" />
    <axis xyz="0 1 0" />
    <limit lower="0" upper="0.06307411789691225" effort="10.00" velocity="6.67" />
  </joint>

  <link name="key_68">
    <visual>
      <origin xyz="0.115 0 0" rpy="0 0 0" />
      <geometry>
        <box size="0.15 0.022 0.022" />
      </geometry>
      <material name="white" />
    </visual>
    <collision>
      <origin xyz="0.115 0 0" rpy="0 0 0" />
      <geometry>
        <box size="0.15 0.022 0.022" />
      </geometry>
    </collision>
    <inertial>
      <origin xyz="0.115 0 0" rpy="0 0 0" />
      <mass value="0.04" />
      <inertia ixx="3.226666666666666e-06" ixy="0.0" ixz="0.0" iyy="7.661333333333333e-05" iyz="0.0" izz="7.661333333333333e-05" />
    </inertial>
  </link>

  <joint name="key_68_joint" type="revolute">
    <parent link="base" />
    <child link="key_68" />
    <origin xyz="-0.04000000000000001 0.3335 0.129" rpy="0 0 0" />
    <axis xyz="0 1 0" />
    <limit lower="0" upper="0.06307411789691225" effort="10.00" velocity="6.67" />
  </joint>

  <link name="key_70">
    <visual>
      <origin xyz="0.115 0 0" rpy="0 0 0" />
      <geometry>
        <box size="0.15 0.022 0.022" />
      </geometry>
      <material name="white" />
    </visual>
    <collision>
      <origin xyz="0.115 0 0" rpy="0 0 0" />
      <geometry>
        <box size="0.15 0.022 0.022" />
      </geometry>
    </collision>
    <inertial>
      <origin xyz="0.115 0 0" rpy="0 0 0" />
      <mass value="0.04" />
      <inertia ixx="3.226666666666666e-06" ixy="0.0" ixz="0.0" iyy="7.661333333333333e-05" iyz="0.0" izz="7.661333333333333e-05" />
    </inertial>
  </link>

  <joint name="key_70_joint" type="revolute">
    <parent link="base" />
    <child link="key_70" />
    <origin xyz="-0.04000000000000001 0.35650000000000004 0.129" rpy="0 0 0" />
    <axis xyz="0 1 0" />
    <limit lower="0" upper="0.06307411789691225" effort="10.00" velocity="6.67" />
  </joint>

  <link name="key_72">
    <visual>
      <origin xyz="0.115 0 0" rpy="0 0 0" />
      <geometry>
        <box size="0.15 0.022 0.022" />
      </geometry>
      <material name="white" />
    </visual>
    <collision>
      <origin xyz="0.115 0 0" rpy="0 0 0" />
      <geometry>
        <box size="0.15 0.022 0.022" />
      </geometry>
    </collision>
    <inertial>
      <origin xyz="0.115 0 0" rpy="0 0 0" />
      <mass value="0.04" />
      <inertia ixx="3.226666666666666e-06" ixy="0.0" ixz="0.0" iyy="7.661333333333333e-05" iyz="0.0" izz="7.661333333333333e-05" />
    </inertial>
  </link>

  <joint name="key_72_joint" type="revolute">
    <parent link="base" />
    <child link="key_72" />
    <origin xyz="-0.04000000000000001 0.37950000000000006 0.129" rpy="0 0 0" />
    <axis xyz="0 1 0" />
    <limit lower="0" upper="0.06307411789691225" effort="10.00" velocity="6.67" />
  </joint>

  <link name="key_74">
    <visual>
      <origin xyz="0.115 0 0" rpy="0 0 0" />
      <geometry>
        <box size="0.15 0.022 0.022" />
      </geometry>
      <material name="white" />
    </visual>
    <collision>
      <origin xyz="0.115 0 0" rpy="0 0 0" />
      <geometry>
        <box size="0.15 0.022 0.022" />
      </geometry>
    </collision>
    <inertial>
      <origin xyz="0.115 0 0" rpy="0 0 0" />
      <mass value="0.04" />
      <inertia ixx="3.226666666666666e-06" ixy="0.0" ixz="0.0" iyy="7.661333333333333e-05" iyz="0.0" izz="7.661333333333333e-05" />
    </inertial>
  </link>

  <joint name="key_74_joint" type="revolute">
    <parent link="base" />
    <child link="key_74" />
    <origin xyz="-0.04000000000000001 0.4025000000000001 0.129" rpy="0 0 0" />
    <axis xyz="0 1 0" />
    <limit lower="0" upper="0.06307411789691225" effort="10.00" velocity="6.67" />
  </joint>

  <link name="key_75">
    <visual>
      <origin xyz="0.115 0 0" rpy="0 0 0" />
      <geometry>
        <box size="0.15 0.022 0.022" />
      </geometry>
      <material name="white" />
    </visual>
    <collision>
      <origin xyz="0.115 0 0" rpy="0 0 0" />
      <geometry>
        <box size="0.15 0.022 0.022" />
      </geometry>
    </collision>
    <inertial>
      <origin xyz="0.115 0 0" rpy="0 0 0" />
      <mass value="0.04" />
      <inertia ixx="3.226666666666666e-06" ixy="0.0" ixz="0.0" iyy="7.661333333333333e-05" iyz="0.0" izz="7.661333333333333e-05" />
    </inertial>
  </link>

  <joint name="key_75_joint" type="revolute">
    <parent link="base" />
    <child link="key_75" />
    <origin xyz="-0.04000000000000001 0.4255000000000001 0.129" rpy="0 0 0" />
    <axis xyz="0 1 0" />
    <limit lower="0" upper="0.06307411789691225" effort="10.00" velocity="6.67" />
  </joint>

  <link name="key_77">
    <visual>
      <origin xyz="0.115 0 0" rpy="0 0 0" />
      <geometry>
        <box size="0.15 0.022 0.022" />
      </geometry>
      <material name="white" />
    </visual>
    <collision>
      <origin xyz="0.115 0 0" rpy="0 0 0" />
      <geometry>
        <box size="0.15 0.022 0.022" />
      </geometry>
    </collision>
    <inertial>
      <origin xyz="0.115 0 0" rpy="0 0 0" />
      <mass value="0.04" />
      <inertia ixx="3.226666666666666e-06" ixy="0.0" ixz="0.0" iyy="7.661333333333333e-05" iyz="0.0" izz="7.661333333333333e-05" />
    </inertial>
  </link>

  <joint name="key_77_joint" type="revolute">
    <parent link="base" />
    <child link="key_77" />
    <origin xyz="-0.04000000000000001 0.4485 0.129" rpy="0 0 0" />
    <axis xyz="0 1 0" />
    <limit lower="0" upper="0.06307411789691225" effort="10.00" velocity="6.67" />
  </joint>

  <link name="key_79">
    <visual>
      <origin xyz="0.115 0 0" rpy="0 0 0" />
      <geometry>
        <box size="0.15 0.022 0.022" />
      </geometry>
      <material name="white" />
    </visual>
    <collision>
      <origin xyz="0.115 0 0" rpy="0 0 0" />
      <geometry>
        <box size="0.15 0.022 0.022" />
      </geometry>
    </collision>
    <inertial>
      <origin xyz="0.115 0 0" rpy="0 0 0" />
      <mass value="0.04" />
      <inertia ixx="3.226666666666666e-06" ixy="0.0" ixz="0.0" iyy="7.661333333333333e-05" iyz="0.0" izz="7.661333333333333e-05" />
    </inertial>
  </link>

  <joint name="key_79_joint" type="revolute">
    <parent link="base" />
    <child link="key_79" />
    <origin xyz="-0.04000000000000001 0.47150000000000014 0.129" rpy="0 0 0" />
    <axis xyz="0 1 0" />
    <limit lower="0" upper="0.06307411789691225" effort="10.00" velocity="6.67" />
  </joint>

  <link name="key_80">
    <visual>
      <origin xyz="0.115 0 0" rpy="0 0 0" />
      <geometry>
        <box size="0.15 0.022 0.022" />
      </geometry>
      <material name="white" />
    </visual>
    <collision>
      <origin xyz="0.115 0 0" rpy="0 0 0" />
      <geometry>
        <box size="0.15 0.022 0.022" />
      </geometry>
    </collision>
    <inertial>
      <origin xyz="0.115 0 0" rpy="0 0 0" />
      <mass value="0.04" />
      <inertia ixx="3.226666666666666e-06" ixy="0.0" ixz="0.0" iyy="7.661333333333333e-05" iyz="0.0" izz="7.661333333333333e-05" />
    </inertial>
  </link>

  <joint name="key_80_joint" type="revolute">
    <parent link="base" />
    <child link="key_80" />
    <origin xyz="-0.04000000000000001 0.49450000000000005 0.129" rpy="0 0 0" />
    <axis xyz="0 1 0" />
    <limit lower="0" upper="0.06307411789691225" effort="10.00" velocity="6.67" />
  </joint>

  <link name="key_82">
    <visual>
      <origin xyz="0.115 0 0" rpy="0 0 0" />
      <geometry>
        <box size="0.15 0.022 0.022" />
      </geometry>
      <material name="white" />
    </visual>
    <collision>
      <origin xyz="0.115 0 0" rpy="0 0 0" />
      <geometry>
        <box size="0.15 0.022 0.022" />
      </geometry>
    </collision>
    <inertial>
      <origin xyz="0.115 0 0" rpy="0 0 0" />
      <mass value="0.04" />
      <inertia ixx="3.226666666666666e-06" ixy="0.0" ixz="0.0" iyy="7.661333333333333e-05" iyz="0.0" izz="7.661333333333333e-05" />
    </inertial>
  </link>

  <joint name="key_82_joint" type="revolute">
    <parent link="base" />
    <child link="key_82" />
    <origin xyz="-0.04000000000000001 0.5175000000000002 0.129" rpy="0 0 0" />
    <axis xyz="0 1 0" />
    <limit lower="0" upper="0.06307411789691225" effort="10.00" velocity="6.67" />
  </joint>

  <link name="key_84">
    <visual>
      <origin xyz="0.115 0 0" rpy="0 0 0" />
      <geometry>
        <box size="0.15 0.022 0.022" />
      </geometry>
      <material name="white" />
    </visual>
    <collision>
      <origin xyz="0.115 0 0" rpy="0 0 0" />
      <geometry>
        <box size="0.15 0.022 0.022" />
      </geometry>
    </collision>
    <inertial>
      <origin xyz="0.115 0 0" rpy="0 0 0" />
      <mass value="0.04" />
      <inertia ixx="3.226666666666666e-06" ixy="0.0" ixz="0.0" iyy="7.661333333333333e-05" iyz="0.0" izz="7.661333333333333e-05" />
    </inertial>
  </link>

  <joint name="key_84_joint" type="revolute">
    <parent link="base" />
    <child link="key_84" />
    <origin xyz="-0.04000000000000001 0.5405000000000001 0.129" rpy="0 0 0" />
    <axis xyz="0 1 0" />
    <limit lower="0" upper="0.06307411789691225" effort="10.00" velocity="6.67" />
  </joint>

  <link name="key_86">
    <visual>
      <origin xyz="0.115 0 0" rpy="0 0 0" />
      <geometry>
        <box size="0.15 0.022 0.022" />
      </geometry>
      <material name="white" />
    </visual>
    <collision>
      <origin xyz="0.115 0 0" rpy="0 0 0" />
      <geometry>
        <box size="0.15 0.022 0.022" />
      </geometry>
    </collision>
    <inertial>
      <origin xyz="0.115 0 0" rpy="0 0 0" />
      <mass value="0.04" />
      <inertia ixx="3.226666666666666e-06" ixy="0.0" ixz="0.0" iyy="7.661333333333333e-05" iyz="0.0" izz="7.661333333333333e-05" />
    </inertial>
  </link>

  <joint name="key_86_joint" type="revolute">
    <parent link="base" />
    <child link="key_86" />
    <origin xyz="-0.04000000000000001 0.5635 0.129" rpy="0 0 0" />
    <axis xyz="0 1 0" />
    <limit lower="0" upper="0.06307411789691225" effort="10.00" velocity="6.67" />
  </joint>

  <link name="key_87">
    <visual>
      <origin xyz="0.115 0 0" rpy="0 0 0" />
      <geometry>
        <box size="0.15 0.022 0.022" />
      </geometry>
      <material name="white" />
    </visual>
    <collision>
      <origin xyz="0.115 0 0" rpy="0 0 0" />
      <geometry>
        <box size="0.15 0.022 0.022" />
      </geometry>
    </collision>
    <inertial>
      <origin xyz="0.115 0 0" rpy="0 0 0" />
      <mass value="0.04" />
      <inertia ixx="3.226666666666666e-06" ixy="0.0" ixz="0.0" iyy="7.661333333333333e-05" iyz="0.0" izz="7.661333333333333e-05" />
    </inertial>
  </link>

  <joint name="key_87_joint" type="revolute">
    <parent link="base" />
    <child link="key_87" />
    <origin xyz="-0.04000000000000001 0.5865000000000001 0.129" rpy="0 0 0" />
    <axis xyz="0 1 0" />
    <limit lower="0" upper="0.06307411789691225" effort="10.00" velocity="6.67" />
  </joint>

  <link name="key_1">
    <visual>
      <origin xyz="0.075 0 0" rpy="0 0 0" />
      <geometry>
        <box size="0.09 0.01 0.018" />
      </geometry>
      <material name="black" />
    </visual>
    <collision>
      <origin xyz="0.075 0 0" rpy="0 0 0" />
      <geometry>
        <box size="0.09 0.01 0.018" />
      </geometry>
    </collision>
    <inertial>
      <origin xyz="0.075 0 0" rpy="0 0 0" />
      <mass value="0.02" />
      <inertia ixx="7.066666666666665e-07" ixy="0.0" ixz="0.0" iyy="1.404e-05" iyz="0.0" izz="1.3666666666666664e-05" />
    </inertial>
  </link>

  <joint name="key_1_joint" type="revolute">
    <parent link="base" />
    <child link="key_1" />
    <origin xyz="-0.03 -0.575 0.14350000000000002" rpy="0 0 0" />
    <axis xyz="0 1 0" />
    <limit lower="0" upper="0.06656816377582381" effort="10.00" velocity="6.67" />
  </joint>

  <link name="key_4">
    <visual>
      <origin xyz="0.075 0 0" rpy="0 0 0" />
      <geometry>
        <box size="0.09 0.01 0.018" />
      </geometry>
      <material name="black" />
    </visual>
    <collision>
      <origin xyz="0.075 0 0" rpy="0 0 0" />
      <geometry>
        <box size="0.09 0.01 0.018" />
      </geometry>
    </collision>
    <inertial>
      <origin xyz="0.075 0 0" rpy="0 0 0" />
      <mass value="0.02" />
      <inertia ixx="7.066666666666665e-07" ixy="0.0" ixz="0.0" iyy="1.404e-05" iyz="0.0" izz="1.3666666666666664e-05" />
    </inertial>
  </link>

  <joint name="key_4_joint" type="revolute">
    <parent link="base" />
    <child link="key_4" />
    <origin xyz="-0.03 -0.5284999999999999 0.14350000000000002" rpy="0 0 0" />
    <axis xyz="0 1 0" />
    <limit lower="0" upper="0.06656816377582381" effort="10.00" velocity="6.67" />
  </joint>

  <link name="key_6">
    <visual>
      <origin xyz="0.075 0 0" rpy="0 0 0" />
      <geometry>
        <box size="0.09 0.01 0.018" />
      </geometry>
      <material name="black" />
    </visual>
    <collision>
      <origin xyz="0.075 0 0" rpy="0 0 0" />
      <geometry>
        <box size="0.09 0.01 0.018" />
      </geometry>
    </collision>
    <inertial>
      <origin xyz="0.075 0 0" rpy="0 0 0" />
      <mass value="0.02" />
      <inertia ixx="7.066666666666665e-07" ixy="0.0" ixz="0.0" iyy="1.404e-05" iyz="0.0" izz="1.3666666666666664e-05" />
    </inertial>
  </link>

  <joint name="key_6_joint" type="revolute">
    <parent link="base" />
    <child link="key_6" />
    <origin xyz="-0.03 -0.5054999999999998 0.14350000000000002" rpy="0 0 0" />
    <axis xyz="0 1 0" />
    <limit lower="0" upper="0.06656816377582381" effort="10.00" velocity="6.67" />
  </joint>

  <link name="key_16">
    <visual>
      <origin xyz="0.075 0 0" rpy="0 0 0" />
      <geometry>
        <box size="0.09 0.01 0.018" />
      </geometry>
      <material name="black" />
    </visual>
    <collision>
      <origin xyz="0.075 0 0" rpy="0 0 0" />
      <geometry>
        <box size="0.09 0.01 0.018" />
      </geometry>
    </collision>
    <inertial>
      <origin xyz="0.075 0 0" rpy="0 0 0" />
      <mass value="0.02" />
      <inertia ixx="7.066666666666665e-07" ixy="0.0" ixz="0.0" iyy="1.404e-05" iyz="0.0" izz="1.3666666666666664e-05" />
    </inertial>
  </link>

  <joint name="key_16_joint" type="revolute">
    <parent link="base" />
    <child link="key_16" />
    <origin xyz="-0.03 -0.36749999999999994 0.14350000000000002" rpy="0 0 0" />
    <axis xyz="0 1 0" />
    <limit lower="0" upper="0.06656816377582381" effort="10.00" velocity="6.67" />
  </joint>

  <link name="key_18">
    <visual>
      <origin xyz="0.075 0 0" rpy="0 0 0" />
      <geometry>
        <box size="0.09 0.01 0.018" />
      </geometry>
      <material name="black" />
    </visual>
    <collision>
      <origin xyz="0.075 0 0" rpy="0 0 0" />
      <geometry>
        <box size="0.09 0.01 0.018" />
      </geometry>
    </collision>
    <inertial>
      <origin xyz="0.075 0 0" rpy="0 0 0" />
      <mass value="0.02" />
      <inertia ixx="7.066666666666665e-07" ixy="0.0" ixz="0.0" iyy="1.404e-05" iyz="0.0" izz="1.3666666666666664e-05" />
    </inertial>
  </link>

  <joint name="key_18_joint" type="revolute">
    <parent link="base" />
    <child link="key_18" />
    <origin xyz="-0.03 -0.3444999999999999 0.14350000000000002" rpy="0 0 0" />
    <axis xyz="0 1 0" />
    <limit lower="0" upper="0.06656816377582381" effort="10.00" velocity="6.67" />
  </joint>

  <link name="key_28">
    <visual>
      <origin xyz="0.075 0 0" rpy="0 0 0" />
      <geometry>
        <box size="0.09 0.01 0.018" />
      </geometry>
      <material name="black" />
    </visual>
    <collision>
      <origin xyz="0.075 0 0" rpy="0 0 0" />
      <geometry>
        <box size="0.09 0.01 0.018" />
      </geometry>
    </collision>
    <inertial>
      <origin xyz="0.075 0 0" rpy="0 0 0" />
      <mass value="0.02" />
      <inertia ixx="7.066666666666665e-07" ixy="0.0" ixz="0.0" iyy="1.404e-05" iyz="0.0" izz="1.3666666666666664e-05" />
    </inertial>
  </link>

  <joint name="key_28_joint" type="revolute">
    <parent link="base" />
    <child link="key_28" />
    <origin xyz="-0.03 -0.2064999999999999 0.14350000000000002" rpy="0 0 0" />
    <axis xyz="0 1 0" />
    <limit lower="0" upper="0.06656816377582381" effort="10.00" velocity="6.67" />
  </joint>

  <link name="key_30">
    <visual>
      <origin xyz="0.075 0 0" rpy="0 0 0" />
      <geometry>
        <box size="0.09 0.01 0.018" />
      </geometry>
      <material name="black" />
    </visual>
    <collision>
      <origin xyz="0.075 0 0" rpy="0 0 0" />
      <geometry>
        <box size="0.09 0.01 0.018" />
      </geometry>
    </collision>
    <inertial>
      <origin xyz="0.075 0 0" rpy="0 0 0" />
      <mass value="0.02" />
      <inertia ixx="7.066666666666665e-07" ixy="0.0" ixz="0.0" iyy="1.404e-05" iyz="0.0" izz="1.3666666666666664e-05" />
    </inertial>
  </link>

  <joint name="key_30_joint" type="revolute">
    <parent link="base" />
    <child link="key_30" />
    <origin xyz="-0.03 -0.18349999999999989 0.14350000000000002" rpy="0 0 0" />
    <axis xyz="0 1 0" />
    <limit lower="0" upper="0.06656816377582381" effort="10.00" velocity="6.67" />
  </joint>

  <link name="key_40">
    <visual>
      <origin xyz="0.075 0 0" rpy="0 0 0" />
      <geometry>
        <box size="0.09 0.01 0.018" />
      </geometry>
      <material name="black" />
    </visual>
    <collision>
      <origin xyz="0.075 0 0" rpy="0 0 0" />
      <geometry>
        <box size="0.09 0.01 0.018" />
      </geometry>
    </collision>
    <inertial>
      <origin xyz="0.075 0 0" rpy="0 0 0" />
      <mass value="0.02" />
      <inertia ixx="7.066666666666665e-07" ixy="0.0" ixz="0.0" iyy="1.404e-05" iyz="0.0" izz="1.3666666666666664e-05" />
    </inertial>
  </link>

  <joint name="key_40_joint" type="revolute">
    <parent link="base" />
    <child link="key_40" />
    <origin xyz="-0.03 -0.045499999999999874 0.14350000000000002" rpy="0 0 0" />
    <axis xyz="0 1 0" />
    <limit lower="0" upper="0.06656816377582381" effort="10.00" velocity="6.67" />
  </joint>

  <link name="key_42">
    <visual>
      <origin xyz="0.075 0 0" rpy="0 0 0" />
      <geometry>
        <box size="0.09 0.01 0.018" />
      </geometry>
      <material name="black" />
    </visual>
    <collision>
      <origin xyz="0.075 0 0" rpy="0 0 0" />
      <geometry>
        <box size="0.09 0.01 0.018" />
      </geometry>
    </collision>
    <inertial>
      <origin xyz="0.075 0 0" rpy="0 0 0" />
      <mass value="0.02" />
      <inertia ixx="7.066666666666665e-07" ixy="0.0" ixz="0.0" iyy="1.404e-05" iyz="0.0" izz="1.3666666666666664e-05" />
    </inertial>
  </link>

  <joint name="key_42_joint" type="revolute">
    <parent link="base" />
    <child link="key_42" />
    <origin xyz="-0.03 -0.022499999999999853 0.14350000000000002" rpy="0 0 0" />
    <axis xyz="0 1 0" />
    <limit lower="0" upper="0.06656816377582381" effort="10.00" velocity="6.67" />
  </joint>

  <link name="key_52">
    <visual>
      <origin xyz="0.075 0 0" rpy="0 0 0" />
      <geometry>
        <box size="0.09 0.01 0.018" />
      </geometry>
      <material name="black" />
    </visual>
    <collision>
      <origin xyz="0.075 0 0" rpy="0 0 0" />
      <geometry>
        <box size="0.09 0.01 0.018" />
      </geometry>
    </collision>
    <inertial>
      <origin xyz="0.075 0 0" rpy="0 0 0" />
      <mass value="0.02" />
      <inertia ixx="7.066666666666665e-07" ixy="0.0" ixz="0.0" iyy="1.404e-05" iyz="0.0" izz="1.3666666666666664e-05" />
    </inertial>
  </link>

  <joint name="key_52_joint" type="revolute">
    <parent link="base" />
    <child link="key_52" />
    <origin xyz="-0.03 0.11550000000000005 0.14350000000000002" rpy="0 0 0" />
    <axis xyz="0 1 0" />
    <limit lower="0" upper="0.06656816377582381" effort="10.00" velocity="6.67" />
  </joint>

  <link name="key_54">
    <visual>
      <origin xyz="0.075 0 0" rpy="0 0 0" />
      <geometry>
        <box size="0.09 0.01 0.018" />
      </geometry>
      <material name="black" />
    </visual>
    <collision>
      <origin xyz="0.075 0 0" rpy="0 0 0" />
      <geometry>
        <box size="0.09 0.01 0.018" />
      </geometry>
    </collision>
    <inertial>
      <origin xyz="0.075 0 0" rpy="0 0 0" />
      <mass value="0.02" />
      <inertia ixx="7.066666666666665e-07" ixy="0.0" ixz="0.0" iyy="1.404e-05" iyz="0.0" izz="1.3666666666666664e-05" />
    </inertial>
  </link>

  <joint name="key_54_joint" type="revolute">
    <parent link="base" />
    <child link="key_54" />
    <origin xyz="-0.03 0.13850000000000007 0.14350000000000002" rpy="0 0 0" />
    <axis xyz="0 1 0" />
    <limit lower="0" upper="0.06656816377582381" effort="10.00" velocity="6.67" />
  </joint>

  <link name="key_64">
    <visual>
      <origin xyz="0.075 0 0" rpy="0 0 0" />
      <geometry>
        <box size="0.09 0.01 0.018" />
      </geometry>
      <material name="black" />
    </visual>
    <collision>
      <origin xyz="0.075 0 0" rpy="0 0 0" />
      <geometry>
        <box size="0.09 0.01 0.018" />
      </geometry>
    </collision>
    <inertial>
      <origin xyz="0.075 0 0" rpy="0 0 0" />
      <mass value="0.02" />
      <inertia ixx="7.066666666666665e-07" ixy="0.0" ixz="0.0" iyy="1.404e-05" iyz="0.0" izz="1.3666666666666664e-05" />
    </inertial>
  </link>

  <joint name="key_64_joint" type="revolute">
    <parent link="base" />
    <child link="key_64" />
    <origin xyz="-0.03 0.2765000000000001 0.14350000000000002" rpy="0 0 0" />
    <axis xyz="0 1 0" />
    <limit lower="0" upper="0.06656816377582381" effort="10.00" velocity="6.67" />
  </joint>

  <link name="key_66">
    <visual>
      <origin xyz="0.075 0 0" rpy="0 0 0" />
      <geometry>
        <box size="0.09 0.01 0.018" />
      </geometry>
      <material name="black" />
    </visual>
    <collision>
      <origin xyz="0.075 0 0" rpy="0 0 0" />
      <geometry>
        <box size="0.09 0.01 0.018" />
      </geometry>
    </collision>
    <inertial>
      <origin xyz="0.075 0 0" rpy="0 0 0" />
      <mass value="0.02" />
      <inertia ixx="7.066666666666665e-07" ixy="0.0" ixz="0.0" iyy="1.404e-05" iyz="0.0" izz="1.3666666666666664e-05" />
    </inertial>
  </link>

  <joint name="key_66_joint" type="revolute">
    <parent link="base" />
    <child link="key_66" />
    <origin xyz="-0.03 0.2995000000000001 0.14350000000000002" rpy="0 0 0" />
    <axis xyz="0 1 0" />
    <limit lower="0" upper="0.06656816377582381" effort="10.00" velocity="6.67" />
  </joint>

  <link name="key_76">
    <visual>
      <origin xyz="0.075 0 0" rpy="0 0 0" />
      <geometry>
        <box size="0.09 0.01 0.018" />
      </geometry>
      <material name="black" />
    </visual>
    <collision>
      <origin xyz="0.075 0 0" rpy="0 0 0" />
      <geometry>
        <box size="0.09 0.01 0.018" />
      </geometry>
    </collision>
    <inertial>
      <origin xyz="0.075 0 0" rpy="0 0 0" />
      <mass value="0.02" />
      <inertia ixx="7.066666666666665e-07" ixy="0.0" ixz="0.0" iyy="1.404e-05" iyz="0.0" izz="1.3666666666666664e-05" />
    </inertial>
  </link>

  <joint name="key_76_joint" type="revolute">
    <parent link="base" />
    <child link="key_76" />
    <origin xyz="-0.03 0.4375000000000001 0.14350000000000002" rpy="0 0 0" />
    <axis xyz="0 1 0" />
    <limit lower="0" upper="0.06656816377582381" effort="10.00" velocity="6.67" />
  </joint>

  <link name="key_78">
    <visual>
      <origin xyz="0.075 0 0" rpy="0 0 0" />
      <geometry>
        <box size="0.09 0.01 0.018" />
      </geometry>
      <material name="black" />
    </visual>
    <collision>
      <origin xyz="0.075 0 0" rpy="0 0 0" />
      <geometry>
        <box size="0.09 0.01 0.018" />
      </geometry>
    </collision>
    <inertial>
      <origin xyz="0.075 0 0" rpy="0 0 0" />
      <mass value="0.02" />
      <inertia ixx="7.066666666666665e-07" ixy="0.0" ixz="0.0" iyy="1.404e-05" iyz="0.0" izz="1.3666666666666664e-05" />
    </inertial>
  </link>

  <joint name="key_78_joint" type="revolute">
    <parent link="base" />
    <child link="key_78" />
    <origin xyz="-0.03 0.46050000000000013 0.14350000000000002" rpy="0 0 0" />
    <axis xyz="0 1 0" />
    <limit lower="0" upper="0.06656816377582381" effort="10.00" velocity="6.67" />
  </joint>

  <link name="key_9">
    <visual>
      <origin xyz="0.075 0 0" rpy="0 0 0" />
      <geometry>
        <box size="0.09 0.01 0.018" />
      </geometry>
      <material name="black" />
    </visual>
    <collision>
      <origin xyz="0.075 0 0" rpy="0 0 0" />
      <geometry>
        <box size="0.09 0.01 0.018" />
      </geometry>
    </collision>
    <inertial>
      <origin xyz="0.075 0 0" rpy="0 0 0" />
      <mass value="0.02" />
      <inertia ixx="7.066666666666665e-07" ixy="0.0" ixz="0.0" iyy="1.404e-05" iyz="0.0" izz="1.3666666666666664e-05" />
    </inertial>
  </link>

  <joint name="key_9_joint" type="revolute">
    <parent link="base" />
    <child link="key_9" />
    <origin xyz="-0.03 -0.4594999999999999 0.14350000000000002" rpy="0 0 0" />
    <axis xyz="0 1 0" />
    <limit lower="0" upper="0.06656816377582381" effort="10.00" velocity="6.67" />
  </joint>

  <link name="key_11">
    <visual>
      <origin xyz="0.075 0 0" rpy="0 0 0" />
      <geometry>
        <box size="0.09 0.01 0.018" />
      </geometry>
      <material name="black" />
    </visual>
    <collision>
      <origin xyz="0.075 0 0" rpy="0 0 0" />
      <geometry>
        <box size="0.09 0.01 0.018" />
      </geometry>
    </collision>
    <inertial>
      <origin xyz="0.075 0 0" rpy="0 0 0" />
      <mass value="0.02" />
      <inertia ixx="7.066666666666665e-07" ixy="0.0" ixz="0.0" iyy="1.404e-05" iyz="0.0" izz="1.3666666666666664e-05" />
    </inertial>
  </link>

  <joint name="key_11_joint" type="revolute">
    <parent link="base" />
    <child link="key_11" />
    <origin xyz="-0.03 -0.4364999999999999 0.14350000000000002" rpy="0 0 0" />
    <axis xyz="0 1 0" />
    <limit lower="0" upper="0.06656816377582381" effort="10.00" velocity="6.67" />
  </joint>

  <link name="key_13">
    <visual>
      <origin xyz="0.075 0 0" rpy="0 0 0" />
      <geometry>
        <box size="0.09 0.01 0.018" />
      </geometry>
      <material name="black" />
    </visual>
    <collision>
      <origin xyz="0.075 0 0" rpy="0 0 0" />
      <geometry>
        <box size="0.09 0.01 0.018" />
      </geometry>
    </collision>
    <inertial>
      <origin xyz="0.075 0 0" rpy="0 0 0" />
      <mass value="0.02" />
      <inertia ixx="7.066666666666665e-07" ixy="0.0" ixz="0.0" iyy="1.404e-05" iyz="0.0" izz="1.3666666666666664e-05" />
    </inertial>
  </link>

  <joint name="key_13_joint" type="revolute">
    <parent link="base" />
    <child link="key_13" />
    <origin xyz="-0.03 -0.4135 0.14350000000000002" rpy="0 0 0" />
    <axis xyz="0 1 0" />
    <limit lower="0" upper="0.06656816377582381" effort="10.00" velocity="6.67" />
  </joint>

  <link name="key_21">
    <visual>
      <origin xyz="0.075 0 0" rpy="0 0 0" />
      <geometry>
        <box size="0.09 0.01 0.018" />
      </geometry>
      <material name="black" />
    </visual>
    <collision>
      <origin xyz="0.075 0 0" rpy="0 0 0" />
      <geometry>
        <box size="0.09 0.01 0.018" />
      </geometry>
    </collision>
    <inertial>
      <origin xyz="0.075 0 0" rpy="0 0 0" />
      <mass value="0.02" />
      <inertia ixx="7.066666666666665e-07" ixy="0.0" ixz="0.0" iyy="1.404e-05" iyz="0.0" izz="1.3666666666666664e-05" />
    </inertial>
  </link>

  <joint name="key_21_joint" type="revolute">
    <parent link="base" />
    <child link="key_21" />
    <origin xyz="-0.03 -0.2984999999999999 0.14350000000000002" rpy="0 0 0" />
    <axis xyz="0 1 0" />
    <limit lower="0" upper="0.06656816377582381" effort="10.00" velocity="6.67" />
  </joint>

  <link name="key_23">
    <visual>
      <origin xyz="0.075 0 0" rpy="0 0 0" />
      <geometry>
        <box size="0.09 0.01 0.018" />
      </geometry>
      <material name="black" />
    </visual>
    <collision>
      <origin xyz="0.075 0 0" rpy="0 0 0" />
      <geometry>
        <box size="0.09 0.01 0.018" />
      </geometry>
    </collision>
    <inertial>
      <origin xyz="0.075 0 0" rpy="0 0 0" />
      <mass value="0.02" />
      <inertia ixx="7.066666666666665e-07" ixy="0.0" ixz="0.0" iyy="1.404e-05" iyz="0.0" izz="1.3666666666666664e-05" />
    </inertial>
  </link>

  <joint name="key_23_joint" type="revolute">
    <parent link="base" />
    <child link="key_23" />
    <origin xyz="-0.03 -0.27549999999999986 0.14350000000000002" rpy="0 0 0" />
    <axis xyz="0 1 0" />
    <limit lower="0" upper="0.06656816377582381" effort="10.00" velocity="6.67" />
  </joint>

  <link name="key_25">
    <visual>
      <origin xyz="0.075 0 0" rpy="0 0 0" />
      <geometry>
        <box size="0.09 0.01 0.018" />
      </geometry>
      <material name="black" />
    </visual>
    <collision>
      <origin xyz="0.075 0 0" rpy="0 0 0" />
      <geometry>
        <box size="0.09 0.01 0.018" />
      </geometry>
    </collision>
    <inertial>
      <origin xyz="0.075 0 0" rpy="0 0 0" />
      <mass value="0.02" />
      <inertia ixx="7.066666666666665e-07" ixy="0.0" ixz="0.0" iyy="1.404e-05" iyz="0.0" izz="1.3666666666666664e-05" />
    </inertial>
  </link>

  <joint name="key_25_joint" type="revolute">
    <parent link="base" />
    <child link="key_25" />
    <origin xyz="-0.03 -0.25249999999999995 0.14350000000000002" rpy="0 0 0" />
    <axis xyz="0 1 0" />
    <limit lower="0" upper="0.06656816377582381" effort="10.00" velocity="6.67" />
  </joint>

  <link name="key_33">
    <visual>
      <origin xyz="0.075 0 0" rpy="0 0 0" />
      <geometry>
        <box size="0.09 0.01 0.018" />
      </geometry>
      <material name="black" />
    </visual>
    <collision>
      <origin xyz="0.075 0 0" rpy="0 0 0" />
      <geometry>
        <box size="0.09 0.01 0.018" />
      </geometry>
    </collision>
    <inertial>
      <origin xyz="0.075 0 0" rpy="0 0 0" />
      <mass value="0.02" />
      <inertia ixx="7.066666666666665e-07" ixy="0.0" ixz="0.0" iyy="1.404e-05" iyz="0.0" izz="1.3666666666666664e-05" />
    </inertial>
  </link>

  <joint name="key_33_joint" type="revolute">
    <parent link="base" />
    <child link="key_33" />
    <origin xyz="-0.03 -0.1374999999999999 0.14350000000000002" rpy="0 0 0" />
    <axis xyz="0 1 0" />
    <limit lower="0" upper="0.06656816377582381" effort="10.00" velocity="6.67" />
  </joint>

  <link name="key_35">
    <visual>
      <origin xyz="0.075 0 0" rpy="0 0 0" />
      <geometry>
        <box size="0.09 0.01 0.018" />
      </geometry>
      <material name="black" />
    </visual>
    <collision>
      <origin xyz="0.075 0 0" rpy="0 0 0" />
      <geometry>
        <box size="0.09 0.01 0.018" />
      </geometry>
    </collision>
    <inertial>
      <origin xyz="0.075 0 0" rpy="0 0 0" />
      <mass value="0.02" />
      <inertia ixx="7.066666666666665e-07" ixy="0.0" ixz="0.0" iyy="1.404e-05" iyz="0.0" izz="1.3666666666666664e-05" />
    </inertial>
  </link>

  <joint name="key_35_joint" type="revolute">
    <parent link="base" />
    <child link="key_35" />
    <origin xyz="-0.03 -0.11449999999999988 0.14350000000000002" rpy="0 0 0" />
    <axis xyz="0 1 0" />
    <limit lower="0" upper="0.06656816377582381" effort="10.00" velocity="6.67" />
  </joint>

  <link name="key_37">
    <visual>
      <origin xyz="0.075 0 0" rpy="0 0 0" />
      <geometry>
        <box size="0.09 0.01 0.018" />
      </geometry>
      <material name="black" />
    </visual>
    <collision>
      <origin xyz="0.075 0 0" rpy="0 0 0" />
      <geometry>
        <box size="0.09 0.01 0.018" />
      </geometry>
    </collision>
    <inertial>
      <origin xyz="0.075 0 0" rpy="0 0 0" />
      <mass value="0.02" />
      <inertia ixx="7.066666666666665e-07" ixy="0.0" ixz="0.0" iyy="1.404e-05" iyz="0.0" izz="1.3666666666666664e-05" />
    </inertial>
  </link>

  <joint name="key_37_joint" type="revolute">
    <parent link="base" />
    <child link="key_37" />
    <origin xyz="-0.03 -0.09149999999999997 0.14350000000000002" rpy="0 0 0" />
    <axis xyz="0 1 0" />
    <limit lower="0" upper="0.06656816377582381" effort="10.00" velocity="6.67" />
  </joint>

  <link name="key_45">
    <visual>
      <origin xyz="0.075 0 0" rpy="0 0 0" />
      <geometry>
        <box size="0.09 0.01 0.018" />
      </geometry>
      <material name="black" />
    </visual>
    <collision>
      <origin xyz="0.075 0 0" rpy="0 0 0" />
      <geometry>
        <box size="0.09 0.01 0.018" />
      </geometry>
    </collision>
    <inertial>
      <origin xyz="0.075 0 0" rpy="0 0 0" />
      <mass value="0.02" />
      <inertia ixx="7.066666666666665e-07" ixy="0.0" ixz="0.0" iyy="1.404e-05" iyz="0.0" izz="1.3666666666666664e-05" />
    </inertial>
  </link>

  <joint name="key_45_joint" type="revolute">
    <parent link="base" />
    <child link="key_45" />
    <origin xyz="-0.03 0.023500000000000076 0.14350000000000002" rpy="0 0 0" />
    <axis xyz="0 1 0" />
    <limit lower="0" upper="0.06656816377582381" effort="10.00" velocity="6.67" />
  </joint>

  <link name="key_47">
    <visual>
      <origin xyz="0.075 0 0" rpy="0 0 0" />
      <geometry>
        <box size="0.09 0.01 0.018" />
      </geometry>
      <material name="black" />
    </visual>
    <collision>
      <origin xyz="0.075 0 0" rpy="0 0 0" />
      <geometry>
        <box size="0.09 0.01 0.018" />
      </geometry>
    </collision>
    <inertial>
      <origin xyz="0.075 0 0" rpy="0 0 0" />
      <mass value="0.02" />
      <inertia ixx="7.066666666666665e-07" ixy="0.0" ixz="0.0" iyy="1.404e-05" iyz="0.0" izz="1.3666666666666664e-05" />
    </inertial>
  </link>

  <joint name="key_47_joint" type="revolute">
    <parent link="base" />
    <child link="key_47" />
    <origin xyz="-0.03 0.0465000000000001 0.14350000000000002" rpy="0 0 0" />
    <axis xyz="0 1 0" />
    <limit lower="0" upper="0.06656816377582381" effort="10.00" velocity="6.67" />
  </joint>

  <link name="key_49">
    <visual>
      <origin xyz="0.075 0 0" rpy="0 0 0" />
      <geometry>
        <box size="0.09 0.01 0.018" />
      </geometry>
      <material name="black" />
    </visual>
    <collision>
      <origin xyz="0.075 0 0" rpy="0 0 0" />
      <geometry>
        <box size="0.09 0.01 0.018" />
      </geometry>
    </collision>
    <inertial>
      <origin xyz="0.075 0 0" rpy="0 0 0" />
      <mass value="0.02" />
      <inertia ixx="7.066666666666665e-07" ixy="0.0" ixz="0.0" iyy="1.404e-05" iyz="0.0" izz="1.3666666666666664e-05" />
    </inertial>
  </link>

  <joint name="key_49_joint" type="revolute">
    <parent link="base" />
    <child link="key_49" />
    <origin xyz="-0.03 0.0695 0.14350000000000002" rpy="0 0 0" />
    <axis xyz="0 1 0" />
    <limit lower="0" upper="0.06656816377582381" effort="10.00" velocity="6.67" />
  </joint>

  <link name="key_57">
    <visual>
      <origin xyz="0.075 0 0" rpy="0 0 0" />
      <geometry>
        <box size="0.09 0.01 0.018" />
      </geometry>
      <material name="black" />
    </visual>
    <collision>
      <origin xyz="0.075 0 0" rpy="0 0 0" />
      <geometry>
        <box size="0.09 0.01 0.018" />
      </geometry>
    </collision>
    <inertial>
      <origin xyz="0.075 0 0" rpy="0 0 0" />
      <mass value="0.02" />
      <inertia ixx="7.066666666666665e-07" ixy="0.0" ixz="0.0" iyy="1.404e-05" iyz="0.0" izz="1.3666666666666664e-05" />
    </inertial>
  </link>

  <joint name="key_57_joint" type="revolute">
    <parent link="base" />
    <child link="key_57" />
    <origin xyz="-0.03 0.1845000000000001 0.14350000000000002" rpy="0 0 0" />
    <axis xyz="0 1 0" />
    <limit lower="0" upper="0.06656816377582381" effort="10.00" velocity="6.67" />
  </joint>

  <link name="key_59">
    <visual>
      <origin xyz="0.075 0 0" rpy="0 0 0" />
      <geometry>
        <box size="0.09 0.01 0.018" />
      </geometry>
      <material name="black" />
    </visual>
    <collision>
      <origin xyz="0.075 0 0" rpy="0 0 0" />
      <geometry>
        <box size="0.09 0.01 0.018" />
      </geometry>
    </collision>
    <inertial>
      <origin xyz="0.075 0 0" rpy="0 0 0" />
      <mass value="0.02" />
      <inertia ixx="7.066666666666665e-07" ixy="0.0" ixz="0.0" iyy="1.404e-05" iyz="0.0" izz="1.3666666666666664e-05" />
    </inertial>
  </link>

  <joint name="key_59_joint" type="revolute">
    <parent link="base" />
    <child link="key_59" />
    <origin xyz="-0.03 0.20750000000000013 0.14350000000000002" rpy="0 0 0" />
    <axis xyz="0 1 0" />
    <limit lower="0" upper="0.06656816377582381" effort="10.00" velocity="6.67" />
  </joint>

  <link name="key_61">
    <visual>
      <origin xyz="0.075 0 0" rpy="0 0 0" />
      <geometry>
        <box size="0.09 0.01 0.018" />
      </geometry>
      <material name="black" />
    </visual>
    <collision>
      <origin xyz="0.075 0 0" rpy="0 0 0" />
      <geometry>
        <box size="0.09 0.01 0.018" />
      </geometry>
    </collision>
    <inertial>
      <origin xyz="0.075 0 0" rpy="0 0 0" />
      <mass value="0.02" />
      <inertia ixx="7.066666666666665e-07" ixy="0.0" ixz="0.0" iyy="1.404e-05" iyz="0.0" izz="1.3666666666666664e-05" />
    </inertial>
  </link>

  <joint name="key_61_joint" type="revolute">
    <parent link="base" />
    <child link="key_61" />
    <origin xyz="-0.03 0.23050000000000004 0.14350000000000002" rpy="0 0 0" />
    <axis xyz="0 1 0" />
    <limit lower="0" upper="0.06656816377582381" effort="10.00" velocity="6.67" />
  </joint>

  <link name="key_69">
    <visual>
      <origin xyz="0.075 0 0" rpy="0 0 0" />
      <geometry>
        <box size="0.09 0.01 0.018" />
      </geometry>
      <material name="black" />
    </visual>
    <collision>
      <origin xyz="0.075 0 0" rpy="0 0 0" />
      <geometry>
        <box size="0.09 0.01 0.018" />
      </geometry>
    </collision>
    <inertial>
      <origin xyz="0.075 0 0" rpy="0 0 0" />
      <mass value="0.02" />
      <inertia ixx="7.066666666666665e-07" ixy="0.0" ixz="0.0" iyy="1.404e-05" iyz="0.0" izz="1.3666666666666664e-05" />
    </inertial>
  </link>

  <joint name="key_69_joint" type="revolute">
    <parent link="base" />
    <child link="key_69" />
    <origin xyz="-0.03 0.34550000000000003 0.14350000000000002" rpy="0 0 0" />
    <axis xyz="0 1 0" />
    <limit lower="0" upper="0.06656816377582381" effort="10.00" velocity="6.67" />
  </joint>

  <link name="key_71">
    <visual>
      <origin xyz="0.075 0 0" rpy="0 0 0" />
      <geometry>
        <box size="0.09 0.01 0.018" />
      </geometry>
      <material name="black" />
    </visual>
    <collision>
      <origin xyz="0.075 0 0" rpy="0 0 0" />
      <geometry>
        <box size="0.09 0.01 0.018" />
      </geometry>
    </collision>
    <inertial>
      <origin xyz="0.075 0 0" rpy="0 0 0" />
      <mass value="0.02" />
      <inertia ixx="7.066666666666665e-07" ixy="0.0" ixz="0.0" iyy="1.404e-05" iyz="0.0" izz="1.3666666666666664e-05" />
    </inertial>
  </link>

  <joint name="key_71_joint" type="revolute">
    <parent link="base" />
    <child link="key_71" />
    <origin xyz="-0.03 0.36850000000000005 0.14350000000000002" rpy="0 0 0" />
    <axis xyz="0 1 0" />
    <limit lower="0" upper="0.06656816377582381" effort="10.00" velocity="6.67" />
  </joint>

  <link name="key_73">
    <visual>
      <origin xyz="0.075 0 0" rpy="0 0 0" />
      <geometry>
        <box size="0.09 0.01 0.018" />
      </geometry>
      <material name="black" />
    </visual>
    <collision>
      <origin xyz="0.075 0 0" rpy="0 0 0" />
      <geometry>
        <box size="0.09 0.01 0.018" />
      </geometry>
    </collision>
    <inertial>
      <origin xyz="0.075 0 0" rpy="0 0 0" />
      <mass value="0.02" />
      <inertia ixx="7.066666666666665e-07" ixy="0.0" ixz="0.0" iyy="1.404e-05" iyz="0.0" izz="1.3666666666666664e-05" />
    </inertial>
  </link>

  <joint name="key_73_joint" type="revolute">
    <parent link="base" />
    <child link="key_73" />
    <origin xyz="-0.03 0.39149999999999996 0.14350000000000002" rpy="0 0 0" />
    <axis xyz="0 1 0" />
    <limit lower="0" upper="0.06656816377582381" effort="10.00" velocity="6.67" />
  </joint>

  <link name="key_81">
    <visual>
      <origin xyz="0.075 0 0" rpy="0 0 0" />
      <geometry>
        <box size="0.09 0.01 0.018" />
      </geometry>
      <material name="black" />
    </visual>
    <collision>
      <origin xyz="0.075 0 0" rpy="0 0 0" />
      <geometry>
        <box size="0.09 0.01 0.018" />
      </geometry>
    </collision>
    <inertial>
      <origin xyz="0.075 0 0" rpy="0 0 0" />
      <mass value="0.02" />
      <inertia ixx="7.066666666666665e-07" ixy="0.0" ixz="0.0" iyy="1.404e-05" iyz="0.0" izz="1.3666666666666664e-05" />
    </inertial>
  </link>

  <joint name="key_81_joint" type="revolute">
    <parent link="base" />
    <child link="key_81" />
    <origin xyz="-0.03 0.5065000000000001 0.14350000000000002" rpy="0 0 0" />
    <axis xyz="0 1 0" />
    <limit lower="0" upper="0.06656816377582381" effort="10.00" velocity="6.67" />
  </joint>

  <link name="key_83">
    <visual>
      <origin xyz="0.075 0 0" rpy="0 0 0" />
      <geometry>
        <box size="0.09 0.01 0.018" />
      </geometry>
      <material name="black" />
    </visual>
    <collision>
      <origin xyz="0.075 0 0" rpy="0 0 0" />
      <geometry>
        <box size="0.09 0.01 0.018" />
      </geometry>
    </collision>
    <inertial>
      <origin xyz="0.075 0 0" rpy="0 0 0" />
      <mass value="0.02" />
      <inertia ixx="7.066666666666665e-07" ixy="0.0" ixz="0.0" iyy="1.404e-05" iyz="0.0" izz="1.3666666666666664e-05" />
    </inertial>
  </link>

  <joint name="key_83_joint" type="revolute">
    <parent link="base" />
    <child link="key_83" />
    <origin xyz="-0.03 0.5295000000000001 0.14350000000000002" rpy="0 0 0" />
    <axis xyz="0 1 0" />
    <limit lower="0" upper="0.06656816377582381" effort="10.00" velocity="6.67" />
  </joint>

  <link name="key_85">
    <visual>
      <origin xyz="0.075 0 0" rpy="0 0 0" />
      <geometry>
        <box size="0.09 0.01 0.018" />
      </geometry>
      <material name="black" />
    </visual>
    <collision>
      <origin xyz="0.075 0 0" rpy="0 0 0" />
      <geometry>
        <box size="0.09 0.01 0.018" />
      </geometry>
    </collision>
    <inertial>
      <origin xyz="0.075 0 0" rpy="0 0 0" />
      <mass value="0.02" />
      <inertia ixx="7.066666666666665e-07" ixy="0.0" ixz="0.0" iyy="1.404e-05" iyz="0.0" izz="1.3666666666666664e-05" />
    </inertial>
  </link>

  <joint name="key_85_joint" type="revolute">
    <parent link="base" />
    <child link="key_85" />
    <origin xyz="-0.03 0.5525 0.14350000000000002" rpy="0 0 0" />
    <axis xyz="0 1 0" />
    <limit lower="0" upper="0.06656816377582381" effort="10.00" velocity="6.67" />
  </joint>

</robot>