<?xml version="1.0" encoding="utf-8"?>
<robot name="piano_nikomaku">
  <material name="white">
    <color rgba="0.9 0.9 0.9 1" />
  </material>
  <material name="black">
    <color rgba="0.1 0.1 0.1 1" />
  </material>

  <!-- Base link -->
  <link name="base">
  </link>

  <!-- Piano body -->
  <link name="body">
    <visual>
      <origin xyz="-0.03 0 -0.027500000000000004" rpy="0 0 0" />
      <geometry>
        <box size="0.06 1.21 0.085" />
      </geometry>
    </visual>
    <visual>
      <origin xyz="0.045 0 -0.04599038461538462" rpy="0 0 0" />
      <geometry>
         <box size="0.21 1.21 0.04801923076923077" />
      </geometry>
    </visual>
    <collision>
      <origin xyz="-0.03 0 -0.027500000000000004" rpy="0 0 0" />
      <geometry>
         <box size="0.06 1.21 0.085" />
      </geometry>
    </collision>
    <collision>
      <origin xyz="0.045 0 -0.04599038461538462" rpy="0 0 0" />
      <geometry>
         <box size="0.21 1.21 0.04801923076923077" />
      </geometry>
    </collision>
    <inertial>
      <origin xyz="-0.03 0 -0.027500000000000004" rpy="0 0 0" />
      <mass value="10.0" />
      <inertia ixx="0.1" ixy="0.0" ixz="0.0" iyy="0.1" iyz="0.0" izz="0.1" />
    </inertial>
  </link>

  <joint name="base_body_joint" type="fixed">
    <parent link="base" />
    <child link="body" />
    <origin xyz="0 0 0" rpy="0 0 0" />
  </joint>

  <link name="white_key_0">
    <visual>
      <origin xyz="0.1 0 0" rpy="0 0 0" />
      <geometry>
        <box size="0.14 0.02198076923076923 0.02198076923076923" />
      </geometry>
      <material name="white" />
    </visual>
    <collision>
      <origin xyz="0.1 0 0" rpy="0 0 0" />
      <geometry>
        <box size="0.14 0.02198076923076923 0.02198076923076923" />
      </geometry>
    </collision>
    <inertial>
      <origin xyz="0.1 0 0" rpy="0 0 0" />
      <mass value="0.04" />
      <inertia ixx="3.2210281065088756e-06" ixy="0.0" ixz="0.0" iyy="6.694384738658778e-05" iyz="0.0" izz="6.694384738658778e-05" />
    </inertial>
  </link>

  <joint name="white_joint_0" type="revolute">
    <parent link="base" />
    <child link="white_key_0" />
    <origin xyz="-0.03 -0.5860096153846154 -0.010990384615384615" rpy="0 0 0" />
    <axis xyz="0 1 0" />
    <limit lower="0" upper="0.07047134457879563" effort="0.3" velocity="6.67" />
  </joint>

  <link name="black_key_1">
    <visual>
      <origin xyz="0.065 0 0" rpy="0 0 0" />
      <geometry>
        <box size="0.09 0.01 0.018" />
      </geometry>
      <material name="black" />
    </visual>
    <collision>
      <origin xyz="0.065 0 0" rpy="0 0 0" />
      <geometry>
        <box size="0.09 0.01 0.018" />
      </geometry>
    </collision>
    <inertial>
      <origin xyz="0.065 0 0" rpy="0 0 0" />
      <mass value="0.02" />
      <inertia ixx="7.066666666666665e-07" ixy="0.0" ixz="0.0" iyy="1.404e-05" iyz="0.0" izz="1.3666666666666664e-05" />
    </inertial>
  </link>

  <joint name="black_joint_1" type="revolute">
    <parent link="base" />
    <child link="black_key_1" />
    <origin xyz="-0.020000000000000004 -0.5745192307692308 0.0035000000000000014" rpy="0 0 0" />
    <axis xyz="0 1 0" />
    <limit lower="0" upper="0.07259945373049462" effort="0.3" velocity="6.67" />
  </joint>

  <link name="white_key_2">
    <visual>
      <origin xyz="0.1 0 0" rpy="0 0 0" />
      <geometry>
        <box size="0.14 0.02198076923076923 0.02198076923076923" />
      </geometry>
      <material name="white" />
    </visual>
    <collision>
      <origin xyz="0.1 0 0" rpy="0 0 0" />
      <geometry>
        <box size="0.14 0.02198076923076923 0.02198076923076923" />
      </geometry>
    </collision>
    <inertial>
      <origin xyz="0.1 0 0" rpy="0 0 0" />
      <mass value="0.04" />
      <inertia ixx="3.2210281065088756e-06" ixy="0.0" ixz="0.0" iyy="6.694384738658778e-05" iyz="0.0" izz="6.694384738658778e-05" />
    </inertial>
  </link>

  <joint name="white_joint_2" type="revolute">
    <parent link="base" />
    <child link="white_key_2" />
    <origin xyz="-0.03 -0.5630288461538462 -0.010990384615384615" rpy="0 0 0" />
    <axis xyz="0 1 0" />
    <limit lower="0" upper="0.07047134457879563" effort="0.3" velocity="6.67" />
  </joint>

  <link name="white_key_3">
    <visual>
      <origin xyz="0.1 0 0" rpy="0 0 0" />
      <geometry>
        <box size="0.14 0.02198076923076923 0.02198076923076923" />
      </geometry>
      <material name="white" />
    </visual>
    <collision>
      <origin xyz="0.1 0 0" rpy="0 0 0" />
      <geometry>
        <box size="0.14 0.02198076923076923 0.02198076923076923" />
      </geometry>
    </collision>
    <inertial>
      <origin xyz="0.1 0 0" rpy="0 0 0" />
      <mass value="0.04" />
      <inertia ixx="3.2210281065088756e-06" ixy="0.0" ixz="0.0" iyy="6.694384738658778e-05" iyz="0.0" izz="6.694384738658778e-05" />
    </inertial>
  </link>

  <joint name="white_joint_3" type="revolute">
    <parent link="base" />
    <child link="white_key_3" />
    <origin xyz="-0.03 -0.5400480769230769 -0.010990384615384615" rpy="0 0 0" />
    <axis xyz="0 1 0" />
    <limit lower="0" upper="0.07047134457879563" effort="0.3" velocity="6.67" />
  </joint>

  <link name="black_key_4">
    <visual>
      <origin xyz="0.065 0 0" rpy="0 0 0" />
      <geometry>
        <box size="0.09 0.01 0.018" />
      </geometry>
      <material name="black" />
    </visual>
    <collision>
      <origin xyz="0.065 0 0" rpy="0 0 0" />
      <geometry>
        <box size="0.09 0.01 0.018" />
      </geometry>
    </collision>
    <inertial>
      <origin xyz="0.065 0 0" rpy="0 0 0" />
      <mass value="0.02" />
      <inertia ixx="7.066666666666665e-07" ixy="0.0" ixz="0.0" iyy="1.404e-05" iyz="0.0" izz="1.3666666666666664e-05" />
    </inertial>
  </link>

  <joint name="black_joint_4" type="revolute">
    <parent link="base" />
    <child link="black_key_4" />
    <origin xyz="-0.020000000000000004 -0.5280576923076923 0.0035000000000000014" rpy="0 0 0" />
    <axis xyz="0 1 0" />
    <limit lower="0" upper="0.07259945373049462" effort="0.3" velocity="6.67" />
  </joint>

  <link name="white_key_5">
    <visual>
      <origin xyz="0.1 0 0" rpy="0 0 0" />
      <geometry>
        <box size="0.14 0.02198076923076923 0.02198076923076923" />
      </geometry>
      <material name="white" />
    </visual>
    <collision>
      <origin xyz="0.1 0 0" rpy="0 0 0" />
      <geometry>
        <box size="0.14 0.02198076923076923 0.02198076923076923" />
      </geometry>
    </collision>
    <inertial>
      <origin xyz="0.1 0 0" rpy="0 0 0" />
      <mass value="0.04" />
      <inertia ixx="3.2210281065088756e-06" ixy="0.0" ixz="0.0" iyy="6.694384738658778e-05" iyz="0.0" izz="6.694384738658778e-05" />
    </inertial>
  </link>

  <joint name="white_joint_5" type="revolute">
    <parent link="base" />
    <child link="white_key_5" />
    <origin xyz="-0.03 -0.5170673076923077 -0.010990384615384615" rpy="0 0 0" />
    <axis xyz="0 1 0" />
    <limit lower="0" upper="0.07047134457879563" effort="0.3" velocity="6.67" />
  </joint>

  <link name="black_key_6">
    <visual>
      <origin xyz="0.065 0 0" rpy="0 0 0" />
      <geometry>
        <box size="0.09 0.01 0.018" />
      </geometry>
      <material name="black" />
    </visual>
    <collision>
      <origin xyz="0.065 0 0" rpy="0 0 0" />
      <geometry>
        <box size="0.09 0.01 0.018" />
      </geometry>
    </collision>
    <inertial>
      <origin xyz="0.065 0 0" rpy="0 0 0" />
      <mass value="0.02" />
      <inertia ixx="7.066666666666665e-07" ixy="0.0" ixz="0.0" iyy="1.404e-05" iyz="0.0" izz="1.3666666666666664e-05" />
    </inertial>
  </link>

  <joint name="black_joint_6" type="revolute">
    <parent link="base" />
    <child link="black_key_6" />
    <origin xyz="-0.020000000000000004 -0.505076923076923 0.0035000000000000014" rpy="0 0 0" />
    <axis xyz="0 1 0" />
    <limit lower="0" upper="0.07259945373049462" effort="0.3" velocity="6.67" />
  </joint>

  <link name="white_key_7">
    <visual>
      <origin xyz="0.1 0 0" rpy="0 0 0" />
      <geometry>
        <box size="0.14 0.02198076923076923 0.02198076923076923" />
      </geometry>
      <material name="white" />
    </visual>
    <collision>
      <origin xyz="0.1 0 0" rpy="0 0 0" />
      <geometry>
        <box size="0.14 0.02198076923076923 0.02198076923076923" />
      </geometry>
    </collision>
    <inertial>
      <origin xyz="0.1 0 0" rpy="0 0 0" />
      <mass value="0.04" />
      <inertia ixx="3.2210281065088756e-06" ixy="0.0" ixz="0.0" iyy="6.694384738658778e-05" iyz="0.0" izz="6.694384738658778e-05" />
    </inertial>
  </link>

  <joint name="white_joint_7" type="revolute">
    <parent link="base" />
    <child link="white_key_7" />
    <origin xyz="-0.03 -0.49408653846153844 -0.010990384615384615" rpy="0 0 0" />
    <axis xyz="0 1 0" />
    <limit lower="0" upper="0.07047134457879563" effort="0.3" velocity="6.67" />
  </joint>

  <link name="white_key_8">
    <visual>
      <origin xyz="0.1 0 0" rpy="0 0 0" />
      <geometry>
        <box size="0.14 0.02198076923076923 0.02198076923076923" />
      </geometry>
      <material name="white" />
    </visual>
    <collision>
      <origin xyz="0.1 0 0" rpy="0 0 0" />
      <geometry>
        <box size="0.14 0.02198076923076923 0.02198076923076923" />
      </geometry>
    </collision>
    <inertial>
      <origin xyz="0.1 0 0" rpy="0 0 0" />
      <mass value="0.04" />
      <inertia ixx="3.2210281065088756e-06" ixy="0.0" ixz="0.0" iyy="6.694384738658778e-05" iyz="0.0" izz="6.694384738658778e-05" />
    </inertial>
  </link>

  <joint name="white_joint_8" type="revolute">
    <parent link="base" />
    <child link="white_key_8" />
    <origin xyz="-0.03 -0.4711057692307692 -0.010990384615384615" rpy="0 0 0" />
    <axis xyz="0 1 0" />
    <limit lower="0" upper="0.07047134457879563" effort="0.3" velocity="6.67" />
  </joint>

  <link name="black_key_9">
    <visual>
      <origin xyz="0.065 0 0" rpy="0 0 0" />
      <geometry>
        <box size="0.09 0.01 0.018" />
      </geometry>
      <material name="black" />
    </visual>
    <collision>
      <origin xyz="0.065 0 0" rpy="0 0 0" />
      <geometry>
        <box size="0.09 0.01 0.018" />
      </geometry>
    </collision>
    <inertial>
      <origin xyz="0.065 0 0" rpy="0 0 0" />
      <mass value="0.02" />
      <inertia ixx="7.066666666666665e-07" ixy="0.0" ixz="0.0" iyy="1.404e-05" iyz="0.0" izz="1.3666666666666664e-05" />
    </inertial>
  </link>

  <joint name="black_joint_9" type="revolute">
    <parent link="base" />
    <child link="black_key_9" />
    <origin xyz="-0.020000000000000004 -0.4591153846153846 0.0035000000000000014" rpy="0 0 0" />
    <axis xyz="0 1 0" />
    <limit lower="0" upper="0.07259945373049462" effort="0.3" velocity="6.67" />
  </joint>

  <link name="white_key_10">
    <visual>
      <origin xyz="0.1 0 0" rpy="0 0 0" />
      <geometry>
        <box size="0.14 0.02198076923076923 0.02198076923076923" />
      </geometry>
      <material name="white" />
    </visual>
    <collision>
      <origin xyz="0.1 0 0" rpy="0 0 0" />
      <geometry>
        <box size="0.14 0.02198076923076923 0.02198076923076923" />
      </geometry>
    </collision>
    <inertial>
      <origin xyz="0.1 0 0" rpy="0 0 0" />
      <mass value="0.04" />
      <inertia ixx="3.2210281065088756e-06" ixy="0.0" ixz="0.0" iyy="6.694384738658778e-05" iyz="0.0" izz="6.694384738658778e-05" />
    </inertial>
  </link>

  <joint name="white_joint_10" type="revolute">
    <parent link="base" />
    <child link="white_key_10" />
    <origin xyz="-0.03 -0.448125 -0.010990384615384615" rpy="0 0 0" />
    <axis xyz="0 1 0" />
    <limit lower="0" upper="0.07047134457879563" effort="0.3" velocity="6.67" />
  </joint>

  <link name="black_key_11">
    <visual>
      <origin xyz="0.065 0 0" rpy="0 0 0" />
      <geometry>
        <box size="0.09 0.01 0.018" />
      </geometry>
      <material name="black" />
    </visual>
    <collision>
      <origin xyz="0.065 0 0" rpy="0 0 0" />
      <geometry>
        <box size="0.09 0.01 0.018" />
      </geometry>
    </collision>
    <inertial>
      <origin xyz="0.065 0 0" rpy="0 0 0" />
      <mass value="0.02" />
      <inertia ixx="7.066666666666665e-07" ixy="0.0" ixz="0.0" iyy="1.404e-05" iyz="0.0" izz="1.3666666666666664e-05" />
    </inertial>
  </link>

  <joint name="black_joint_11" type="revolute">
    <parent link="base" />
    <child link="black_key_11" />
    <origin xyz="-0.020000000000000004 -0.4361346153846153 0.0035000000000000014" rpy="0 0 0" />
    <axis xyz="0 1 0" />
    <limit lower="0" upper="0.07259945373049462" effort="0.3" velocity="6.67" />
  </joint>

  <link name="white_key_12">
    <visual>
      <origin xyz="0.1 0 0" rpy="0 0 0" />
      <geometry>
        <box size="0.14 0.02198076923076923 0.02198076923076923" />
      </geometry>
      <material name="white" />
    </visual>
    <collision>
      <origin xyz="0.1 0 0" rpy="0 0 0" />
      <geometry>
        <box size="0.14 0.02198076923076923 0.02198076923076923" />
      </geometry>
    </collision>
    <inertial>
      <origin xyz="0.1 0 0" rpy="0 0 0" />
      <mass value="0.04" />
      <inertia ixx="3.2210281065088756e-06" ixy="0.0" ixz="0.0" iyy="6.694384738658778e-05" iyz="0.0" izz="6.694384738658778e-05" />
    </inertial>
  </link>

  <joint name="white_joint_12" type="revolute">
    <parent link="base" />
    <child link="white_key_12" />
    <origin xyz="-0.03 -0.42514423076923075 -0.010990384615384615" rpy="0 0 0" />
    <axis xyz="0 1 0" />
    <limit lower="0" upper="0.07047134457879563" effort="0.3" velocity="6.67" />
  </joint>

  <link name="black_key_13">
    <visual>
      <origin xyz="0.065 0 0" rpy="0 0 0" />
      <geometry>
        <box size="0.09 0.01 0.018" />
      </geometry>
      <material name="black" />
    </visual>
    <collision>
      <origin xyz="0.065 0 0" rpy="0 0 0" />
      <geometry>
        <box size="0.09 0.01 0.018" />
      </geometry>
    </collision>
    <inertial>
      <origin xyz="0.065 0 0" rpy="0 0 0" />
      <mass value="0.02" />
      <inertia ixx="7.066666666666665e-07" ixy="0.0" ixz="0.0" iyy="1.404e-05" iyz="0.0" izz="1.3666666666666664e-05" />
    </inertial>
  </link>

  <joint name="black_joint_13" type="revolute">
    <parent link="base" />
    <child link="black_key_13" />
    <origin xyz="-0.020000000000000004 -0.4131538461538461 0.0035000000000000014" rpy="0 0 0" />
    <axis xyz="0 1 0" />
    <limit lower="0" upper="0.07259945373049462" effort="0.3" velocity="6.67" />
  </joint>

  <link name="white_key_14">
    <visual>
      <origin xyz="0.1 0 0" rpy="0 0 0" />
      <geometry>
        <box size="0.14 0.02198076923076923 0.02198076923076923" />
      </geometry>
      <material name="white" />
    </visual>
    <collision>
      <origin xyz="0.1 0 0" rpy="0 0 0" />
      <geometry>
        <box size="0.14 0.02198076923076923 0.02198076923076923" />
      </geometry>
    </collision>
    <inertial>
      <origin xyz="0.1 0 0" rpy="0 0 0" />
      <mass value="0.04" />
      <inertia ixx="3.2210281065088756e-06" ixy="0.0" ixz="0.0" iyy="6.694384738658778e-05" iyz="0.0" izz="6.694384738658778e-05" />
    </inertial>
  </link>

  <joint name="white_joint_14" type="revolute">
    <parent link="base" />
    <child link="white_key_14" />
    <origin xyz="-0.03 -0.4021634615384615 -0.010990384615384615" rpy="0 0 0" />
    <axis xyz="0 1 0" />
    <limit lower="0" upper="0.07047134457879563" effort="0.3" velocity="6.67" />
  </joint>

  <link name="white_key_15">
    <visual>
      <origin xyz="0.1 0 0" rpy="0 0 0" />
      <geometry>
        <box size="0.14 0.02198076923076923 0.02198076923076923" />
      </geometry>
      <material name="white" />
    </visual>
    <collision>
      <origin xyz="0.1 0 0" rpy="0 0 0" />
      <geometry>
        <box size="0.14 0.02198076923076923 0.02198076923076923" />
      </geometry>
    </collision>
    <inertial>
      <origin xyz="0.1 0 0" rpy="0 0 0" />
      <mass value="0.04" />
      <inertia ixx="3.2210281065088756e-06" ixy="0.0" ixz="0.0" iyy="6.694384738658778e-05" iyz="0.0" izz="6.694384738658778e-05" />
    </inertial>
  </link>

  <joint name="white_joint_15" type="revolute">
    <parent link="base" />
    <child link="white_key_15" />
    <origin xyz="-0.03 -0.3791826923076923 -0.010990384615384615" rpy="0 0 0" />
    <axis xyz="0 1 0" />
    <limit lower="0" upper="0.07047134457879563" effort="0.3" velocity="6.67" />
  </joint>

  <link name="black_key_16">
    <visual>
      <origin xyz="0.065 0 0" rpy="0 0 0" />
      <geometry>
        <box size="0.09 0.01 0.018" />
      </geometry>
      <material name="black" />
    </visual>
    <collision>
      <origin xyz="0.065 0 0" rpy="0 0 0" />
      <geometry>
        <box size="0.09 0.01 0.018" />
      </geometry>
    </collision>
    <inertial>
      <origin xyz="0.065 0 0" rpy="0 0 0" />
      <mass value="0.02" />
      <inertia ixx="7.066666666666665e-07" ixy="0.0" ixz="0.0" iyy="1.404e-05" iyz="0.0" izz="1.3666666666666664e-05" />
    </inertial>
  </link>

  <joint name="black_joint_16" type="revolute">
    <parent link="base" />
    <child link="black_key_16" />
    <origin xyz="-0.020000000000000004 -0.3671923076923077 0.0035000000000000014" rpy="0 0 0" />
    <axis xyz="0 1 0" />
    <limit lower="0" upper="0.07259945373049462" effort="0.3" velocity="6.67" />
  </joint>

  <link name="white_key_17">
    <visual>
      <origin xyz="0.1 0 0" rpy="0 0 0" />
      <geometry>
        <box size="0.14 0.02198076923076923 0.02198076923076923" />
      </geometry>
      <material name="white" />
    </visual>
    <collision>
      <origin xyz="0.1 0 0" rpy="0 0 0" />
      <geometry>
        <box size="0.14 0.02198076923076923 0.02198076923076923" />
      </geometry>
    </collision>
    <inertial>
      <origin xyz="0.1 0 0" rpy="0 0 0" />
      <mass value="0.04" />
      <inertia ixx="3.2210281065088756e-06" ixy="0.0" ixz="0.0" iyy="6.694384738658778e-05" iyz="0.0" izz="6.694384738658778e-05" />
    </inertial>
  </link>

  <joint name="white_joint_17" type="revolute">
    <parent link="base" />
    <child link="white_key_17" />
    <origin xyz="-0.03 -0.35620192307692305 -0.010990384615384615" rpy="0 0 0" />
    <axis xyz="0 1 0" />
    <limit lower="0" upper="0.07047134457879563" effort="0.3" velocity="6.67" />
  </joint>

  <link name="black_key_18">
    <visual>
      <origin xyz="0.065 0 0" rpy="0 0 0" />
      <geometry>
        <box size="0.09 0.01 0.018" />
      </geometry>
      <material name="black" />
    </visual>
    <collision>
      <origin xyz="0.065 0 0" rpy="0 0 0" />
      <geometry>
        <box size="0.09 0.01 0.018" />
      </geometry>
    </collision>
    <inertial>
      <origin xyz="0.065 0 0" rpy="0 0 0" />
      <mass value="0.02" />
      <inertia ixx="7.066666666666665e-07" ixy="0.0" ixz="0.0" iyy="1.404e-05" iyz="0.0" izz="1.3666666666666664e-05" />
    </inertial>
  </link>

  <joint name="black_joint_18" type="revolute">
    <parent link="base" />
    <child link="black_key_18" />
    <origin xyz="-0.020000000000000004 -0.3442115384615384 0.0035000000000000014" rpy="0 0 0" />
    <axis xyz="0 1 0" />
    <limit lower="0" upper="0.07259945373049462" effort="0.3" velocity="6.67" />
  </joint>

  <link name="white_key_19">
    <visual>
      <origin xyz="0.1 0 0" rpy="0 0 0" />
      <geometry>
        <box size="0.14 0.02198076923076923 0.02198076923076923" />
      </geometry>
      <material name="white" />
    </visual>
    <collision>
      <origin xyz="0.1 0 0" rpy="0 0 0" />
      <geometry>
        <box size="0.14 0.02198076923076923 0.02198076923076923" />
      </geometry>
    </collision>
    <inertial>
      <origin xyz="0.1 0 0" rpy="0 0 0" />
      <mass value="0.04" />
      <inertia ixx="3.2210281065088756e-06" ixy="0.0" ixz="0.0" iyy="6.694384738658778e-05" iyz="0.0" izz="6.694384738658778e-05" />
    </inertial>
  </link>

  <joint name="white_joint_19" type="revolute">
    <parent link="base" />
    <child link="white_key_19" />
    <origin xyz="-0.03 -0.3332211538461538 -0.010990384615384615" rpy="0 0 0" />
    <axis xyz="0 1 0" />
    <limit lower="0" upper="0.07047134457879563" effort="0.3" velocity="6.67" />
  </joint>

  <link name="white_key_20">
    <visual>
      <origin xyz="0.1 0 0" rpy="0 0 0" />
      <geometry>
        <box size="0.14 0.02198076923076923 0.02198076923076923" />
      </geometry>
      <material name="white" />
    </visual>
    <collision>
      <origin xyz="0.1 0 0" rpy="0 0 0" />
      <geometry>
        <box size="0.14 0.02198076923076923 0.02198076923076923" />
      </geometry>
    </collision>
    <inertial>
      <origin xyz="0.1 0 0" rpy="0 0 0" />
      <mass value="0.04" />
      <inertia ixx="3.2210281065088756e-06" ixy="0.0" ixz="0.0" iyy="6.694384738658778e-05" iyz="0.0" izz="6.694384738658778e-05" />
    </inertial>
  </link>

  <joint name="white_joint_20" type="revolute">
    <parent link="base" />
    <child link="white_key_20" />
    <origin xyz="-0.03 -0.3102403846153846 -0.010990384615384615" rpy="0 0 0" />
    <axis xyz="0 1 0" />
    <limit lower="0" upper="0.07047134457879563" effort="0.3" velocity="6.67" />
  </joint>

  <link name="black_key_21">
    <visual>
      <origin xyz="0.065 0 0" rpy="0 0 0" />
      <geometry>
        <box size="0.09 0.01 0.018" />
      </geometry>
      <material name="black" />
    </visual>
    <collision>
      <origin xyz="0.065 0 0" rpy="0 0 0" />
      <geometry>
        <box size="0.09 0.01 0.018" />
      </geometry>
    </collision>
    <inertial>
      <origin xyz="0.065 0 0" rpy="0 0 0" />
      <mass value="0.02" />
      <inertia ixx="7.066666666666665e-07" ixy="0.0" ixz="0.0" iyy="1.404e-05" iyz="0.0" izz="1.3666666666666664e-05" />
    </inertial>
  </link>

  <joint name="black_joint_21" type="revolute">
    <parent link="base" />
    <child link="black_key_21" />
    <origin xyz="-0.020000000000000004 -0.29825 0.0035000000000000014" rpy="0 0 0" />
    <axis xyz="0 1 0" />
    <limit lower="0" upper="0.07259945373049462" effort="0.3" velocity="6.67" />
  </joint>

  <link name="white_key_22">
    <visual>
      <origin xyz="0.1 0 0" rpy="0 0 0" />
      <geometry>
        <box size="0.14 0.02198076923076923 0.02198076923076923" />
      </geometry>
      <material name="white" />
    </visual>
    <collision>
      <origin xyz="0.1 0 0" rpy="0 0 0" />
      <geometry>
        <box size="0.14 0.02198076923076923 0.02198076923076923" />
      </geometry>
    </collision>
    <inertial>
      <origin xyz="0.1 0 0" rpy="0 0 0" />
      <mass value="0.04" />
      <inertia ixx="3.2210281065088756e-06" ixy="0.0" ixz="0.0" iyy="6.694384738658778e-05" iyz="0.0" izz="6.694384738658778e-05" />
    </inertial>
  </link>

  <joint name="white_joint_22" type="revolute">
    <parent link="base" />
    <child link="white_key_22" />
    <origin xyz="-0.03 -0.28725961538461536 -0.010990384615384615" rpy="0 0 0" />
    <axis xyz="0 1 0" />
    <limit lower="0" upper="0.07047134457879563" effort="0.3" velocity="6.67" />
  </joint>

  <link name="black_key_23">
    <visual>
      <origin xyz="0.065 0 0" rpy="0 0 0" />
      <geometry>
        <box size="0.09 0.01 0.018" />
      </geometry>
      <material name="black" />
    </visual>
    <collision>
      <origin xyz="0.065 0 0" rpy="0 0 0" />
      <geometry>
        <box size="0.09 0.01 0.018" />
      </geometry>
    </collision>
    <inertial>
      <origin xyz="0.065 0 0" rpy="0 0 0" />
      <mass value="0.02" />
      <inertia ixx="7.066666666666665e-07" ixy="0.0" ixz="0.0" iyy="1.404e-05" iyz="0.0" izz="1.3666666666666664e-05" />
    </inertial>
  </link>

  <joint name="black_joint_23" type="revolute">
    <parent link="base" />
    <child link="black_key_23" />
    <origin xyz="-0.020000000000000004 -0.2752692307692307 0.0035000000000000014" rpy="0 0 0" />
    <axis xyz="0 1 0" />
    <limit lower="0" upper="0.07259945373049462" effort="0.3" velocity="6.67" />
  </joint>

  <link name="white_key_24">
    <visual>
      <origin xyz="0.1 0 0" rpy="0 0 0" />
      <geometry>
        <box size="0.14 0.02198076923076923 0.02198076923076923" />
      </geometry>
      <material name="white" />
    </visual>
    <collision>
      <origin xyz="0.1 0 0" rpy="0 0 0" />
      <geometry>
        <box size="0.14 0.02198076923076923 0.02198076923076923" />
      </geometry>
    </collision>
    <inertial>
      <origin xyz="0.1 0 0" rpy="0 0 0" />
      <mass value="0.04" />
      <inertia ixx="3.2210281065088756e-06" ixy="0.0" ixz="0.0" iyy="6.694384738658778e-05" iyz="0.0" izz="6.694384738658778e-05" />
    </inertial>
  </link>

  <joint name="white_joint_24" type="revolute">
    <parent link="base" />
    <child link="white_key_24" />
    <origin xyz="-0.03 -0.2642788461538461 -0.010990384615384615" rpy="0 0 0" />
    <axis xyz="0 1 0" />
    <limit lower="0" upper="0.07047134457879563" effort="0.3" velocity="6.67" />
  </joint>

  <link name="black_key_25">
    <visual>
      <origin xyz="0.065 0 0" rpy="0 0 0" />
      <geometry>
        <box size="0.09 0.01 0.018" />
      </geometry>
      <material name="black" />
    </visual>
    <collision>
      <origin xyz="0.065 0 0" rpy="0 0 0" />
      <geometry>
        <box size="0.09 0.01 0.018" />
      </geometry>
    </collision>
    <inertial>
      <origin xyz="0.065 0 0" rpy="0 0 0" />
      <mass value="0.02" />
      <inertia ixx="7.066666666666665e-07" ixy="0.0" ixz="0.0" iyy="1.404e-05" iyz="0.0" izz="1.3666666666666664e-05" />
    </inertial>
  </link>

  <joint name="black_joint_25" type="revolute">
    <parent link="base" />
    <child link="black_key_25" />
    <origin xyz="-0.020000000000000004 -0.2522884615384615 0.0035000000000000014" rpy="0 0 0" />
    <axis xyz="0 1 0" />
    <limit lower="0" upper="0.07259945373049462" effort="0.3" velocity="6.67" />
  </joint>

  <link name="white_key_26">
    <visual>
      <origin xyz="0.1 0 0" rpy="0 0 0" />
      <geometry>
        <box size="0.14 0.02198076923076923 0.02198076923076923" />
      </geometry>
      <material name="white" />
    </visual>
    <collision>
      <origin xyz="0.1 0 0" rpy="0 0 0" />
      <geometry>
        <box size="0.14 0.02198076923076923 0.02198076923076923" />
      </geometry>
    </collision>
    <inertial>
      <origin xyz="0.1 0 0" rpy="0 0 0" />
      <mass value="0.04" />
      <inertia ixx="3.2210281065088756e-06" ixy="0.0" ixz="0.0" iyy="6.694384738658778e-05" iyz="0.0" izz="6.694384738658778e-05" />
    </inertial>
  </link>

  <joint name="white_joint_26" type="revolute">
    <parent link="base" />
    <child link="white_key_26" />
    <origin xyz="-0.03 -0.24129807692307692 -0.010990384615384615" rpy="0 0 0" />
    <axis xyz="0 1 0" />
    <limit lower="0" upper="0.07047134457879563" effort="0.3" velocity="6.67" />
  </joint>

  <link name="white_key_27">
    <visual>
      <origin xyz="0.1 0 0" rpy="0 0 0" />
      <geometry>
        <box size="0.14 0.02198076923076923 0.02198076923076923" />
      </geometry>
      <material name="white" />
    </visual>
    <collision>
      <origin xyz="0.1 0 0" rpy="0 0 0" />
      <geometry>
        <box size="0.14 0.02198076923076923 0.02198076923076923" />
      </geometry>
    </collision>
    <inertial>
      <origin xyz="0.1 0 0" rpy="0 0 0" />
      <mass value="0.04" />
      <inertia ixx="3.2210281065088756e-06" ixy="0.0" ixz="0.0" iyy="6.694384738658778e-05" iyz="0.0" izz="6.694384738658778e-05" />
    </inertial>
  </link>

  <joint name="white_joint_27" type="revolute">
    <parent link="base" />
    <child link="white_key_27" />
    <origin xyz="-0.03 -0.21831730769230767 -0.010990384615384615" rpy="0 0 0" />
    <axis xyz="0 1 0" />
    <limit lower="0" upper="0.07047134457879563" effort="0.3" velocity="6.67" />
  </joint>

  <link name="black_key_28">
    <visual>
      <origin xyz="0.065 0 0" rpy="0 0 0" />
      <geometry>
        <box size="0.09 0.01 0.018" />
      </geometry>
      <material name="black" />
    </visual>
    <collision>
      <origin xyz="0.065 0 0" rpy="0 0 0" />
      <geometry>
        <box size="0.09 0.01 0.018" />
      </geometry>
    </collision>
    <inertial>
      <origin xyz="0.065 0 0" rpy="0 0 0" />
      <mass value="0.02" />
      <inertia ixx="7.066666666666665e-07" ixy="0.0" ixz="0.0" iyy="1.404e-05" iyz="0.0" izz="1.3666666666666664e-05" />
    </inertial>
  </link>

  <joint name="black_joint_28" type="revolute">
    <parent link="base" />
    <child link="black_key_28" />
    <origin xyz="-0.020000000000000004 -0.20632692307692307 0.0035000000000000014" rpy="0 0 0" />
    <axis xyz="0 1 0" />
    <limit lower="0" upper="0.07259945373049462" effort="0.3" velocity="6.67" />
  </joint>

  <link name="white_key_29">
    <visual>
      <origin xyz="0.1 0 0" rpy="0 0 0" />
      <geometry>
        <box size="0.14 0.02198076923076923 0.02198076923076923" />
      </geometry>
      <material name="white" />
    </visual>
    <collision>
      <origin xyz="0.1 0 0" rpy="0 0 0" />
      <geometry>
        <box size="0.14 0.02198076923076923 0.02198076923076923" />
      </geometry>
    </collision>
    <inertial>
      <origin xyz="0.1 0 0" rpy="0 0 0" />
      <mass value="0.04" />
      <inertia ixx="3.2210281065088756e-06" ixy="0.0" ixz="0.0" iyy="6.694384738658778e-05" iyz="0.0" izz="6.694384738658778e-05" />
    </inertial>
  </link>

  <joint name="white_joint_29" type="revolute">
    <parent link="base" />
    <child link="white_key_29" />
    <origin xyz="-0.03 -0.19533653846153842 -0.010990384615384615" rpy="0 0 0" />
    <axis xyz="0 1 0" />
    <limit lower="0" upper="0.07047134457879563" effort="0.3" velocity="6.67" />
  </joint>

  <link name="black_key_30">
    <visual>
      <origin xyz="0.065 0 0" rpy="0 0 0" />
      <geometry>
        <box size="0.09 0.01 0.018" />
      </geometry>
      <material name="black" />
    </visual>
    <collision>
      <origin xyz="0.065 0 0" rpy="0 0 0" />
      <geometry>
        <box size="0.09 0.01 0.018" />
      </geometry>
    </collision>
    <inertial>
      <origin xyz="0.065 0 0" rpy="0 0 0" />
      <mass value="0.02" />
      <inertia ixx="7.066666666666665e-07" ixy="0.0" ixz="0.0" iyy="1.404e-05" iyz="0.0" izz="1.3666666666666664e-05" />
    </inertial>
  </link>

  <joint name="black_joint_30" type="revolute">
    <parent link="base" />
    <child link="black_key_30" />
    <origin xyz="-0.020000000000000004 -0.18334615384615377 0.0035000000000000014" rpy="0 0 0" />
    <axis xyz="0 1 0" />
    <limit lower="0" upper="0.07259945373049462" effort="0.3" velocity="6.67" />
  </joint>

  <link name="white_key_31">
    <visual>
      <origin xyz="0.1 0 0" rpy="0 0 0" />
      <geometry>
        <box size="0.14 0.02198076923076923 0.02198076923076923" />
      </geometry>
      <material name="white" />
    </visual>
    <collision>
      <origin xyz="0.1 0 0" rpy="0 0 0" />
      <geometry>
        <box size="0.14 0.02198076923076923 0.02198076923076923" />
      </geometry>
    </collision>
    <inertial>
      <origin xyz="0.1 0 0" rpy="0 0 0" />
      <mass value="0.04" />
      <inertia ixx="3.2210281065088756e-06" ixy="0.0" ixz="0.0" iyy="6.694384738658778e-05" iyz="0.0" izz="6.694384738658778e-05" />
    </inertial>
  </link>

  <joint name="white_joint_31" type="revolute">
    <parent link="base" />
    <child link="white_key_31" />
    <origin xyz="-0.03 -0.17235576923076923 -0.010990384615384615" rpy="0 0 0" />
    <axis xyz="0 1 0" />
    <limit lower="0" upper="0.07047134457879563" effort="0.3" velocity="6.67" />
  </joint>

  <link name="white_key_32">
    <visual>
      <origin xyz="0.1 0 0" rpy="0 0 0" />
      <geometry>
        <box size="0.14 0.02198076923076923 0.02198076923076923" />
      </geometry>
      <material name="white" />
    </visual>
    <collision>
      <origin xyz="0.1 0 0" rpy="0 0 0" />
      <geometry>
        <box size="0.14 0.02198076923076923 0.02198076923076923" />
      </geometry>
    </collision>
    <inertial>
      <origin xyz="0.1 0 0" rpy="0 0 0" />
      <mass value="0.04" />
      <inertia ixx="3.2210281065088756e-06" ixy="0.0" ixz="0.0" iyy="6.694384738658778e-05" iyz="0.0" izz="6.694384738658778e-05" />
    </inertial>
  </link>

  <joint name="white_joint_32" type="revolute">
    <parent link="base" />
    <child link="white_key_32" />
    <origin xyz="-0.03 -0.14937499999999998 -0.010990384615384615" rpy="0 0 0" />
    <axis xyz="0 1 0" />
    <limit lower="0" upper="0.07047134457879563" effort="0.3" velocity="6.67" />
  </joint>

  <link name="black_key_33">
    <visual>
      <origin xyz="0.065 0 0" rpy="0 0 0" />
      <geometry>
        <box size="0.09 0.01 0.018" />
      </geometry>
      <material name="black" />
    </visual>
    <collision>
      <origin xyz="0.065 0 0" rpy="0 0 0" />
      <geometry>
        <box size="0.09 0.01 0.018" />
      </geometry>
    </collision>
    <inertial>
      <origin xyz="0.065 0 0" rpy="0 0 0" />
      <mass value="0.02" />
      <inertia ixx="7.066666666666665e-07" ixy="0.0" ixz="0.0" iyy="1.404e-05" iyz="0.0" izz="1.3666666666666664e-05" />
    </inertial>
  </link>

  <joint name="black_joint_33" type="revolute">
    <parent link="base" />
    <child link="black_key_33" />
    <origin xyz="-0.020000000000000004 -0.13738461538461538 0.0035000000000000014" rpy="0 0 0" />
    <axis xyz="0 1 0" />
    <limit lower="0" upper="0.07259945373049462" effort="0.3" velocity="6.67" />
  </joint>

  <link name="white_key_34">
    <visual>
      <origin xyz="0.1 0 0" rpy="0 0 0" />
      <geometry>
        <box size="0.14 0.02198076923076923 0.02198076923076923" />
      </geometry>
      <material name="white" />
    </visual>
    <collision>
      <origin xyz="0.1 0 0" rpy="0 0 0" />
      <geometry>
        <box size="0.14 0.02198076923076923 0.02198076923076923" />
      </geometry>
    </collision>
    <inertial>
      <origin xyz="0.1 0 0" rpy="0 0 0" />
      <mass value="0.04" />
      <inertia ixx="3.2210281065088756e-06" ixy="0.0" ixz="0.0" iyy="6.694384738658778e-05" iyz="0.0" izz="6.694384738658778e-05" />
    </inertial>
  </link>

  <joint name="white_joint_34" type="revolute">
    <parent link="base" />
    <child link="white_key_34" />
    <origin xyz="-0.03 -0.12639423076923073 -0.010990384615384615" rpy="0 0 0" />
    <axis xyz="0 1 0" />
    <limit lower="0" upper="0.07047134457879563" effort="0.3" velocity="6.67" />
  </joint>

  <link name="black_key_35">
    <visual>
      <origin xyz="0.065 0 0" rpy="0 0 0" />
      <geometry>
        <box size="0.09 0.01 0.018" />
      </geometry>
      <material name="black" />
    </visual>
    <collision>
      <origin xyz="0.065 0 0" rpy="0 0 0" />
      <geometry>
        <box size="0.09 0.01 0.018" />
      </geometry>
    </collision>
    <inertial>
      <origin xyz="0.065 0 0" rpy="0 0 0" />
      <mass value="0.02" />
      <inertia ixx="7.066666666666665e-07" ixy="0.0" ixz="0.0" iyy="1.404e-05" iyz="0.0" izz="1.3666666666666664e-05" />
    </inertial>
  </link>

  <joint name="black_joint_35" type="revolute">
    <parent link="base" />
    <child link="black_key_35" />
    <origin xyz="-0.020000000000000004 -0.11440384615384608 0.0035000000000000014" rpy="0 0 0" />
    <axis xyz="0 1 0" />
    <limit lower="0" upper="0.07259945373049462" effort="0.3" velocity="6.67" />
  </joint>

  <link name="white_key_36">
    <visual>
      <origin xyz="0.1 0 0" rpy="0 0 0" />
      <geometry>
        <box size="0.14 0.02198076923076923 0.02198076923076923" />
      </geometry>
      <material name="white" />
    </visual>
    <collision>
      <origin xyz="0.1 0 0" rpy="0 0 0" />
      <geometry>
        <box size="0.14 0.02198076923076923 0.02198076923076923" />
      </geometry>
    </collision>
    <inertial>
      <origin xyz="0.1 0 0" rpy="0 0 0" />
      <mass value="0.04" />
      <inertia ixx="3.2210281065088756e-06" ixy="0.0" ixz="0.0" iyy="6.694384738658778e-05" iyz="0.0" izz="6.694384738658778e-05" />
    </inertial>
  </link>

  <joint name="white_joint_36" type="revolute">
    <parent link="base" />
    <child link="white_key_36" />
    <origin xyz="-0.03 -0.10341346153846154 -0.010990384615384615" rpy="0 0 0" />
    <axis xyz="0 1 0" />
    <limit lower="0" upper="0.07047134457879563" effort="0.3" velocity="6.67" />
  </joint>

  <link name="black_key_37">
    <visual>
      <origin xyz="0.065 0 0" rpy="0 0 0" />
      <geometry>
        <box size="0.09 0.01 0.018" />
      </geometry>
      <material name="black" />
    </visual>
    <collision>
      <origin xyz="0.065 0 0" rpy="0 0 0" />
      <geometry>
        <box size="0.09 0.01 0.018" />
      </geometry>
    </collision>
    <inertial>
      <origin xyz="0.065 0 0" rpy="0 0 0" />
      <mass value="0.02" />
      <inertia ixx="7.066666666666665e-07" ixy="0.0" ixz="0.0" iyy="1.404e-05" iyz="0.0" izz="1.3666666666666664e-05" />
    </inertial>
  </link>

  <joint name="black_joint_37" type="revolute">
    <parent link="base" />
    <child link="black_key_37" />
    <origin xyz="-0.020000000000000004 -0.09142307692307688 0.0035000000000000014" rpy="0 0 0" />
    <axis xyz="0 1 0" />
    <limit lower="0" upper="0.07259945373049462" effort="0.3" velocity="6.67" />
  </joint>

  <link name="white_key_38">
    <visual>
      <origin xyz="0.1 0 0" rpy="0 0 0" />
      <geometry>
        <box size="0.14 0.02198076923076923 0.02198076923076923" />
      </geometry>
      <material name="white" />
    </visual>
    <collision>
      <origin xyz="0.1 0 0" rpy="0 0 0" />
      <geometry>
        <box size="0.14 0.02198076923076923 0.02198076923076923" />
      </geometry>
    </collision>
    <inertial>
      <origin xyz="0.1 0 0" rpy="0 0 0" />
      <mass value="0.04" />
      <inertia ixx="3.2210281065088756e-06" ixy="0.0" ixz="0.0" iyy="6.694384738658778e-05" iyz="0.0" izz="6.694384738658778e-05" />
    </inertial>
  </link>

  <joint name="white_joint_38" type="revolute">
    <parent link="base" />
    <child link="white_key_38" />
    <origin xyz="-0.03 -0.08043269230769223 -0.010990384615384615" rpy="0 0 0" />
    <axis xyz="0 1 0" />
    <limit lower="0" upper="0.07047134457879563" effort="0.3" velocity="6.67" />
  </joint>

  <link name="white_key_39">
    <visual>
      <origin xyz="0.1 0 0" rpy="0 0 0" />
      <geometry>
        <box size="0.14 0.02198076923076923 0.02198076923076923" />
      </geometry>
      <material name="white" />
    </visual>
    <collision>
      <origin xyz="0.1 0 0" rpy="0 0 0" />
      <geometry>
        <box size="0.14 0.02198076923076923 0.02198076923076923" />
      </geometry>
    </collision>
    <inertial>
      <origin xyz="0.1 0 0" rpy="0 0 0" />
      <mass value="0.04" />
      <inertia ixx="3.2210281065088756e-06" ixy="0.0" ixz="0.0" iyy="6.694384738658778e-05" iyz="0.0" izz="6.694384738658778e-05" />
    </inertial>
  </link>

  <joint name="white_joint_39" type="revolute">
    <parent link="base" />
    <child link="white_key_39" />
    <origin xyz="-0.03 -0.05745192307692304 -0.010990384615384615" rpy="0 0 0" />
    <axis xyz="0 1 0" />
    <limit lower="0" upper="0.07047134457879563" effort="0.3" velocity="6.67" />
  </joint>

  <link name="black_key_40">
    <visual>
      <origin xyz="0.065 0 0" rpy="0 0 0" />
      <geometry>
        <box size="0.09 0.01 0.018" />
      </geometry>
      <material name="black" />
    </visual>
    <collision>
      <origin xyz="0.065 0 0" rpy="0 0 0" />
      <geometry>
        <box size="0.09 0.01 0.018" />
      </geometry>
    </collision>
    <inertial>
      <origin xyz="0.065 0 0" rpy="0 0 0" />
      <mass value="0.02" />
      <inertia ixx="7.066666666666665e-07" ixy="0.0" ixz="0.0" iyy="1.404e-05" iyz="0.0" izz="1.3666666666666664e-05" />
    </inertial>
  </link>

  <joint name="black_joint_40" type="revolute">
    <parent link="base" />
    <child link="black_key_40" />
    <origin xyz="-0.020000000000000004 -0.04546153846153844 0.0035000000000000014" rpy="0 0 0" />
    <axis xyz="0 1 0" />
    <limit lower="0" upper="0.07259945373049462" effort="0.3" velocity="6.67" />
  </joint>

  <link name="white_key_41">
    <visual>
      <origin xyz="0.1 0 0" rpy="0 0 0" />
      <geometry>
        <box size="0.14 0.02198076923076923 0.02198076923076923" />
      </geometry>
      <material name="white" />
    </visual>
    <collision>
      <origin xyz="0.1 0 0" rpy="0 0 0" />
      <geometry>
        <box size="0.14 0.02198076923076923 0.02198076923076923" />
      </geometry>
    </collision>
    <inertial>
      <origin xyz="0.1 0 0" rpy="0 0 0" />
      <mass value="0.04" />
      <inertia ixx="3.2210281065088756e-06" ixy="0.0" ixz="0.0" iyy="6.694384738658778e-05" iyz="0.0" izz="6.694384738658778e-05" />
    </inertial>
  </link>

  <joint name="white_joint_41" type="revolute">
    <parent link="base" />
    <child link="white_key_41" />
    <origin xyz="-0.03 -0.034471153846153846 -0.010990384615384615" rpy="0 0 0" />
    <axis xyz="0 1 0" />
    <limit lower="0" upper="0.07047134457879563" effort="0.3" velocity="6.67" />
  </joint>

  <link name="black_key_42">
    <visual>
      <origin xyz="0.065 0 0" rpy="0 0 0" />
      <geometry>
        <box size="0.09 0.01 0.018" />
      </geometry>
      <material name="black" />
    </visual>
    <collision>
      <origin xyz="0.065 0 0" rpy="0 0 0" />
      <geometry>
        <box size="0.09 0.01 0.018" />
      </geometry>
    </collision>
    <inertial>
      <origin xyz="0.065 0 0" rpy="0 0 0" />
      <mass value="0.02" />
      <inertia ixx="7.066666666666665e-07" ixy="0.0" ixz="0.0" iyy="1.404e-05" iyz="0.0" izz="1.3666666666666664e-05" />
    </inertial>
  </link>

  <joint name="black_joint_42" type="revolute">
    <parent link="base" />
    <child link="black_key_42" />
    <origin xyz="-0.020000000000000004 -0.022480769230769138 0.0035000000000000014" rpy="0 0 0" />
    <axis xyz="0 1 0" />
    <limit lower="0" upper="0.07259945373049462" effort="0.3" velocity="6.67" />
  </joint>

  <link name="white_key_43">
    <visual>
      <origin xyz="0.1 0 0" rpy="0 0 0" />
      <geometry>
        <box size="0.14 0.02198076923076923 0.02198076923076923" />
      </geometry>
      <material name="white" />
    </visual>
    <collision>
      <origin xyz="0.1 0 0" rpy="0 0 0" />
      <geometry>
        <box size="0.14 0.02198076923076923 0.02198076923076923" />
      </geometry>
    </collision>
    <inertial>
      <origin xyz="0.1 0 0" rpy="0 0 0" />
      <mass value="0.04" />
      <inertia ixx="3.2210281065088756e-06" ixy="0.0" ixz="0.0" iyy="6.694384738658778e-05" iyz="0.0" izz="6.694384738658778e-05" />
    </inertial>
  </link>

  <joint name="white_joint_43" type="revolute">
    <parent link="base" />
    <child link="white_key_43" />
    <origin xyz="-0.03 -0.011490384615384541 -0.010990384615384615" rpy="0 0 0" />
    <axis xyz="0 1 0" />
    <limit lower="0" upper="0.07047134457879563" effort="0.3" velocity="6.67" />
  </joint>

  <link name="white_key_44">
    <visual>
      <origin xyz="0.1 0 0" rpy="0 0 0" />
      <geometry>
        <box size="0.14 0.02198076923076923 0.02198076923076923" />
      </geometry>
      <material name="white" />
    </visual>
    <collision>
      <origin xyz="0.1 0 0" rpy="0 0 0" />
      <geometry>
        <box size="0.14 0.02198076923076923 0.02198076923076923" />
      </geometry>
    </collision>
    <inertial>
      <origin xyz="0.1 0 0" rpy="0 0 0" />
      <mass value="0.04" />
      <inertia ixx="3.2210281065088756e-06" ixy="0.0" ixz="0.0" iyy="6.694384738658778e-05" iyz="0.0" izz="6.694384738658778e-05" />
    </inertial>
  </link>

  <joint name="white_joint_44" type="revolute">
    <parent link="base" />
    <child link="white_key_44" />
    <origin xyz="-0.03 0.011490384615384652 -0.010990384615384615" rpy="0 0 0" />
    <axis xyz="0 1 0" />
    <limit lower="0" upper="0.07047134457879563" effort="0.3" velocity="6.67" />
  </joint>

  <link name="black_key_45">
    <visual>
      <origin xyz="0.065 0 0" rpy="0 0 0" />
      <geometry>
        <box size="0.09 0.01 0.018" />
      </geometry>
      <material name="black" />
    </visual>
    <collision>
      <origin xyz="0.065 0 0" rpy="0 0 0" />
      <geometry>
        <box size="0.09 0.01 0.018" />
      </geometry>
    </collision>
    <inertial>
      <origin xyz="0.065 0 0" rpy="0 0 0" />
      <mass value="0.02" />
      <inertia ixx="7.066666666666665e-07" ixy="0.0" ixz="0.0" iyy="1.404e-05" iyz="0.0" izz="1.3666666666666664e-05" />
    </inertial>
  </link>

  <joint name="black_joint_45" type="revolute">
    <parent link="base" />
    <child link="black_key_45" />
    <origin xyz="-0.020000000000000004 0.02348076923076925 0.0035000000000000014" rpy="0 0 0" />
    <axis xyz="0 1 0" />
    <limit lower="0" upper="0.07259945373049462" effort="0.3" velocity="6.67" />
  </joint>

  <link name="white_key_46">
    <visual>
      <origin xyz="0.1 0 0" rpy="0 0 0" />
      <geometry>
        <box size="0.14 0.02198076923076923 0.02198076923076923" />
      </geometry>
      <material name="white" />
    </visual>
    <collision>
      <origin xyz="0.1 0 0" rpy="0 0 0" />
      <geometry>
        <box size="0.14 0.02198076923076923 0.02198076923076923" />
      </geometry>
    </collision>
    <inertial>
      <origin xyz="0.1 0 0" rpy="0 0 0" />
      <mass value="0.04" />
      <inertia ixx="3.2210281065088756e-06" ixy="0.0" ixz="0.0" iyy="6.694384738658778e-05" iyz="0.0" izz="6.694384738658778e-05" />
    </inertial>
  </link>

  <joint name="white_joint_46" type="revolute">
    <parent link="base" />
    <child link="white_key_46" />
    <origin xyz="-0.03 0.034471153846153846 -0.010990384615384615" rpy="0 0 0" />
    <axis xyz="0 1 0" />
    <limit lower="0" upper="0.07047134457879563" effort="0.3" velocity="6.67" />
  </joint>

  <link name="black_key_47">
    <visual>
      <origin xyz="0.065 0 0" rpy="0 0 0" />
      <geometry>
        <box size="0.09 0.01 0.018" />
      </geometry>
      <material name="black" />
    </visual>
    <collision>
      <origin xyz="0.065 0 0" rpy="0 0 0" />
      <geometry>
        <box size="0.09 0.01 0.018" />
      </geometry>
    </collision>
    <inertial>
      <origin xyz="0.065 0 0" rpy="0 0 0" />
      <mass value="0.02" />
      <inertia ixx="7.066666666666665e-07" ixy="0.0" ixz="0.0" iyy="1.404e-05" iyz="0.0" izz="1.3666666666666664e-05" />
    </inertial>
  </link>

  <joint name="black_joint_47" type="revolute">
    <parent link="base" />
    <child link="black_key_47" />
    <origin xyz="-0.020000000000000004 0.046461538461538554 0.0035000000000000014" rpy="0 0 0" />
    <axis xyz="0 1 0" />
    <limit lower="0" upper="0.07259945373049462" effort="0.3" velocity="6.67" />
  </joint>

  <link name="white_key_48">
    <visual>
      <origin xyz="0.1 0 0" rpy="0 0 0" />
      <geometry>
        <box size="0.14 0.02198076923076923 0.02198076923076923" />
      </geometry>
      <material name="white" />
    </visual>
    <collision>
      <origin xyz="0.1 0 0" rpy="0 0 0" />
      <geometry>
        <box size="0.14 0.02198076923076923 0.02198076923076923" />
      </geometry>
    </collision>
    <inertial>
      <origin xyz="0.1 0 0" rpy="0 0 0" />
      <mass value="0.04" />
      <inertia ixx="3.2210281065088756e-06" ixy="0.0" ixz="0.0" iyy="6.694384738658778e-05" iyz="0.0" izz="6.694384738658778e-05" />
    </inertial>
  </link>

  <joint name="white_joint_48" type="revolute">
    <parent link="base" />
    <child link="white_key_48" />
    <origin xyz="-0.03 0.05745192307692315 -0.010990384615384615" rpy="0 0 0" />
    <axis xyz="0 1 0" />
    <limit lower="0" upper="0.07047134457879563" effort="0.3" velocity="6.67" />
  </joint>

  <link name="black_key_49">
    <visual>
      <origin xyz="0.065 0 0" rpy="0 0 0" />
      <geometry>
        <box size="0.09 0.01 0.018" />
      </geometry>
      <material name="black" />
    </visual>
    <collision>
      <origin xyz="0.065 0 0" rpy="0 0 0" />
      <geometry>
        <box size="0.09 0.01 0.018" />
      </geometry>
    </collision>
    <inertial>
      <origin xyz="0.065 0 0" rpy="0 0 0" />
      <mass value="0.02" />
      <inertia ixx="7.066666666666665e-07" ixy="0.0" ixz="0.0" iyy="1.404e-05" iyz="0.0" izz="1.3666666666666664e-05" />
    </inertial>
  </link>

  <joint name="black_joint_49" type="revolute">
    <parent link="base" />
    <child link="black_key_49" />
    <origin xyz="-0.020000000000000004 0.06944230769230775 0.0035000000000000014" rpy="0 0 0" />
    <axis xyz="0 1 0" />
    <limit lower="0" upper="0.07259945373049462" effort="0.3" velocity="6.67" />
  </joint>

  <link name="white_key_50">
    <visual>
      <origin xyz="0.1 0 0" rpy="0 0 0" />
      <geometry>
        <box size="0.14 0.02198076923076923 0.02198076923076923" />
      </geometry>
      <material name="white" />
    </visual>
    <collision>
      <origin xyz="0.1 0 0" rpy="0 0 0" />
      <geometry>
        <box size="0.14 0.02198076923076923 0.02198076923076923" />
      </geometry>
    </collision>
    <inertial>
      <origin xyz="0.1 0 0" rpy="0 0 0" />
      <mass value="0.04" />
      <inertia ixx="3.2210281065088756e-06" ixy="0.0" ixz="0.0" iyy="6.694384738658778e-05" iyz="0.0" izz="6.694384738658778e-05" />
    </inertial>
  </link>

  <joint name="white_joint_50" type="revolute">
    <parent link="base" />
    <child link="white_key_50" />
    <origin xyz="-0.03 0.08043269230769234 -0.010990384615384615" rpy="0 0 0" />
    <axis xyz="0 1 0" />
    <limit lower="0" upper="0.07047134457879563" effort="0.3" velocity="6.67" />
  </joint>

  <link name="white_key_51">
    <visual>
      <origin xyz="0.1 0 0" rpy="0 0 0" />
      <geometry>
        <box size="0.14 0.02198076923076923 0.02198076923076923" />
      </geometry>
      <material name="white" />
    </visual>
    <collision>
      <origin xyz="0.1 0 0" rpy="0 0 0" />
      <geometry>
        <box size="0.14 0.02198076923076923 0.02198076923076923" />
      </geometry>
    </collision>
    <inertial>
      <origin xyz="0.1 0 0" rpy="0 0 0" />
      <mass value="0.04" />
      <inertia ixx="3.2210281065088756e-06" ixy="0.0" ixz="0.0" iyy="6.694384738658778e-05" iyz="0.0" izz="6.694384738658778e-05" />
    </inertial>
  </link>

  <joint name="white_joint_51" type="revolute">
    <parent link="base" />
    <child link="white_key_51" />
    <origin xyz="-0.03 0.10341346153846154 -0.010990384615384615" rpy="0 0 0" />
    <axis xyz="0 1 0" />
    <limit lower="0" upper="0.07047134457879563" effort="0.3" velocity="6.67" />
  </joint>

  <link name="black_key_52">
    <visual>
      <origin xyz="0.065 0 0" rpy="0 0 0" />
      <geometry>
        <box size="0.09 0.01 0.018" />
      </geometry>
      <material name="black" />
    </visual>
    <collision>
      <origin xyz="0.065 0 0" rpy="0 0 0" />
      <geometry>
        <box size="0.09 0.01 0.018" />
      </geometry>
    </collision>
    <inertial>
      <origin xyz="0.065 0 0" rpy="0 0 0" />
      <mass value="0.02" />
      <inertia ixx="7.066666666666665e-07" ixy="0.0" ixz="0.0" iyy="1.404e-05" iyz="0.0" izz="1.3666666666666664e-05" />
    </inertial>
  </link>

  <joint name="black_joint_52" type="revolute">
    <parent link="base" />
    <child link="black_key_52" />
    <origin xyz="-0.020000000000000004 0.11540384615384613 0.0035000000000000014" rpy="0 0 0" />
    <axis xyz="0 1 0" />
    <limit lower="0" upper="0.07259945373049462" effort="0.3" velocity="6.67" />
  </joint>

  <link name="white_key_53">
    <visual>
      <origin xyz="0.1 0 0" rpy="0 0 0" />
      <geometry>
        <box size="0.14 0.02198076923076923 0.02198076923076923" />
      </geometry>
      <material name="white" />
    </visual>
    <collision>
      <origin xyz="0.1 0 0" rpy="0 0 0" />
      <geometry>
        <box size="0.14 0.02198076923076923 0.02198076923076923" />
      </geometry>
    </collision>
    <inertial>
      <origin xyz="0.1 0 0" rpy="0 0 0" />
      <mass value="0.04" />
      <inertia ixx="3.2210281065088756e-06" ixy="0.0" ixz="0.0" iyy="6.694384738658778e-05" iyz="0.0" izz="6.694384738658778e-05" />
    </inertial>
  </link>

  <joint name="white_joint_53" type="revolute">
    <parent link="base" />
    <child link="white_key_53" />
    <origin xyz="-0.03 0.12639423076923084 -0.010990384615384615" rpy="0 0 0" />
    <axis xyz="0 1 0" />
    <limit lower="0" upper="0.07047134457879563" effort="0.3" velocity="6.67" />
  </joint>

  <link name="black_key_54">
    <visual>
      <origin xyz="0.065 0 0" rpy="0 0 0" />
      <geometry>
        <box size="0.09 0.01 0.018" />
      </geometry>
      <material name="black" />
    </visual>
    <collision>
      <origin xyz="0.065 0 0" rpy="0 0 0" />
      <geometry>
        <box size="0.09 0.01 0.018" />
      </geometry>
    </collision>
    <inertial>
      <origin xyz="0.065 0 0" rpy="0 0 0" />
      <mass value="0.02" />
      <inertia ixx="7.066666666666665e-07" ixy="0.0" ixz="0.0" iyy="1.404e-05" iyz="0.0" izz="1.3666666666666664e-05" />
    </inertial>
  </link>

  <joint name="black_joint_54" type="revolute">
    <parent link="base" />
    <child link="black_key_54" />
    <origin xyz="-0.020000000000000004 0.13838461538461544 0.0035000000000000014" rpy="0 0 0" />
    <axis xyz="0 1 0" />
    <limit lower="0" upper="0.07259945373049462" effort="0.3" velocity="6.67" />
  </joint>

  <link name="white_key_55">
    <visual>
      <origin xyz="0.1 0 0" rpy="0 0 0" />
      <geometry>
        <box size="0.14 0.02198076923076923 0.02198076923076923" />
      </geometry>
      <material name="white" />
    </visual>
    <collision>
      <origin xyz="0.1 0 0" rpy="0 0 0" />
      <geometry>
        <box size="0.14 0.02198076923076923 0.02198076923076923" />
      </geometry>
    </collision>
    <inertial>
      <origin xyz="0.1 0 0" rpy="0 0 0" />
      <mass value="0.04" />
      <inertia ixx="3.2210281065088756e-06" ixy="0.0" ixz="0.0" iyy="6.694384738658778e-05" iyz="0.0" izz="6.694384738658778e-05" />
    </inertial>
  </link>

  <joint name="white_joint_55" type="revolute">
    <parent link="base" />
    <child link="white_key_55" />
    <origin xyz="-0.03 0.14937500000000004 -0.010990384615384615" rpy="0 0 0" />
    <axis xyz="0 1 0" />
    <limit lower="0" upper="0.07047134457879563" effort="0.3" velocity="6.67" />
  </joint>

  <link name="white_key_56">
    <visual>
      <origin xyz="0.1 0 0" rpy="0 0 0" />
      <geometry>
        <box size="0.14 0.02198076923076923 0.02198076923076923" />
      </geometry>
      <material name="white" />
    </visual>
    <collision>
      <origin xyz="0.1 0 0" rpy="0 0 0" />
      <geometry>
        <box size="0.14 0.02198076923076923 0.02198076923076923" />
      </geometry>
    </collision>
    <inertial>
      <origin xyz="0.1 0 0" rpy="0 0 0" />
      <mass value="0.04" />
      <inertia ixx="3.2210281065088756e-06" ixy="0.0" ixz="0.0" iyy="6.694384738658778e-05" iyz="0.0" izz="6.694384738658778e-05" />
    </inertial>
  </link>

  <joint name="white_joint_56" type="revolute">
    <parent link="base" />
    <child link="white_key_56" />
    <origin xyz="-0.03 0.17235576923076923 -0.010990384615384615" rpy="0 0 0" />
    <axis xyz="0 1 0" />
    <limit lower="0" upper="0.07047134457879563" effort="0.3" velocity="6.67" />
  </joint>

  <link name="black_key_57">
    <visual>
      <origin xyz="0.065 0 0" rpy="0 0 0" />
      <geometry>
        <box size="0.09 0.01 0.018" />
      </geometry>
      <material name="black" />
    </visual>
    <collision>
      <origin xyz="0.065 0 0" rpy="0 0 0" />
      <geometry>
        <box size="0.09 0.01 0.018" />
      </geometry>
    </collision>
    <inertial>
      <origin xyz="0.065 0 0" rpy="0 0 0" />
      <mass value="0.02" />
      <inertia ixx="7.066666666666665e-07" ixy="0.0" ixz="0.0" iyy="1.404e-05" iyz="0.0" izz="1.3666666666666664e-05" />
    </inertial>
  </link>

  <joint name="black_joint_57" type="revolute">
    <parent link="base" />
    <child link="black_key_57" />
    <origin xyz="-0.020000000000000004 0.18434615384615383 0.0035000000000000014" rpy="0 0 0" />
    <axis xyz="0 1 0" />
    <limit lower="0" upper="0.07259945373049462" effort="0.3" velocity="6.67" />
  </joint>

  <link name="white_key_58">
    <visual>
      <origin xyz="0.1 0 0" rpy="0 0 0" />
      <geometry>
        <box size="0.14 0.02198076923076923 0.02198076923076923" />
      </geometry>
      <material name="white" />
    </visual>
    <collision>
      <origin xyz="0.1 0 0" rpy="0 0 0" />
      <geometry>
        <box size="0.14 0.02198076923076923 0.02198076923076923" />
      </geometry>
    </collision>
    <inertial>
      <origin xyz="0.1 0 0" rpy="0 0 0" />
      <mass value="0.04" />
      <inertia ixx="3.2210281065088756e-06" ixy="0.0" ixz="0.0" iyy="6.694384738658778e-05" iyz="0.0" izz="6.694384738658778e-05" />
    </inertial>
  </link>

  <joint name="white_joint_58" type="revolute">
    <parent link="base" />
    <child link="white_key_58" />
    <origin xyz="-0.03 0.19533653846153853 -0.010990384615384615" rpy="0 0 0" />
    <axis xyz="0 1 0" />
    <limit lower="0" upper="0.07047134457879563" effort="0.3" velocity="6.67" />
  </joint>

  <link name="black_key_59">
    <visual>
      <origin xyz="0.065 0 0" rpy="0 0 0" />
      <geometry>
        <box size="0.09 0.01 0.018" />
      </geometry>
      <material name="black" />
    </visual>
    <collision>
      <origin xyz="0.065 0 0" rpy="0 0 0" />
      <geometry>
        <box size="0.09 0.01 0.018" />
      </geometry>
    </collision>
    <inertial>
      <origin xyz="0.065 0 0" rpy="0 0 0" />
      <mass value="0.02" />
      <inertia ixx="7.066666666666665e-07" ixy="0.0" ixz="0.0" iyy="1.404e-05" iyz="0.0" izz="1.3666666666666664e-05" />
    </inertial>
  </link>

  <joint name="black_joint_59" type="revolute">
    <parent link="base" />
    <child link="black_key_59" />
    <origin xyz="-0.020000000000000004 0.20732692307692313 0.0035000000000000014" rpy="0 0 0" />
    <axis xyz="0 1 0" />
    <limit lower="0" upper="0.07259945373049462" effort="0.3" velocity="6.67" />
  </joint>

  <link name="white_key_60">
    <visual>
      <origin xyz="0.1 0 0" rpy="0 0 0" />
      <geometry>
        <box size="0.14 0.02198076923076923 0.02198076923076923" />
      </geometry>
      <material name="white" />
    </visual>
    <collision>
      <origin xyz="0.1 0 0" rpy="0 0 0" />
      <geometry>
        <box size="0.14 0.02198076923076923 0.02198076923076923" />
      </geometry>
    </collision>
    <inertial>
      <origin xyz="0.1 0 0" rpy="0 0 0" />
      <mass value="0.04" />
      <inertia ixx="3.2210281065088756e-06" ixy="0.0" ixz="0.0" iyy="6.694384738658778e-05" iyz="0.0" izz="6.694384738658778e-05" />
    </inertial>
  </link>

  <joint name="white_joint_60" type="revolute">
    <parent link="base" />
    <child link="white_key_60" />
    <origin xyz="-0.03 0.21831730769230773 -0.010990384615384615" rpy="0 0 0" />
    <axis xyz="0 1 0" />
    <limit lower="0" upper="0.07047134457879563" effort="0.3" velocity="6.67" />
  </joint>

  <link name="black_key_61">
    <visual>
      <origin xyz="0.065 0 0" rpy="0 0 0" />
      <geometry>
        <box size="0.09 0.01 0.018" />
      </geometry>
      <material name="black" />
    </visual>
    <collision>
      <origin xyz="0.065 0 0" rpy="0 0 0" />
      <geometry>
        <box size="0.09 0.01 0.018" />
      </geometry>
    </collision>
    <inertial>
      <origin xyz="0.065 0 0" rpy="0 0 0" />
      <mass value="0.02" />
      <inertia ixx="7.066666666666665e-07" ixy="0.0" ixz="0.0" iyy="1.404e-05" iyz="0.0" izz="1.3666666666666664e-05" />
    </inertial>
  </link>

  <joint name="black_joint_61" type="revolute">
    <parent link="base" />
    <child link="black_key_61" />
    <origin xyz="-0.020000000000000004 0.23030769230769232 0.0035000000000000014" rpy="0 0 0" />
    <axis xyz="0 1 0" />
    <limit lower="0" upper="0.07259945373049462" effort="0.3" velocity="6.67" />
  </joint>

  <link name="white_key_62">
    <visual>
      <origin xyz="0.1 0 0" rpy="0 0 0" />
      <geometry>
        <box size="0.14 0.02198076923076923 0.02198076923076923" />
      </geometry>
      <material name="white" />
    </visual>
    <collision>
      <origin xyz="0.1 0 0" rpy="0 0 0" />
      <geometry>
        <box size="0.14 0.02198076923076923 0.02198076923076923" />
      </geometry>
    </collision>
    <inertial>
      <origin xyz="0.1 0 0" rpy="0 0 0" />
      <mass value="0.04" />
      <inertia ixx="3.2210281065088756e-06" ixy="0.0" ixz="0.0" iyy="6.694384738658778e-05" iyz="0.0" izz="6.694384738658778e-05" />
    </inertial>
  </link>

  <joint name="white_joint_62" type="revolute">
    <parent link="base" />
    <child link="white_key_62" />
    <origin xyz="-0.03 0.24129807692307692 -0.010990384615384615" rpy="0 0 0" />
    <axis xyz="0 1 0" />
    <limit lower="0" upper="0.07047134457879563" effort="0.3" velocity="6.67" />
  </joint>

  <link name="white_key_63">
    <visual>
      <origin xyz="0.1 0 0" rpy="0 0 0" />
      <geometry>
        <box size="0.14 0.02198076923076923 0.02198076923076923" />
      </geometry>
      <material name="white" />
    </visual>
    <collision>
      <origin xyz="0.1 0 0" rpy="0 0 0" />
      <geometry>
        <box size="0.14 0.02198076923076923 0.02198076923076923" />
      </geometry>
    </collision>
    <inertial>
      <origin xyz="0.1 0 0" rpy="0 0 0" />
      <mass value="0.04" />
      <inertia ixx="3.2210281065088756e-06" ixy="0.0" ixz="0.0" iyy="6.694384738658778e-05" iyz="0.0" izz="6.694384738658778e-05" />
    </inertial>
  </link>

  <joint name="white_joint_63" type="revolute">
    <parent link="base" />
    <child link="white_key_63" />
    <origin xyz="-0.03 0.2642788461538462 -0.010990384615384615" rpy="0 0 0" />
    <axis xyz="0 1 0" />
    <limit lower="0" upper="0.07047134457879563" effort="0.3" velocity="6.67" />
  </joint>

  <link name="black_key_64">
    <visual>
      <origin xyz="0.065 0 0" rpy="0 0 0" />
      <geometry>
        <box size="0.09 0.01 0.018" />
      </geometry>
      <material name="black" />
    </visual>
    <collision>
      <origin xyz="0.065 0 0" rpy="0 0 0" />
      <geometry>
        <box size="0.09 0.01 0.018" />
      </geometry>
    </collision>
    <inertial>
      <origin xyz="0.065 0 0" rpy="0 0 0" />
      <mass value="0.02" />
      <inertia ixx="7.066666666666665e-07" ixy="0.0" ixz="0.0" iyy="1.404e-05" iyz="0.0" izz="1.3666666666666664e-05" />
    </inertial>
  </link>

  <joint name="black_joint_64" type="revolute">
    <parent link="base" />
    <child link="black_key_64" />
    <origin xyz="-0.020000000000000004 0.2762692307692308 0.0035000000000000014" rpy="0 0 0" />
    <axis xyz="0 1 0" />
    <limit lower="0" upper="0.07259945373049462" effort="0.3" velocity="6.67" />
  </joint>

  <link name="white_key_65">
    <visual>
      <origin xyz="0.1 0 0" rpy="0 0 0" />
      <geometry>
        <box size="0.14 0.02198076923076923 0.02198076923076923" />
      </geometry>
      <material name="white" />
    </visual>
    <collision>
      <origin xyz="0.1 0 0" rpy="0 0 0" />
      <geometry>
        <box size="0.14 0.02198076923076923 0.02198076923076923" />
      </geometry>
    </collision>
    <inertial>
      <origin xyz="0.1 0 0" rpy="0 0 0" />
      <mass value="0.04" />
      <inertia ixx="3.2210281065088756e-06" ixy="0.0" ixz="0.0" iyy="6.694384738658778e-05" iyz="0.0" izz="6.694384738658778e-05" />
    </inertial>
  </link>

  <joint name="white_joint_65" type="revolute">
    <parent link="base" />
    <child link="white_key_65" />
    <origin xyz="-0.03 0.2872596153846154 -0.010990384615384615" rpy="0 0 0" />
    <axis xyz="0 1 0" />
    <limit lower="0" upper="0.07047134457879563" effort="0.3" velocity="6.67" />
  </joint>

  <link name="black_key_66">
    <visual>
      <origin xyz="0.065 0 0" rpy="0 0 0" />
      <geometry>
        <box size="0.09 0.01 0.018" />
      </geometry>
      <material name="black" />
    </visual>
    <collision>
      <origin xyz="0.065 0 0" rpy="0 0 0" />
      <geometry>
        <box size="0.09 0.01 0.018" />
      </geometry>
    </collision>
    <inertial>
      <origin xyz="0.065 0 0" rpy="0 0 0" />
      <mass value="0.02" />
      <inertia ixx="7.066666666666665e-07" ixy="0.0" ixz="0.0" iyy="1.404e-05" iyz="0.0" izz="1.3666666666666664e-05" />
    </inertial>
  </link>

  <joint name="black_joint_66" type="revolute">
    <parent link="base" />
    <child link="black_key_66" />
    <origin xyz="-0.020000000000000004 0.2992500000000001 0.0035000000000000014" rpy="0 0 0" />
    <axis xyz="0 1 0" />
    <limit lower="0" upper="0.07259945373049462" effort="0.3" velocity="6.67" />
  </joint>

  <link name="white_key_67">
    <visual>
      <origin xyz="0.1 0 0" rpy="0 0 0" />
      <geometry>
        <box size="0.14 0.02198076923076923 0.02198076923076923" />
      </geometry>
      <material name="white" />
    </visual>
    <collision>
      <origin xyz="0.1 0 0" rpy="0 0 0" />
      <geometry>
        <box size="0.14 0.02198076923076923 0.02198076923076923" />
      </geometry>
    </collision>
    <inertial>
      <origin xyz="0.1 0 0" rpy="0 0 0" />
      <mass value="0.04" />
      <inertia ixx="3.2210281065088756e-06" ixy="0.0" ixz="0.0" iyy="6.694384738658778e-05" iyz="0.0" izz="6.694384738658778e-05" />
    </inertial>
  </link>

  <joint name="white_joint_67" type="revolute">
    <parent link="base" />
    <child link="white_key_67" />
    <origin xyz="-0.03 0.3102403846153846 -0.010990384615384615" rpy="0 0 0" />
    <axis xyz="0 1 0" />
    <limit lower="0" upper="0.07047134457879563" effort="0.3" velocity="6.67" />
  </joint>

  <link name="white_key_68">
    <visual>
      <origin xyz="0.1 0 0" rpy="0 0 0" />
      <geometry>
        <box size="0.14 0.02198076923076923 0.02198076923076923" />
      </geometry>
      <material name="white" />
    </visual>
    <collision>
      <origin xyz="0.1 0 0" rpy="0 0 0" />
      <geometry>
        <box size="0.14 0.02198076923076923 0.02198076923076923" />
      </geometry>
    </collision>
    <inertial>
      <origin xyz="0.1 0 0" rpy="0 0 0" />
      <mass value="0.04" />
      <inertia ixx="3.2210281065088756e-06" ixy="0.0" ixz="0.0" iyy="6.694384738658778e-05" iyz="0.0" izz="6.694384738658778e-05" />
    </inertial>
  </link>

  <joint name="white_joint_68" type="revolute">
    <parent link="base" />
    <child link="white_key_68" />
    <origin xyz="-0.03 0.3332211538461539 -0.010990384615384615" rpy="0 0 0" />
    <axis xyz="0 1 0" />
    <limit lower="0" upper="0.07047134457879563" effort="0.3" velocity="6.67" />
  </joint>

  <link name="black_key_69">
    <visual>
      <origin xyz="0.065 0 0" rpy="0 0 0" />
      <geometry>
        <box size="0.09 0.01 0.018" />
      </geometry>
      <material name="black" />
    </visual>
    <collision>
      <origin xyz="0.065 0 0" rpy="0 0 0" />
      <geometry>
        <box size="0.09 0.01 0.018" />
      </geometry>
    </collision>
    <inertial>
      <origin xyz="0.065 0 0" rpy="0 0 0" />
      <mass value="0.02" />
      <inertia ixx="7.066666666666665e-07" ixy="0.0" ixz="0.0" iyy="1.404e-05" iyz="0.0" izz="1.3666666666666664e-05" />
    </inertial>
  </link>

  <joint name="black_joint_69" type="revolute">
    <parent link="base" />
    <child link="black_key_69" />
    <origin xyz="-0.020000000000000004 0.3452115384615385 0.0035000000000000014" rpy="0 0 0" />
    <axis xyz="0 1 0" />
    <limit lower="0" upper="0.07259945373049462" effort="0.3" velocity="6.67" />
  </joint>

  <link name="white_key_70">
    <visual>
      <origin xyz="0.1 0 0" rpy="0 0 0" />
      <geometry>
        <box size="0.14 0.02198076923076923 0.02198076923076923" />
      </geometry>
      <material name="white" />
    </visual>
    <collision>
      <origin xyz="0.1 0 0" rpy="0 0 0" />
      <geometry>
        <box size="0.14 0.02198076923076923 0.02198076923076923" />
      </geometry>
    </collision>
    <inertial>
      <origin xyz="0.1 0 0" rpy="0 0 0" />
      <mass value="0.04" />
      <inertia ixx="3.2210281065088756e-06" ixy="0.0" ixz="0.0" iyy="6.694384738658778e-05" iyz="0.0" izz="6.694384738658778e-05" />
    </inertial>
  </link>

  <joint name="white_joint_70" type="revolute">
    <parent link="base" />
    <child link="white_key_70" />
    <origin xyz="-0.03 0.3562019230769231 -0.010990384615384615" rpy="0 0 0" />
    <axis xyz="0 1 0" />
    <limit lower="0" upper="0.07047134457879563" effort="0.3" velocity="6.67" />
  </joint>

  <link name="black_key_71">
    <visual>
      <origin xyz="0.065 0 0" rpy="0 0 0" />
      <geometry>
        <box size="0.09 0.01 0.018" />
      </geometry>
      <material name="black" />
    </visual>
    <collision>
      <origin xyz="0.065 0 0" rpy="0 0 0" />
      <geometry>
        <box size="0.09 0.01 0.018" />
      </geometry>
    </collision>
    <inertial>
      <origin xyz="0.065 0 0" rpy="0 0 0" />
      <mass value="0.02" />
      <inertia ixx="7.066666666666665e-07" ixy="0.0" ixz="0.0" iyy="1.404e-05" iyz="0.0" izz="1.3666666666666664e-05" />
    </inertial>
  </link>

  <joint name="black_joint_71" type="revolute">
    <parent link="base" />
    <child link="black_key_71" />
    <origin xyz="-0.020000000000000004 0.3681923076923078 0.0035000000000000014" rpy="0 0 0" />
    <axis xyz="0 1 0" />
    <limit lower="0" upper="0.07259945373049462" effort="0.3" velocity="6.67" />
  </joint>

  <link name="white_key_72">
    <visual>
      <origin xyz="0.1 0 0" rpy="0 0 0" />
      <geometry>
        <box size="0.14 0.02198076923076923 0.02198076923076923" />
      </geometry>
      <material name="white" />
    </visual>
    <collision>
      <origin xyz="0.1 0 0" rpy="0 0 0" />
      <geometry>
        <box size="0.14 0.02198076923076923 0.02198076923076923" />
      </geometry>
    </collision>
    <inertial>
      <origin xyz="0.1 0 0" rpy="0 0 0" />
      <mass value="0.04" />
      <inertia ixx="3.2210281065088756e-06" ixy="0.0" ixz="0.0" iyy="6.694384738658778e-05" iyz="0.0" izz="6.694384738658778e-05" />
    </inertial>
  </link>

  <joint name="white_joint_72" type="revolute">
    <parent link="base" />
    <child link="white_key_72" />
    <origin xyz="-0.03 0.3791826923076923 -0.010990384615384615" rpy="0 0 0" />
    <axis xyz="0 1 0" />
    <limit lower="0" upper="0.07047134457879563" effort="0.3" velocity="6.67" />
  </joint>

  <link name="black_key_73">
    <visual>
      <origin xyz="0.065 0 0" rpy="0 0 0" />
      <geometry>
        <box size="0.09 0.01 0.018" />
      </geometry>
      <material name="black" />
    </visual>
    <collision>
      <origin xyz="0.065 0 0" rpy="0 0 0" />
      <geometry>
        <box size="0.09 0.01 0.018" />
      </geometry>
    </collision>
    <inertial>
      <origin xyz="0.065 0 0" rpy="0 0 0" />
      <mass value="0.02" />
      <inertia ixx="7.066666666666665e-07" ixy="0.0" ixz="0.0" iyy="1.404e-05" iyz="0.0" izz="1.3666666666666664e-05" />
    </inertial>
  </link>

  <joint name="black_joint_73" type="revolute">
    <parent link="base" />
    <child link="black_key_73" />
    <origin xyz="-0.020000000000000004 0.391173076923077 0.0035000000000000014" rpy="0 0 0" />
    <axis xyz="0 1 0" />
    <limit lower="0" upper="0.07259945373049462" effort="0.3" velocity="6.67" />
  </joint>

  <link name="white_key_74">
    <visual>
      <origin xyz="0.1 0 0" rpy="0 0 0" />
      <geometry>
        <box size="0.14 0.02198076923076923 0.02198076923076923" />
      </geometry>
      <material name="white" />
    </visual>
    <collision>
      <origin xyz="0.1 0 0" rpy="0 0 0" />
      <geometry>
        <box size="0.14 0.02198076923076923 0.02198076923076923" />
      </geometry>
    </collision>
    <inertial>
      <origin xyz="0.1 0 0" rpy="0 0 0" />
      <mass value="0.04" />
      <inertia ixx="3.2210281065088756e-06" ixy="0.0" ixz="0.0" iyy="6.694384738658778e-05" iyz="0.0" izz="6.694384738658778e-05" />
    </inertial>
  </link>

  <joint name="white_joint_74" type="revolute">
    <parent link="base" />
    <child link="white_key_74" />
    <origin xyz="-0.03 0.4021634615384616 -0.010990384615384615" rpy="0 0 0" />
    <axis xyz="0 1 0" />
    <limit lower="0" upper="0.07047134457879563" effort="0.3" velocity="6.67" />
  </joint>

  <link name="white_key_75">
    <visual>
      <origin xyz="0.1 0 0" rpy="0 0 0" />
      <geometry>
        <box size="0.14 0.02198076923076923 0.02198076923076923" />
      </geometry>
      <material name="white" />
    </visual>
    <collision>
      <origin xyz="0.1 0 0" rpy="0 0 0" />
      <geometry>
        <box size="0.14 0.02198076923076923 0.02198076923076923" />
      </geometry>
    </collision>
    <inertial>
      <origin xyz="0.1 0 0" rpy="0 0 0" />
      <mass value="0.04" />
      <inertia ixx="3.2210281065088756e-06" ixy="0.0" ixz="0.0" iyy="6.694384738658778e-05" iyz="0.0" izz="6.694384738658778e-05" />
    </inertial>
  </link>

  <joint name="white_joint_75" type="revolute">
    <parent link="base" />
    <child link="white_key_75" />
    <origin xyz="-0.03 0.4251442307692309 -0.010990384615384615" rpy="0 0 0" />
    <axis xyz="0 1 0" />
    <limit lower="0" upper="0.07047134457879563" effort="0.3" velocity="6.67" />
  </joint>

  <link name="black_key_76">
    <visual>
      <origin xyz="0.065 0 0" rpy="0 0 0" />
      <geometry>
        <box size="0.09 0.01 0.018" />
      </geometry>
      <material name="black" />
    </visual>
    <collision>
      <origin xyz="0.065 0 0" rpy="0 0 0" />
      <geometry>
        <box size="0.09 0.01 0.018" />
      </geometry>
    </collision>
    <inertial>
      <origin xyz="0.065 0 0" rpy="0 0 0" />
      <mass value="0.02" />
      <inertia ixx="7.066666666666665e-07" ixy="0.0" ixz="0.0" iyy="1.404e-05" iyz="0.0" izz="1.3666666666666664e-05" />
    </inertial>
  </link>

  <joint name="black_joint_76" type="revolute">
    <parent link="base" />
    <child link="black_key_76" />
    <origin xyz="-0.020000000000000004 0.4371346153846155 0.0035000000000000014" rpy="0 0 0" />
    <axis xyz="0 1 0" />
    <limit lower="0" upper="0.07259945373049462" effort="0.3" velocity="6.67" />
  </joint>

  <link name="white_key_77">
    <visual>
      <origin xyz="0.1 0 0" rpy="0 0 0" />
      <geometry>
        <box size="0.14 0.02198076923076923 0.02198076923076923" />
      </geometry>
      <material name="white" />
    </visual>
    <collision>
      <origin xyz="0.1 0 0" rpy="0 0 0" />
      <geometry>
        <box size="0.14 0.02198076923076923 0.02198076923076923" />
      </geometry>
    </collision>
    <inertial>
      <origin xyz="0.1 0 0" rpy="0 0 0" />
      <mass value="0.04" />
      <inertia ixx="3.2210281065088756e-06" ixy="0.0" ixz="0.0" iyy="6.694384738658778e-05" iyz="0.0" izz="6.694384738658778e-05" />
    </inertial>
  </link>

  <joint name="white_joint_77" type="revolute">
    <parent link="base" />
    <child link="white_key_77" />
    <origin xyz="-0.03 0.448125 -0.010990384615384615" rpy="0 0 0" />
    <axis xyz="0 1 0" />
    <limit lower="0" upper="0.07047134457879563" effort="0.3" velocity="6.67" />
  </joint>

  <link name="black_key_78">
    <visual>
      <origin xyz="0.065 0 0" rpy="0 0 0" />
      <geometry>
        <box size="0.09 0.01 0.018" />
      </geometry>
      <material name="black" />
    </visual>
    <collision>
      <origin xyz="0.065 0 0" rpy="0 0 0" />
      <geometry>
        <box size="0.09 0.01 0.018" />
      </geometry>
    </collision>
    <inertial>
      <origin xyz="0.065 0 0" rpy="0 0 0" />
      <mass value="0.02" />
      <inertia ixx="7.066666666666665e-07" ixy="0.0" ixz="0.0" iyy="1.404e-05" iyz="0.0" izz="1.3666666666666664e-05" />
    </inertial>
  </link>

  <joint name="black_joint_78" type="revolute">
    <parent link="base" />
    <child link="black_key_78" />
    <origin xyz="-0.020000000000000004 0.4601153846153848 0.0035000000000000014" rpy="0 0 0" />
    <axis xyz="0 1 0" />
    <limit lower="0" upper="0.07259945373049462" effort="0.3" velocity="6.67" />
  </joint>

  <link name="white_key_79">
    <visual>
      <origin xyz="0.1 0 0" rpy="0 0 0" />
      <geometry>
        <box size="0.14 0.02198076923076923 0.02198076923076923" />
      </geometry>
      <material name="white" />
    </visual>
    <collision>
      <origin xyz="0.1 0 0" rpy="0 0 0" />
      <geometry>
        <box size="0.14 0.02198076923076923 0.02198076923076923" />
      </geometry>
    </collision>
    <inertial>
      <origin xyz="0.1 0 0" rpy="0 0 0" />
      <mass value="0.04" />
      <inertia ixx="3.2210281065088756e-06" ixy="0.0" ixz="0.0" iyy="6.694384738658778e-05" iyz="0.0" izz="6.694384738658778e-05" />
    </inertial>
  </link>

  <joint name="white_joint_79" type="revolute">
    <parent link="base" />
    <child link="white_key_79" />
    <origin xyz="-0.03 0.4711057692307693 -0.010990384615384615" rpy="0 0 0" />
    <axis xyz="0 1 0" />
    <limit lower="0" upper="0.07047134457879563" effort="0.3" velocity="6.67" />
  </joint>

  <link name="white_key_80">
    <visual>
      <origin xyz="0.1 0 0" rpy="0 0 0" />
      <geometry>
        <box size="0.14 0.02198076923076923 0.02198076923076923" />
      </geometry>
      <material name="white" />
    </visual>
    <collision>
      <origin xyz="0.1 0 0" rpy="0 0 0" />
      <geometry>
        <box size="0.14 0.02198076923076923 0.02198076923076923" />
      </geometry>
    </collision>
    <inertial>
      <origin xyz="0.1 0 0" rpy="0 0 0" />
      <mass value="0.04" />
      <inertia ixx="3.2210281065088756e-06" ixy="0.0" ixz="0.0" iyy="6.694384738658778e-05" iyz="0.0" izz="6.694384738658778e-05" />
    </inertial>
  </link>

  <joint name="white_joint_80" type="revolute">
    <parent link="base" />
    <child link="white_key_80" />
    <origin xyz="-0.03 0.4940865384615386 -0.010990384615384615" rpy="0 0 0" />
    <axis xyz="0 1 0" />
    <limit lower="0" upper="0.07047134457879563" effort="0.3" velocity="6.67" />
  </joint>

  <link name="black_key_81">
    <visual>
      <origin xyz="0.065 0 0" rpy="0 0 0" />
      <geometry>
        <box size="0.09 0.01 0.018" />
      </geometry>
      <material name="black" />
    </visual>
    <collision>
      <origin xyz="0.065 0 0" rpy="0 0 0" />
      <geometry>
        <box size="0.09 0.01 0.018" />
      </geometry>
    </collision>
    <inertial>
      <origin xyz="0.065 0 0" rpy="0 0 0" />
      <mass value="0.02" />
      <inertia ixx="7.066666666666665e-07" ixy="0.0" ixz="0.0" iyy="1.404e-05" iyz="0.0" izz="1.3666666666666664e-05" />
    </inertial>
  </link>

  <joint name="black_joint_81" type="revolute">
    <parent link="base" />
    <child link="black_key_81" />
    <origin xyz="-0.020000000000000004 0.5060769230769232 0.0035000000000000014" rpy="0 0 0" />
    <axis xyz="0 1 0" />
    <limit lower="0" upper="0.07259945373049462" effort="0.3" velocity="6.67" />
  </joint>

  <link name="white_key_82">
    <visual>
      <origin xyz="0.1 0 0" rpy="0 0 0" />
      <geometry>
        <box size="0.14 0.02198076923076923 0.02198076923076923" />
      </geometry>
      <material name="white" />
    </visual>
    <collision>
      <origin xyz="0.1 0 0" rpy="0 0 0" />
      <geometry>
        <box size="0.14 0.02198076923076923 0.02198076923076923" />
      </geometry>
    </collision>
    <inertial>
      <origin xyz="0.1 0 0" rpy="0 0 0" />
      <mass value="0.04" />
      <inertia ixx="3.2210281065088756e-06" ixy="0.0" ixz="0.0" iyy="6.694384738658778e-05" iyz="0.0" izz="6.694384738658778e-05" />
    </inertial>
  </link>

  <joint name="white_joint_82" type="revolute">
    <parent link="base" />
    <child link="white_key_82" />
    <origin xyz="-0.03 0.5170673076923077 -0.010990384615384615" rpy="0 0 0" />
    <axis xyz="0 1 0" />
    <limit lower="0" upper="0.07047134457879563" effort="0.3" velocity="6.67" />
  </joint>

  <link name="black_key_83">
    <visual>
      <origin xyz="0.065 0 0" rpy="0 0 0" />
      <geometry>
        <box size="0.09 0.01 0.018" />
      </geometry>
      <material name="black" />
    </visual>
    <collision>
      <origin xyz="0.065 0 0" rpy="0 0 0" />
      <geometry>
        <box size="0.09 0.01 0.018" />
      </geometry>
    </collision>
    <inertial>
      <origin xyz="0.065 0 0" rpy="0 0 0" />
      <mass value="0.02" />
      <inertia ixx="7.066666666666665e-07" ixy="0.0" ixz="0.0" iyy="1.404e-05" iyz="0.0" izz="1.3666666666666664e-05" />
    </inertial>
  </link>

  <joint name="black_joint_83" type="revolute">
    <parent link="base" />
    <child link="black_key_83" />
    <origin xyz="-0.020000000000000004 0.5290576923076925 0.0035000000000000014" rpy="0 0 0" />
    <axis xyz="0 1 0" />
    <limit lower="0" upper="0.07259945373049462" effort="0.3" velocity="6.67" />
  </joint>

  <link name="white_key_84">
    <visual>
      <origin xyz="0.1 0 0" rpy="0 0 0" />
      <geometry>
        <box size="0.14 0.02198076923076923 0.02198076923076923" />
      </geometry>
      <material name="white" />
    </visual>
    <collision>
      <origin xyz="0.1 0 0" rpy="0 0 0" />
      <geometry>
        <box size="0.14 0.02198076923076923 0.02198076923076923" />
      </geometry>
    </collision>
    <inertial>
      <origin xyz="0.1 0 0" rpy="0 0 0" />
      <mass value="0.04" />
      <inertia ixx="3.2210281065088756e-06" ixy="0.0" ixz="0.0" iyy="6.694384738658778e-05" iyz="0.0" izz="6.694384738658778e-05" />
    </inertial>
  </link>

  <joint name="white_joint_84" type="revolute">
    <parent link="base" />
    <child link="white_key_84" />
    <origin xyz="-0.03 0.540048076923077 -0.010990384615384615" rpy="0 0 0" />
    <axis xyz="0 1 0" />
    <limit lower="0" upper="0.07047134457879563" effort="0.3" velocity="6.67" />
  </joint>

  <link name="black_key_85">
    <visual>
      <origin xyz="0.065 0 0" rpy="0 0 0" />
      <geometry>
        <box size="0.09 0.01 0.018" />
      </geometry>
      <material name="black" />
    </visual>
    <collision>
      <origin xyz="0.065 0 0" rpy="0 0 0" />
      <geometry>
        <box size="0.09 0.01 0.018" />
      </geometry>
    </collision>
    <inertial>
      <origin xyz="0.065 0 0" rpy="0 0 0" />
      <mass value="0.02" />
      <inertia ixx="7.066666666666665e-07" ixy="0.0" ixz="0.0" iyy="1.404e-05" iyz="0.0" izz="1.3666666666666664e-05" />
    </inertial>
  </link>

  <joint name="black_joint_85" type="revolute">
    <parent link="base" />
    <child link="black_key_85" />
    <origin xyz="-0.020000000000000004 0.5520384615384617 0.0035000000000000014" rpy="0 0 0" />
    <axis xyz="0 1 0" />
    <limit lower="0" upper="0.07259945373049462" effort="0.3" velocity="6.67" />
  </joint>

  <link name="white_key_86">
    <visual>
      <origin xyz="0.1 0 0" rpy="0 0 0" />
      <geometry>
        <box size="0.14 0.02198076923076923 0.02198076923076923" />
      </geometry>
      <material name="white" />
    </visual>
    <collision>
      <origin xyz="0.1 0 0" rpy="0 0 0" />
      <geometry>
        <box size="0.14 0.02198076923076923 0.02198076923076923" />
      </geometry>
    </collision>
    <inertial>
      <origin xyz="0.1 0 0" rpy="0 0 0" />
      <mass value="0.04" />
      <inertia ixx="3.2210281065088756e-06" ixy="0.0" ixz="0.0" iyy="6.694384738658778e-05" iyz="0.0" izz="6.694384738658778e-05" />
    </inertial>
  </link>

  <joint name="white_joint_86" type="revolute">
    <parent link="base" />
    <child link="white_key_86" />
    <origin xyz="-0.03 0.5630288461538463 -0.010990384615384615" rpy="0 0 0" />
    <axis xyz="0 1 0" />
    <limit lower="0" upper="0.07047134457879563" effort="0.3" velocity="6.67" />
  </joint>

  <link name="white_key_87">
    <visual>
      <origin xyz="0.1 0 0" rpy="0 0 0" />
      <geometry>
        <box size="0.14 0.02198076923076923 0.02198076923076923" />
      </geometry>
      <material name="white" />
    </visual>
    <collision>
      <origin xyz="0.1 0 0" rpy="0 0 0" />
      <geometry>
        <box size="0.14 0.02198076923076923 0.02198076923076923" />
      </geometry>
    </collision>
    <inertial>
      <origin xyz="0.1 0 0" rpy="0 0 0" />
      <mass value="0.04" />
      <inertia ixx="3.2210281065088756e-06" ixy="0.0" ixz="0.0" iyy="6.694384738658778e-05" iyz="0.0" izz="6.694384738658778e-05" />
    </inertial>
  </link>

  <joint name="white_joint_87" type="revolute">
    <parent link="base" />
    <child link="white_key_87" />
    <origin xyz="-0.03 0.5860096153846154 -0.010990384615384615" rpy="0 0 0" />
    <axis xyz="0 1 0" />
    <limit lower="0" upper="0.07047134457879563" effort="0.3" velocity="6.67" />
  </joint>

</robot>