<mujoco model="piano">
  <compiler autolimits="true" angle="radian"/>
  <default>
    <default class="/">
      <joint type="hinge" axis="0 1 0"/>
      <geom type="box" contype="0" conaffinity="1"/>
      <site type="box" group="4" rgba="1 0 0 1"/>
      <default class="white_key">
        <joint pos="-0.115 0 0" stiffness="4" range="0 0.063074117896912252" springref="-0.00017453292519943296" armature="0.001" damping="0.050000000000000003"/>
        <geom size="0.074999999999999997 0.010999999999999999 0.010999999999999999" material="white" mass="0.040000000000000001"/>
        <site size="0.074999999999999997 0.010999999999999999 0.010999999999999999"/>
      </default>
      <default class="black_key">
        <joint pos="-0.074999999999999997 0 0" stiffness="4" range="0 0.066568163775823808" springref="-0.00017453292519943296" armature="0.001" damping="0.050000000000000003"/>
        <geom size="0.044999999999999998 0.0050000000000000001 0.0089999999999999993" material="black" mass="0.02"/>
        <site size="0.044999999999999998 0.0050000000000000001 0.0089999999999999993"/>
      </default>
    </default>
  </default>
  <asset>
    <material name="white" class="/" rgba="0.90000000000000002 0.90000000000000002 0.90000000000000002 1"/>
    <material name="black" class="/" rgba="0.10000000000000001 0.10000000000000001 0.10000000000000001 1"/>
  </asset>
  <worldbody>
    <body name="piano">
      <body name="base">
        <geom name="base_1" class="/" type="box" size="0.059999999999999998 0.66000000000000003 0.089999999999999997" rgba="0.14999999999999999 0.14999999999999999 0.14999999999999999 1" pos="-0.059999999999999998 0 0.089999999999999997"/>
        <geom name="base_2" class="/" type="box" size="0.14749999999999999 0.66000000000000003 0.059000000000000011" rgba="0.14999999999999999 0.14999999999999999 0.14999999999999999 1" pos="0.027499999999999997 0 0.059000000000000011"/>
      </body>
      <body name="white_key_0" pos="0.074999999999999997 -0.58649999999999991 0.129">
        <geom name="white_key_geom_0" class="white_key"/>
        <joint name="white_joint_0" class="white_key"/>
        <site name="white_key_site_0" class="white_key"/>
      </body>
      <body name="black_key_1" pos="0.044999999999999998 -0.57499999999999996 0.14350000000000002">
        <geom name="black_key_geom_1" class="black_key"/>
        <joint name="black_joint_1" class="black_key"/>
        <site name="black_key_site_1" class="black_key"/>
      </body>
      <body name="white_key_2" pos="0.074999999999999997 -0.56349999999999989 0.129">
        <geom name="white_key_geom_2" class="white_key"/>
        <joint name="white_joint_2" class="white_key"/>
        <site name="white_key_site_2" class="white_key"/>
      </body>
      <body name="white_key_3" pos="0.074999999999999997 -0.54049999999999987 0.129">
        <geom name="white_key_geom_3" class="white_key"/>
        <joint name="white_joint_3" class="white_key"/>
        <site name="white_key_site_3" class="white_key"/>
      </body>
      <body name="black_key_4" pos="0.044999999999999998 -0.52849999999999986 0.14350000000000002">
        <geom name="black_key_geom_4" class="black_key"/>
        <joint name="black_joint_4" class="black_key"/>
        <site name="black_key_site_4" class="black_key"/>
      </body>
      <body name="white_key_5" pos="0.074999999999999997 -0.51749999999999985 0.129">
        <geom name="white_key_geom_5" class="white_key"/>
        <joint name="white_joint_5" class="white_key"/>
        <site name="white_key_site_5" class="white_key"/>
      </body>
      <body name="black_key_6" pos="0.044999999999999998 -0.50549999999999984 0.14350000000000002">
        <geom name="black_key_geom_6" class="black_key"/>
        <joint name="black_joint_6" class="black_key"/>
        <site name="black_key_site_6" class="black_key"/>
      </body>
      <body name="white_key_7" pos="0.074999999999999997 -0.49449999999999994 0.129">
        <geom name="white_key_geom_7" class="white_key"/>
        <joint name="white_joint_7" class="white_key"/>
        <site name="white_key_site_7" class="white_key"/>
      </body>
      <body name="white_key_8" pos="0.074999999999999997 -0.47149999999999992 0.129">
        <geom name="white_key_geom_8" class="white_key"/>
        <joint name="white_joint_8" class="white_key"/>
        <site name="white_key_site_8" class="white_key"/>
      </body>
      <body name="black_key_9" pos="0.044999999999999998 -0.45949999999999991 0.14350000000000002">
        <geom name="black_key_geom_9" class="black_key"/>
        <joint name="black_joint_9" class="black_key"/>
        <site name="black_key_site_9" class="black_key"/>
      </body>
      <body name="white_key_10" pos="0.074999999999999997 -0.4484999999999999 0.129">
        <geom name="white_key_geom_10" class="white_key"/>
        <joint name="white_joint_10" class="white_key"/>
        <site name="white_key_site_10" class="white_key"/>
      </body>
      <body name="black_key_11" pos="0.044999999999999998 -0.43649999999999989 0.14350000000000002">
        <geom name="black_key_geom_11" class="black_key"/>
        <joint name="black_joint_11" class="black_key"/>
        <site name="black_key_site_11" class="black_key"/>
      </body>
      <body name="white_key_12" pos="0.074999999999999997 -0.42549999999999988 0.129">
        <geom name="white_key_geom_12" class="white_key"/>
        <joint name="white_joint_12" class="white_key"/>
        <site name="white_key_site_12" class="white_key"/>
      </body>
      <body name="black_key_13" pos="0.044999999999999998 -0.41349999999999998 0.14350000000000002">
        <geom name="black_key_geom_13" class="black_key"/>
        <joint name="black_joint_13" class="black_key"/>
        <site name="black_key_site_13" class="black_key"/>
      </body>
      <body name="white_key_14" pos="0.074999999999999997 -0.40249999999999991 0.129">
        <geom name="white_key_geom_14" class="white_key"/>
        <joint name="white_joint_14" class="white_key"/>
        <site name="white_key_site_14" class="white_key"/>
      </body>
      <body name="white_key_15" pos="0.074999999999999997 -0.37949999999999995 0.129">
        <geom name="white_key_geom_15" class="white_key"/>
        <joint name="white_joint_15" class="white_key"/>
        <site name="white_key_site_15" class="white_key"/>
      </body>
      <body name="black_key_16" pos="0.044999999999999998 -0.36749999999999994 0.14350000000000002">
        <geom name="black_key_geom_16" class="black_key"/>
        <joint name="black_joint_16" class="black_key"/>
        <site name="black_key_site_16" class="black_key"/>
      </body>
      <body name="white_key_17" pos="0.074999999999999997 -0.35649999999999993 0.129">
        <geom name="white_key_geom_17" class="white_key"/>
        <joint name="white_joint_17" class="white_key"/>
        <site name="white_key_site_17" class="white_key"/>
      </body>
      <body name="black_key_18" pos="0.044999999999999998 -0.34449999999999992 0.14350000000000002">
        <geom name="black_key_geom_18" class="black_key"/>
        <joint name="black_joint_18" class="black_key"/>
        <site name="black_key_site_18" class="black_key"/>
      </body>
      <body name="white_key_19" pos="0.074999999999999997 -0.33349999999999991 0.129">
        <geom name="white_key_geom_19" class="white_key"/>
        <joint name="white_joint_19" class="white_key"/>
        <site name="white_key_site_19" class="white_key"/>
      </body>
      <body name="white_key_20" pos="0.074999999999999997 -0.31049999999999989 0.129">
        <geom name="white_key_geom_20" class="white_key"/>
        <joint name="white_joint_20" class="white_key"/>
        <site name="white_key_site_20" class="white_key"/>
      </body>
      <body name="black_key_21" pos="0.044999999999999998 -0.29849999999999988 0.14350000000000002">
        <geom name="black_key_geom_21" class="black_key"/>
        <joint name="black_joint_21" class="black_key"/>
        <site name="black_key_site_21" class="black_key"/>
      </body>
      <body name="white_key_22" pos="0.074999999999999997 -0.28749999999999992 0.129">
        <geom name="white_key_geom_22" class="white_key"/>
        <joint name="white_joint_22" class="white_key"/>
        <site name="white_key_site_22" class="white_key"/>
      </body>
      <body name="black_key_23" pos="0.044999999999999998 -0.27549999999999986 0.14350000000000002">
        <geom name="black_key_geom_23" class="black_key"/>
        <joint name="black_joint_23" class="black_key"/>
        <site name="black_key_site_23" class="black_key"/>
      </body>
      <body name="white_key_24" pos="0.074999999999999997 -0.2644999999999999 0.129">
        <geom name="white_key_geom_24" class="white_key"/>
        <joint name="white_joint_24" class="white_key"/>
        <site name="white_key_site_24" class="white_key"/>
      </body>
      <body name="black_key_25" pos="0.044999999999999998 -0.25249999999999995 0.14350000000000002">
        <geom name="black_key_geom_25" class="black_key"/>
        <joint name="black_joint_25" class="black_key"/>
        <site name="black_key_site_25" class="black_key"/>
      </body>
      <body name="white_key_26" pos="0.074999999999999997 -0.24149999999999994 0.129">
        <geom name="white_key_geom_26" class="white_key"/>
        <joint name="white_joint_26" class="white_key"/>
        <site name="white_key_site_26" class="white_key"/>
      </body>
      <body name="white_key_27" pos="0.074999999999999997 -0.21849999999999992 0.129">
        <geom name="white_key_geom_27" class="white_key"/>
        <joint name="white_joint_27" class="white_key"/>
        <site name="white_key_site_27" class="white_key"/>
      </body>
      <body name="black_key_28" pos="0.044999999999999998 -0.20649999999999991 0.14350000000000002">
        <geom name="black_key_geom_28" class="black_key"/>
        <joint name="black_joint_28" class="black_key"/>
        <site name="black_key_site_28" class="black_key"/>
      </body>
      <body name="white_key_29" pos="0.074999999999999997 -0.1954999999999999 0.129">
        <geom name="white_key_geom_29" class="white_key"/>
        <joint name="white_joint_29" class="white_key"/>
        <site name="white_key_site_29" class="white_key"/>
      </body>
      <body name="black_key_30" pos="0.044999999999999998 -0.18349999999999989 0.14350000000000002">
        <geom name="black_key_geom_30" class="black_key"/>
        <joint name="black_joint_30" class="black_key"/>
        <site name="black_key_site_30" class="black_key"/>
      </body>
      <body name="white_key_31" pos="0.074999999999999997 -0.17249999999999993 0.129">
        <geom name="white_key_geom_31" class="white_key"/>
        <joint name="white_joint_31" class="white_key"/>
        <site name="white_key_site_31" class="white_key"/>
      </body>
      <body name="white_key_32" pos="0.074999999999999997 -0.14949999999999991 0.129">
        <geom name="white_key_geom_32" class="white_key"/>
        <joint name="white_joint_32" class="white_key"/>
        <site name="white_key_site_32" class="white_key"/>
      </body>
      <body name="black_key_33" pos="0.044999999999999998 -0.1374999999999999 0.14350000000000002">
        <geom name="black_key_geom_33" class="black_key"/>
        <joint name="black_joint_33" class="black_key"/>
        <site name="black_key_site_33" class="black_key"/>
      </body>
      <body name="white_key_34" pos="0.074999999999999997 -0.12649999999999995 0.129">
        <geom name="white_key_geom_34" class="white_key"/>
        <joint name="white_joint_34" class="white_key"/>
        <site name="white_key_site_34" class="white_key"/>
      </body>
      <body name="black_key_35" pos="0.044999999999999998 -0.11449999999999988 0.14350000000000002">
        <geom name="black_key_geom_35" class="black_key"/>
        <joint name="black_joint_35" class="black_key"/>
        <site name="black_key_site_35" class="black_key"/>
      </body>
      <body name="white_key_36" pos="0.074999999999999997 -0.10349999999999993 0.129">
        <geom name="white_key_geom_36" class="white_key"/>
        <joint name="white_joint_36" class="white_key"/>
        <site name="white_key_site_36" class="white_key"/>
      </body>
      <body name="black_key_37" pos="0.044999999999999998 -0.09149999999999997 0.14350000000000002">
        <geom name="black_key_geom_37" class="black_key"/>
        <joint name="black_joint_37" class="black_key"/>
        <site name="black_key_site_37" class="black_key"/>
      </body>
      <body name="white_key_38" pos="0.074999999999999997 -0.080499999999999905 0.129">
        <geom name="white_key_geom_38" class="white_key"/>
        <joint name="white_joint_38" class="white_key"/>
        <site name="white_key_site_38" class="white_key"/>
      </body>
      <body name="white_key_39" pos="0.074999999999999997 -0.057499999999999885 0.129">
        <geom name="white_key_geom_39" class="white_key"/>
        <joint name="white_joint_39" class="white_key"/>
        <site name="white_key_site_39" class="white_key"/>
      </body>
      <body name="black_key_40" pos="0.044999999999999998 -0.045499999999999874 0.14350000000000002">
        <geom name="black_key_geom_40" class="black_key"/>
        <joint name="black_joint_40" class="black_key"/>
        <site name="black_key_site_40" class="black_key"/>
      </body>
      <body name="white_key_41" pos="0.074999999999999997 -0.034499999999999864 0.129">
        <geom name="white_key_geom_41" class="white_key"/>
        <joint name="white_joint_41" class="white_key"/>
        <site name="white_key_site_41" class="white_key"/>
      </body>
      <body name="black_key_42" pos="0.044999999999999998 -0.022499999999999853 0.14350000000000002">
        <geom name="black_key_geom_42" class="black_key"/>
        <joint name="black_joint_42" class="black_key"/>
        <site name="black_key_site_42" class="black_key"/>
      </body>
      <body name="white_key_43" pos="0.074999999999999997 -0.011499999999999955 0.129">
        <geom name="white_key_geom_43" class="white_key"/>
        <joint name="white_joint_43" class="white_key"/>
        <site name="white_key_site_43" class="white_key"/>
      </body>
      <body name="white_key_44" pos="0.074999999999999997 0.011500000000000066 0.129">
        <geom name="white_key_geom_44" class="white_key"/>
        <joint name="white_joint_44" class="white_key"/>
        <site name="white_key_site_44" class="white_key"/>
      </body>
      <body name="black_key_45" pos="0.044999999999999998 0.023500000000000076 0.14350000000000002">
        <geom name="black_key_geom_45" class="black_key"/>
        <joint name="black_joint_45" class="black_key"/>
        <site name="black_key_site_45" class="black_key"/>
      </body>
      <body name="white_key_46" pos="0.074999999999999997 0.034500000000000086 0.129">
        <geom name="white_key_geom_46" class="white_key"/>
        <joint name="white_joint_46" class="white_key"/>
        <site name="white_key_site_46" class="white_key"/>
      </body>
      <body name="black_key_47" pos="0.044999999999999998 0.046500000000000097 0.14350000000000002">
        <geom name="black_key_geom_47" class="black_key"/>
        <joint name="black_joint_47" class="black_key"/>
        <site name="black_key_site_47" class="black_key"/>
      </body>
      <body name="white_key_48" pos="0.074999999999999997 0.057500000000000107 0.129">
        <geom name="white_key_geom_48" class="white_key"/>
        <joint name="white_joint_48" class="white_key"/>
        <site name="white_key_site_48" class="white_key"/>
      </body>
      <body name="black_key_49" pos="0.044999999999999998 0.069500000000000006 0.14350000000000002">
        <geom name="black_key_geom_49" class="black_key"/>
        <joint name="black_joint_49" class="black_key"/>
        <site name="black_key_site_49" class="black_key"/>
      </body>
      <body name="white_key_50" pos="0.074999999999999997 0.080500000000000127 0.129">
        <geom name="white_key_geom_50" class="white_key"/>
        <joint name="white_joint_50" class="white_key"/>
        <site name="white_key_site_50" class="white_key"/>
      </body>
      <body name="white_key_51" pos="0.074999999999999997 0.10350000000000004 0.129">
        <geom name="white_key_geom_51" class="white_key"/>
        <joint name="white_joint_51" class="white_key"/>
        <site name="white_key_site_51" class="white_key"/>
      </body>
      <body name="black_key_52" pos="0.044999999999999998 0.11550000000000005 0.14350000000000002">
        <geom name="black_key_geom_52" class="black_key"/>
        <joint name="black_joint_52" class="black_key"/>
        <site name="black_key_site_52" class="black_key"/>
      </body>
      <body name="white_key_53" pos="0.074999999999999997 0.12650000000000006 0.129">
        <geom name="white_key_geom_53" class="white_key"/>
        <joint name="white_joint_53" class="white_key"/>
        <site name="white_key_site_53" class="white_key"/>
      </body>
      <body name="black_key_54" pos="0.044999999999999998 0.13850000000000007 0.14350000000000002">
        <geom name="black_key_geom_54" class="black_key"/>
        <joint name="black_joint_54" class="black_key"/>
        <site name="black_key_site_54" class="black_key"/>
      </body>
      <body name="white_key_55" pos="0.074999999999999997 0.14950000000000008 0.129">
        <geom name="white_key_geom_55" class="white_key"/>
        <joint name="white_joint_55" class="white_key"/>
        <site name="white_key_site_55" class="white_key"/>
      </body>
      <body name="white_key_56" pos="0.074999999999999997 0.1725000000000001 0.129">
        <geom name="white_key_geom_56" class="white_key"/>
        <joint name="white_joint_56" class="white_key"/>
        <site name="white_key_site_56" class="white_key"/>
      </body>
      <body name="black_key_57" pos="0.044999999999999998 0.18450000000000011 0.14350000000000002">
        <geom name="black_key_geom_57" class="black_key"/>
        <joint name="black_joint_57" class="black_key"/>
        <site name="black_key_site_57" class="black_key"/>
      </body>
      <body name="white_key_58" pos="0.074999999999999997 0.19550000000000012 0.129">
        <geom name="white_key_geom_58" class="white_key"/>
        <joint name="white_joint_58" class="white_key"/>
        <site name="white_key_site_58" class="white_key"/>
      </body>
      <body name="black_key_59" pos="0.044999999999999998 0.20750000000000013 0.14350000000000002">
        <geom name="black_key_geom_59" class="black_key"/>
        <joint name="black_joint_59" class="black_key"/>
        <site name="black_key_site_59" class="black_key"/>
      </body>
      <body name="white_key_60" pos="0.074999999999999997 0.21850000000000003 0.129">
        <geom name="white_key_geom_60" class="white_key"/>
        <joint name="white_joint_60" class="white_key"/>
        <site name="white_key_site_60" class="white_key"/>
      </body>
      <body name="black_key_61" pos="0.044999999999999998 0.23050000000000004 0.14350000000000002">
        <geom name="black_key_geom_61" class="black_key"/>
        <joint name="black_joint_61" class="black_key"/>
        <site name="black_key_site_61" class="black_key"/>
      </body>
      <body name="white_key_62" pos="0.074999999999999997 0.24150000000000005 0.129">
        <geom name="white_key_geom_62" class="white_key"/>
        <joint name="white_joint_62" class="white_key"/>
        <site name="white_key_site_62" class="white_key"/>
      </body>
      <body name="white_key_63" pos="0.074999999999999997 0.26450000000000007 0.129">
        <geom name="white_key_geom_63" class="white_key"/>
        <joint name="white_joint_63" class="white_key"/>
        <site name="white_key_site_63" class="white_key"/>
      </body>
      <body name="black_key_64" pos="0.044999999999999998 0.27650000000000008 0.14350000000000002">
        <geom name="black_key_geom_64" class="black_key"/>
        <joint name="black_joint_64" class="black_key"/>
        <site name="black_key_site_64" class="black_key"/>
      </body>
      <body name="white_key_65" pos="0.074999999999999997 0.28750000000000009 0.129">
        <geom name="white_key_geom_65" class="white_key"/>
        <joint name="white_joint_65" class="white_key"/>
        <site name="white_key_site_65" class="white_key"/>
      </body>
      <body name="black_key_66" pos="0.044999999999999998 0.2995000000000001 0.14350000000000002">
        <geom name="black_key_geom_66" class="black_key"/>
        <joint name="black_joint_66" class="black_key"/>
        <site name="black_key_site_66" class="black_key"/>
      </body>
      <body name="white_key_67" pos="0.074999999999999997 0.31050000000000011 0.129">
        <geom name="white_key_geom_67" class="white_key"/>
        <joint name="white_joint_67" class="white_key"/>
        <site name="white_key_site_67" class="white_key"/>
      </body>
      <body name="white_key_68" pos="0.074999999999999997 0.33350000000000002 0.129">
        <geom name="white_key_geom_68" class="white_key"/>
        <joint name="white_joint_68" class="white_key"/>
        <site name="white_key_site_68" class="white_key"/>
      </body>
      <body name="black_key_69" pos="0.044999999999999998 0.34550000000000003 0.14350000000000002">
        <geom name="black_key_geom_69" class="black_key"/>
        <joint name="black_joint_69" class="black_key"/>
        <site name="black_key_site_69" class="black_key"/>
      </body>
      <body name="white_key_70" pos="0.074999999999999997 0.35650000000000004 0.129">
        <geom name="white_key_geom_70" class="white_key"/>
        <joint name="white_joint_70" class="white_key"/>
        <site name="white_key_site_70" class="white_key"/>
      </body>
      <body name="black_key_71" pos="0.044999999999999998 0.36850000000000005 0.14350000000000002">
        <geom name="black_key_geom_71" class="black_key"/>
        <joint name="black_joint_71" class="black_key"/>
        <site name="black_key_site_71" class="black_key"/>
      </body>
      <body name="white_key_72" pos="0.074999999999999997 0.37950000000000006 0.129">
        <geom name="white_key_geom_72" class="white_key"/>
        <joint name="white_joint_72" class="white_key"/>
        <site name="white_key_site_72" class="white_key"/>
      </body>
      <body name="black_key_73" pos="0.044999999999999998 0.39149999999999996 0.14350000000000002">
        <geom name="black_key_geom_73" class="black_key"/>
        <joint name="black_joint_73" class="black_key"/>
        <site name="black_key_site_73" class="black_key"/>
      </body>
      <body name="white_key_74" pos="0.074999999999999997 0.40250000000000008 0.129">
        <geom name="white_key_geom_74" class="white_key"/>
        <joint name="white_joint_74" class="white_key"/>
        <site name="white_key_site_74" class="white_key"/>
      </body>
      <body name="white_key_75" pos="0.074999999999999997 0.4255000000000001 0.129">
        <geom name="white_key_geom_75" class="white_key"/>
        <joint name="white_joint_75" class="white_key"/>
        <site name="white_key_site_75" class="white_key"/>
      </body>
      <body name="black_key_76" pos="0.044999999999999998 0.43750000000000011 0.14350000000000002">
        <geom name="black_key_geom_76" class="black_key"/>
        <joint name="black_joint_76" class="black_key"/>
        <site name="black_key_site_76" class="black_key"/>
      </body>
      <body name="white_key_77" pos="0.074999999999999997 0.44850000000000001 0.129">
        <geom name="white_key_geom_77" class="white_key"/>
        <joint name="white_joint_77" class="white_key"/>
        <site name="white_key_site_77" class="white_key"/>
      </body>
      <body name="black_key_78" pos="0.044999999999999998 0.46050000000000013 0.14350000000000002">
        <geom name="black_key_geom_78" class="black_key"/>
        <joint name="black_joint_78" class="black_key"/>
        <site name="black_key_site_78" class="black_key"/>
      </body>
      <body name="white_key_79" pos="0.074999999999999997 0.47150000000000014 0.129">
        <geom name="white_key_geom_79" class="white_key"/>
        <joint name="white_joint_79" class="white_key"/>
        <site name="white_key_site_79" class="white_key"/>
      </body>
      <body name="white_key_80" pos="0.074999999999999997 0.49450000000000005 0.129">
        <geom name="white_key_geom_80" class="white_key"/>
        <joint name="white_joint_80" class="white_key"/>
        <site name="white_key_site_80" class="white_key"/>
      </body>
      <body name="black_key_81" pos="0.044999999999999998 0.50650000000000006 0.14350000000000002">
        <geom name="black_key_geom_81" class="black_key"/>
        <joint name="black_joint_81" class="black_key"/>
        <site name="black_key_site_81" class="black_key"/>
      </body>
      <body name="white_key_82" pos="0.074999999999999997 0.51750000000000018 0.129">
        <geom name="white_key_geom_82" class="white_key"/>
        <joint name="white_joint_82" class="white_key"/>
        <site name="white_key_site_82" class="white_key"/>
      </body>
      <body name="black_key_83" pos="0.044999999999999998 0.52950000000000008 0.14350000000000002">
        <geom name="black_key_geom_83" class="black_key"/>
        <joint name="black_joint_83" class="black_key"/>
        <site name="black_key_site_83" class="black_key"/>
      </body>
      <body name="white_key_84" pos="0.074999999999999997 0.54050000000000009 0.129">
        <geom name="white_key_geom_84" class="white_key"/>
        <joint name="white_joint_84" class="white_key"/>
        <site name="white_key_site_84" class="white_key"/>
      </body>
      <body name="black_key_85" pos="0.044999999999999998 0.55249999999999999 0.14350000000000002">
        <geom name="black_key_geom_85" class="black_key"/>
        <joint name="black_joint_85" class="black_key"/>
        <site name="black_key_site_85" class="black_key"/>
      </body>
      <body name="white_key_86" pos="0.074999999999999997 0.5635 0.129">
        <geom name="white_key_geom_86" class="white_key"/>
        <joint name="white_joint_86" class="white_key"/>
        <site name="white_key_site_86" class="white_key"/>
      </body>
      <body name="white_key_87" pos="0.074999999999999997 0.58650000000000013 0.129">
        <geom name="white_key_geom_87" class="white_key"/>
        <joint name="white_joint_87" class="white_key"/>
        <site name="white_key_site_87" class="white_key"/>
      </body>
    </body>
  </worldbody>
</mujoco>
